Workbook

Sheet README
A1: Atlas Integrated Scoring Formula Model
A3: Purpose | B3: Reproduces Levels 1 and 2 from atlas_integrated_scoring(20260811-220550).ipynb using Excel formulas linked to the five embedded source-data sheets.
A4: Update workflow | B4: Edit or replace values within the existing source rows. Do not sort source sheets unless the linked calculation rows are rebuilt.
A5: Yellow cells | B5: Source data embedded from the five standardized scoring tables.
A6: Blue headers | B6: Formula-driven calculation and output tables.
A7: Score precision | B7: Formulas retain full precision. Displayed score fields use six decimal places for auditability.
A8: Level 1 impact | B8: fish_use_score_decimal × condition_score × vulnerability_score
A9: Level 1 risk | B9: impact_component × population_priority
A10: Condition improvement | B10: Σ(condition_score × lfat_score), by BSR and action
A11: Action benefit | B11: Σ(limiting-factor risk_score × lfat_score), by BSR and action
A12: Review metadata | B12: Action definitions and review flags are not present in the embedded source tables. They do not affect the numeric scores and are omitted from the output tables.
A13: Sheet | B13: Role | C13: Primary content
A14: Fish Use | B14: Source | C14: BSR × species × life-stage fish-use ratings
A15: Population | B15: Source | C15: Basin × species × life-stage population priorities
A16: Limiting Factors | B16: Source | C16: BSR × limiting-factor condition scores
A17: Vulnerability | B17: Source | C17: Species × source life-stage × limiting-factor vulnerability
A18: LFAT | B18: Source | C18: Action × limiting-factor relationship weights
A19: Vulnerability Mapped | B19: Calculation | C19: Migration-stage collapse using the maximum source vulnerability
A20: L1 Calculation Grid | B20: Calculation | C20: 4,350 row-level impact and risk components
A21: Life Stage Scores | B21: Output | C21: Level 1 summaries by BSR, species, and life stage
A22: Limiting Factor Scores | B22: Output | C22: Level 1 summaries by BSR and limiting factor
A23: Action Components | B23: Calculation | C23: Level 2 action × limiting-factor components
A24: Action Scores | B24: Output | C24: Level 2 summaries by BSR and action type
... A26: QC | B26: Control | C26: Row-count, balance, and formula checks

Sheet Fish Use
A1: bsr | B1: basin | C1: bsr_crosswalk_status | D1: species | E1: life_stage | F1: fish_use_score_decimal
A2: CC1 | B2: Catherine Creek | C2: provisional_positional | D2: Chinook | E2: Spawning | F2: 0.4162
A3: CC1 | B3: Catherine Creek | C3: provisional_positional | D3: Chinook | E3: Winter Rearing | F3: 0.4162
A4: CC1 | B4: Catherine Creek | C4: provisional_positional | D4: Chinook | E4: Summer Rearing | F4: 0.4162
A5: CC1 | B5: Catherine Creek | C5: provisional_positional | D5: Chinook | E5: Migration | F5: 0.4162
A6: CC1 | B6: Catherine Creek | C6: provisional_positional | D6: Steelhead | E6: Spawning | F6: 0.4162
A7: CC1 | B7: Catherine Creek | C7: provisional_positional | D7: Steelhead | E7: Winter Rearing | F7: 0.4162
A8: CC1 | B8: Catherine Creek | C8: provisional_positional | D8: Steelhead | E8: Summer Rearing | F8: 0.4162
A9: CC1 | B9: Catherine Creek | C9: provisional_positional | D9: Steelhead | E9: Migration | F9: 0.4162
A10: CC1 | B10: Catherine Creek | C10: provisional_positional | D10: Bull Trout | E10: Spawning & Resident | F10: 0.4162
A11: CC1 | B11: Catherine Creek | C11: provisional_positional | D11: Bull Trout | E11: FMO | F11: 0.4162
A12: CC2 | B12: Catherine Creek | C12: provisional_positional | D12: Chinook | E12: Spawning | F12: 0.2803
A13: CC2 | B13: Catherine Creek | C13: provisional_positional | D13: Chinook | E13: Winter Rearing | F13: 0.2803
... A291: UGR20 | B291: Upper Grande Ronde | C291: exact_identifier | D291: Bull Trout | E291: FMO | F291: 0.8697

Sheet Population
A1: basin | B1: species | C1: life_stage | D1: population_priority
A2: Catherine Creek | B2: Chinook | C2: Spawning | D2: 0.12
A3: Catherine Creek | B3: Steelhead | C3: Spawning | D3: 0.25
A4: Catherine Creek | B4: Chinook | C4: Summer Rearing | D4: 0.21
A5: Catherine Creek | B5: Steelhead | C5: Summer Rearing | D5: 0.25
A6: Catherine Creek | B6: Chinook | C6: Winter Rearing | D6: 0.36
A7: Catherine Creek | B7: Steelhead | C7: Winter Rearing | D7: 0.25
A8: Catherine Creek | B8: Chinook | C8: Migration | D8: 0.3
A9: Catherine Creek | B9: Steelhead | C9: Migration | D9: 0.25
A10: Upper Grande Ronde | B10: Chinook | C10: Spawning | D10: 0.08
A11: Upper Grande Ronde | B11: Steelhead | C11: Spawning | D11: 0.25
A12: Upper Grande Ronde | B12: Chinook | C12: Summer Rearing | D12: 0.24
A13: Upper Grande Ronde | B13: Steelhead | C13: Summer Rearing | D13: 0.25
... A21: Upper Grande Ronde | B21: Bull Trout | C21: FMO | D21: 0.4

Sheet Limiting Factors
A1: bsr | B1: limiting_factor | C1: lf_condition_score_raw_1_5 | D1: lf_condition_score
A2: CC1 | B2: Riparian Condition | C2: 4.57 | D2: 0.90325
A3: CC1 | B3: Floodplain Condition | C3: 4.78 | D3: 0.9505
A4: CC1 | B4: Side Channel and Wetland Habitat | C4: 4.08 | D4: 0.793
A5: CC1 | B5: Channel and Habitat Structure | C5: 4.57 | D5: 0.90325
A6: CC1 | B6: Decreased Sediment Quantity | C6: 2.95 | D6: 0.53875
A7: CC1 | B7: Increased Sediment Quantity | C7: 4.51 | D7: 0.88975
A8: CC1 | B8: Anthropogenic Barriers | C8: 3.68 | D8: 0.703
A9: CC1 | B9: Predation | C9: 4.22 | D9: 0.8245
A10: CC1 | B10: Altered Primary Productivity | C10: 4.31 | D10: 0.84475
A11: CC1 | B11: Non-Native Species Interactions and Competition | C11: 4.64 | D11: 0.919
A12: CC1 | B12: Decreased Water Quantity | C12: 5 | D12: 1
A13: CC1 | B13: Altered Flow Timing | C13: 4.31 | D13: 0.84475
... A436: UGR9 | B436: Water Quality | C436: 3.42 | D436: 0.6445

Sheet Vulnerability
A1: species | B1: source_life_stage | C1: life_stage | D1: limiting_factor | E1: vulnerability_rank | F1: vulnerability_score
A2: Bull Trout | B2: FMO (Fluvial) | C2: FMO | D2: Summer Water Temperature | E2: 1 | F2: 1
A3: Bull Trout | B3: FMO (Fluvial) | C3: FMO | D3: Decreased Water Quantity | E3: 2 | F3: 0.93571429
A4: Bull Trout | B4: FMO (Fluvial) | C4: FMO | D4: Anthropogenic Barriers | E4: 3 | F4: 0.87142857
A5: Bull Trout | B5: FMO (Fluvial) | C5: FMO | D5: Channel and Habitat Structure | E5: 4 | F5: 0.80714286
A6: Bull Trout | B6: FMO (Fluvial) | C6: FMO | D6: Riparian Condition | E6: 5 | F6: 0.74285714
A7: Bull Trout | B7: FMO (Fluvial) | C7: FMO | D7: Water Quality | E7: 6 | F7: 0.67857143
A8: Bull Trout | B8: FMO (Fluvial) | C8: FMO | D8: Predation | E8: 7 | F8: 0.61428571
A9: Bull Trout | B9: FMO (Fluvial) | C9: FMO | D9: Side Channel and Wetland Habitat | E9: 8 | F9: 0.55
A10: Bull Trout | B10: FMO (Fluvial) | C10: FMO | D10: Floodplain Condition | E10: 9 | F10: 0.48571429
A11: Bull Trout | B11: FMO (Fluvial) | C11: FMO | D11: Non-Native Species Interactions and Competition | E11: 10 | F11: 0.42142857
A12: Bull Trout | B12: FMO (Fluvial) | C12: FMO | D12: Altered Flow Timing | E12: 11 | F12: 0.35714286
A13: Bull Trout | B13: FMO (Fluvial) | C13: FMO | D13: Altered Primary Productivity | E13: 12 | F13: 0.29285714
... A181: Steelhead | B181: Winter Rearing | C181: Winter Rearing | D181: Summer Water Temperature | E181: 15 | F181: 0.1

Sheet LFAT
A1: action_id | B1: action_type | C1: limiting_factor | D1: directness_code | E1: directness_rating | F1: directness_value | G1: frequency_code | H1: frequency_rating | I1: frequency_value | J1: lfat_score
A2: 1 | B2: Protect Land (Easement and Acquisition) | C2: Anthropogenic Barriers | D2: I | E2: Indirect Benefit | F2: 0.5 | G2: CD | H2: Context-Dependant Benefit | I2: 0.5 | J2: 0.25
A3: 1 | B3: Protect Land (Easement and Acquisition) | C3: Riparian Condition | D3: I | E3: Indirect Benefit | F3: 0.5 | G3: C | H3: Common Benefit | I3: 1 | J3: 0.5
A4: 1 | B4: Protect Land (Easement and Acquisition) | C4: Floodplain Condition | D4: I | E4: Indirect Benefit | F4: 0.5 | G4: CD | H4: Context-Dependant Benefit | I4: 0.5 | J4: 0.25
A5: 1 | B5: Protect Land (Easement and Acquisition) | C5: Side Channel and Wetland Habitat | D5: I | E5: Indirect Benefit | F5: 0.5 | G5: CD | H5: Context-Dependant Benefit | I5: 0.5 | J5: 0.25
A6: 1 | B6: Protect Land (Easement and Acquisition) | C6: Channel and Habitat Structure | D6: I | E6: Indirect Benefit | F6: 0.5 | G6: CD | H6: Context-Dependant Benefit | I6: 0.5 | J6: 0.25
A7: 1 | B7: Protect Land (Easement and Acquisition) | C7: Decreased Water Quantity | D7: I | E7: Indirect Benefit | F7: 0.5 | G7: CD | H7: Context-Dependant Benefit | I7: 0.5 | J7: 0.25
A8: 1 | B8: Protect Land (Easement and Acquisition) | C8: Altered Flow Timing | D8: I | E8: Indirect Benefit | F8: 0.5 | G8: CD | H8: Context-Dependant Benefit | I8: 0.5 | J8: 0.25
A9: 1 | B9: Protect Land (Easement and Acquisition) | C9: Decreased Sediment Quantity | D9: I | E9: Indirect Benefit | F9: 0.5 | G9: CD | H9: Context-Dependant Benefit | I9: 0.5 | J9: 0.25
A10: 1 | B10: Protect Land (Easement and Acquisition) | C10: Increased Sediment Quantity | D10: I | E10: Indirect Benefit | F10: 0.5 | G10: CD | H10: Context-Dependant Benefit | I10: 0.5 | J10: 0.25
A11: 1 | B11: Protect Land (Easement and Acquisition) | C11: Summer Water Temperature | D11: I | E11: Indirect Benefit | F11: 0.5 | G11: R | H11: Rare Benefit | I11: 0.1 | J11: 0.05
A12: 1 | B12: Protect Land (Easement and Acquisition) | C12: Winter Water Temperature | D12: I | E12: Indirect Benefit | F12: 0.5 | G12: R | H12: Rare Benefit | I12: 0.1 | J12: 0.05
A13: 1 | B13: Protect Land (Easement and Acquisition) | C13: Water Quality | D13: I | E13: Indirect Benefit | F13: 0.5 | G13: CD | H13: Context-Dependant Benefit | I13: 0.5 | J13: 0.25
... A166: 11 | B166: Species Management (non-native or unnatural) | C166: Non-Native Species Interactions and Competition | D166: D | E166: Direct Benefit | F166: 1 | G166: C | H166: Common Benefit | I166: 1 | J166: 1

Sheet Vulnerability Mapped
A1: species | B1: life_stage | C1: limiting_factor | D1: vulnerability_rank_min | E1: vulnerability_rank_max | F1: vulnerability_score_min | G1: vulnerability_score_max | H1: vulnerability_score | I1: source_vulnerability_rows | J1: source_life_stages
A2: =Vulnerability!A12 -> Bull Trout | B2: =Vulnerability!C12 -> FMO | C2: =Vulnerability!D12 -> Altered Flow Timing | D2: =MIN(Vulnerability!E12) -> 11 | E2: =MAX(Vulnerability!E12) -> 11 | F2: =MIN(Vulnerability!F12) -> 0.35714286 | G2: =MAX(Vulnerability!F12) -> 0.35714286 | H2: =MAX(Vulnerability!F12) -> 0.35714286 | I2: =COUNTA(Vulnerability!A12) -> 1 | J2: =Vulnerability!B12 -> FMO (Fluvial)
A3: =Vulnerability!A13 -> Bull Trout | B3: =Vulnerability!C13 -> FMO | C3: =Vulnerability!D13 -> Altered Primary Productivity | D3: =MIN(Vulnerability!E13) -> 12 | E3: =MAX(Vulnerability!E13) -> 12 | F3: =MIN(Vulnerability!F13) -> 0.29285714 | G3: =MAX(Vulnerability!F13) -> 0.29285714 | H3: =MAX(Vulnerability!F13) -> 0.29285714 | I3: =COUNTA(Vulnerability!A13) -> 1 | J3: =Vulnerability!B13 -> FMO (Fluvial)
A4: =Vulnerability!A4 -> Bull Trout | B4: =Vulnerability!C4 -> FMO | C4: =Vulnerability!D4 -> Anthropogenic Barriers | D4: =MIN(Vulnerability!E4) -> 3 | E4: =MAX(Vulnerability!E4) -> 3 | F4: =MIN(Vulnerability!F4) -> 0.87142857 | G4: =MAX(Vulnerability!F4) -> 0.87142857 | H4: =MAX(Vulnerability!F4) -> 0.87142857 | I4: =COUNTA(Vulnerability!A4) -> 1 | J4: =Vulnerability!B4 -> FMO (Fluvial)
A5: =Vulnerability!A5 -> Bull Trout | B5: =Vulnerability!C5 -> FMO | C5: =Vulnerability!D5 -> Channel and Habitat Structure | D5: =MIN(Vulnerability!E5) -> 4 | E5: =MAX(Vulnerability!E5) -> 4 | F5: =MIN(Vulnerability!F5) -> 0.80714286 | G5: =MAX(Vulnerability!F5) -> 0.80714286 | H5: =MAX(Vulnerability!F5) -> 0.80714286 | I5: =COUNTA(Vulnerability!A5) -> 1 | J5: =Vulnerability!B5 -> FMO (Fluvial)
A6: =Vulnerability!A14 -> Bull Trout | B6: =Vulnerability!C14 -> FMO | C6: =Vulnerability!D14 -> Decreased Sediment Quantity | D6: =MIN(Vulnerability!E14) -> 13 | E6: =MAX(Vulnerability!E14) -> 13 | F6: =MIN(Vulnerability!F14) -> 0.22857143 | G6: =MAX(Vulnerability!F14) -> 0.22857143 | H6: =MAX(Vulnerability!F14) -> 0.22857143 | I6: =COUNTA(Vulnerability!A14) -> 1 | J6: =Vulnerability!B14 -> FMO (Fluvial)
A7: =Vulnerability!A3 -> Bull Trout | B7: =Vulnerability!C3 -> FMO | C7: =Vulnerability!D3 -> Decreased Water Quantity | D7: =MIN(Vulnerability!E3) -> 2 | E7: =MAX(Vulnerability!E3) -> 2 | F7: =MIN(Vulnerability!F3) -> 0.93571429 | G7: =MAX(Vulnerability!F3) -> 0.93571429 | H7: =MAX(Vulnerability!F3) -> 0.93571429 | I7: =COUNTA(Vulnerability!A3) -> 1 | J7: =Vulnerability!B3 -> FMO (Fluvial)
A8: =Vulnerability!A10 -> Bull Trout | B8: =Vulnerability!C10 -> FMO | C8: =Vulnerability!D10 -> Floodplain Condition | D8: =MIN(Vulnerability!E10) -> 9 | E8: =MAX(Vulnerability!E10) -> 9 | F8: =MIN(Vulnerability!F10) -> 0.48571429 | G8: =MAX(Vulnerability!F10) -> 0.48571429 | H8: =MAX(Vulnerability!F10) -> 0.48571429 | I8: =COUNTA(Vulnerability!A10) -> 1 | J8: =Vulnerability!B10 -> FMO (Fluvial)
A9: =Vulnerability!A15 -> Bull Trout | B9: =Vulnerability!C15 -> FMO | C9: =Vulnerability!D15 -> Increased Sediment Quantity | D9: =MIN(Vulnerability!E15) -> 14 | E9: =MAX(Vulnerability!E15) -> 14 | F9: =MIN(Vulnerability!F15) -> 0.16428571 | G9: =MAX(Vulnerability!F15) -> 0.16428571 | H9: =MAX(Vulnerability!F15) -> 0.16428571 | I9: =COUNTA(Vulnerability!A15) -> 1 | J9: =Vulnerability!B15 -> FMO (Fluvial)
A10: =Vulnerability!A11 -> Bull Trout | B10: =Vulnerability!C11 -> FMO | C10: =Vulnerability!D11 -> Non-Native Species Interactions and Competition | D10: =MIN(Vulnerability!E11) -> 10 | E10: =MAX(Vulnerability!E11) -> 10 | F10: =MIN(Vulnerability!F11) -> 0.42142857 | G10: =MAX(Vulnerability!F11) -> 0.42142857 | H10: =MAX(Vulnerability!F11) -> 0.42142857 | I10: =COUNTA(Vulnerability!A11) -> 1 | J10: =Vulnerability!B11 -> FMO (Fluvial)
A11: =Vulnerability!A8 -> Bull Trout | B11: =Vulnerability!C8 -> FMO | C11: =Vulnerability!D8 -> Predation | D11: =MIN(Vulnerability!E8) -> 7 | E11: =MAX(Vulnerability!E8) -> 7 | F11: =MIN(Vulnerability!F8) -> 0.61428571 | G11: =MAX(Vulnerability!F8) -> 0.61428571 | H11: =MAX(Vulnerability!F8) -> 0.61428571 | I11: =COUNTA(Vulnerability!A8) -> 1 | J11: =Vulnerability!B8 -> FMO (Fluvial)
A12: =Vulnerability!A6 -> Bull Trout | B12: =Vulnerability!C6 -> FMO | C12: =Vulnerability!D6 -> Riparian Condition | D12: =MIN(Vulnerability!E6) -> 5 | E12: =MAX(Vulnerability!E6) -> 5 | F12: =MIN(Vulnerability!F6) -> 0.74285714 | G12: =MAX(Vulnerability!F6) -> 0.74285714 | H12: =MAX(Vulnerability!F6) -> 0.74285714 | I12: =COUNTA(Vulnerability!A6) -> 1 | J12: =Vulnerability!B6 -> FMO (Fluvial)
A13: =Vulnerability!A9 -> Bull Trout | B13: =Vulnerability!C9 -> FMO | C13: =Vulnerability!D9 -> Side Channel and Wetland Habitat | D13: =MIN(Vulnerability!E9) -> 8 | E13: =MAX(Vulnerability!E9) -> 8 | F13: =MIN(Vulnerability!F9) -> 0.55 | G13: =MAX(Vulnerability!F9) -> 0.55 | H13: =MAX(Vulnerability!F9) -> 0.55 | I13: =COUNTA(Vulnerability!A9) -> 1 | J13: =Vulnerability!B9 -> FMO (Fluvial)
A14: =Vulnerability!A2 -> Bull Trout | B14: =Vulnerability!C2 -> FMO | C14: =Vulnerability!D2 -> Summer Water Temperature | D14: =MIN(Vulnerability!E2) -> 1 | E14: =MAX(Vulnerability!E2) -> 1 | F14: =MIN(Vulnerability!F2) -> 1 | G14: =MAX(Vulnerability!F2) -> 1 | H14: =MAX(Vulnerability!F2) -> 1 | I14: =COUNTA(Vulnerability!A2) -> 1 | J14: =Vulnerability!B2 -> FMO (Fluvial)
A15: =Vulnerability!A7 -> Bull Trout | B15: =Vulnerability!C7 -> FMO | C15: =Vulnerability!D7 -> Water Quality | D15: =MIN(Vulnerability!E7) -> 6 | E15: =MAX(Vulnerability!E7) -> 6 | F15: =MIN(Vulnerability!F7) -> 0.67857143 | G15: =MAX(Vulnerability!F7) -> 0.67857143 | H15: =MAX(Vulnerability!F7) -> 0.67857143 | I15: =COUNTA(Vulnerability!A7) -> 1 | J15: =Vulnerability!B7 -> FMO (Fluvial)
A16: =Vulnerability!A16 -> Bull Trout | B16: =Vulnerability!C16 -> FMO | C16: =Vulnerability!D16 -> Winter Water Temperature | D16: =MIN(Vulnerability!E16) -> 15 | E16: =MAX(Vulnerability!E16) -> 15 | F16: =MIN(Vulnerability!F16) -> 0.1 | G16: =MAX(Vulnerability!F16) -> 0.1 | H16: =MAX(Vulnerability!F16) -> 0.1 | I16: =COUNTA(Vulnerability!A16) -> 1 | J16: =Vulnerability!B16 -> FMO (Fluvial)
A17: =Vulnerability!A29 -> Bull Trout | B17: =Vulnerability!C29 -> Spawning & Resident | C17: =Vulnerability!D29 -> Altered Flow Timing | D17: =MIN(Vulnerability!E29) -> 13 | E17: =MAX(Vulnerability!E29) -> 13 | F17: =MIN(Vulnerability!F29) -> 0.22857143 | G17: =MAX(Vulnerability!F29) -> 0.22857143 | H17: =MAX(Vulnerability!F29) -> 0.22857143 | I17: =COUNTA(Vulnerability!A29) -> 1 | J17: =Vulnerability!B29 -> Spawning/Rearing (fluvial) & Resident
A18: =Vulnerability!A30 -> Bull Trout | B18: =Vulnerability!C30 -> Spawning & Resident | C18: =Vulnerability!D30 -> Altered Primary Productivity | D18: =MIN(Vulnerability!E30) -> 14 | E18: =MAX(Vulnerability!E30) -> 14 | F18: =MIN(Vulnerability!F30) -> 0.16428571 | G18: =MAX(Vulnerability!F30) -> 0.16428571 | H18: =MAX(Vulnerability!F30) -> 0.16428571 | I18: =COUNTA(Vulnerability!A30) -> 1 | J18: =Vulnerability!B30 -> Spawning/Rearing (fluvial) & Resident
A19: =Vulnerability!A26 -> Bull Trout | B19: =Vulnerability!C26 -> Spawning & Resident | C19: =Vulnerability!D26 -> Anthropogenic Barriers | D19: =MIN(Vulnerability!E26) -> 10 | E19: =MAX(Vulnerability!E26) -> 10 | F19: =MIN(Vulnerability!F26) -> 0.42142857 | G19: =MAX(Vulnerability!F26) -> 0.42142857 | H19: =MAX(Vulnerability!F26) -> 0.42142857 | I19: =COUNTA(Vulnerability!A26) -> 1 | J19: =Vulnerability!B26 -> Spawning/Rearing (fluvial) & Resident
A20: =Vulnerability!A19 -> Bull Trout | B20: =Vulnerability!C19 -> Spawning & Resident | C20: =Vulnerability!D19 -> Channel and Habitat Structure | D20: =MIN(Vulnerability!E19) -> 3 | E20: =MAX(Vulnerability!E19) -> 3 | F20: =MIN(Vulnerability!F19) -> 0.87142857 | G20: =MAX(Vulnerability!F19) -> 0.87142857 | H20: =MAX(Vulnerability!F19) -> 0.87142857 | I20: =COUNTA(Vulnerability!A19) -> 1 | J20: =Vulnerability!B19 -> Spawning/Rearing (fluvial) & Resident
A21: =Vulnerability!A21 -> Bull Trout | B21: =Vulnerability!C21 -> Spawning & Resident | C21: =Vulnerability!D21 -> Decreased Sediment Quantity | D21: =MIN(Vulnerability!E21) -> 5 | E21: =MAX(Vulnerability!E21) -> 5 | F21: =MIN(Vulnerability!F21) -> 0.74285714 | G21: =MAX(Vulnerability!F21) -> 0.74285714 | H21: =MAX(Vulnerability!F21) -> 0.74285714 | I21: =COUNTA(Vulnerability!A21) -> 1 | J21: =Vulnerability!B21 -> Spawning/Rearing (fluvial) & Resident
A22: =Vulnerability!A24 -> Bull Trout | B22: =Vulnerability!C24 -> Spawning & Resident | C22: =Vulnerability!D24 -> Decreased Water Quantity | D22: =MIN(Vulnerability!E24) -> 8 | E22: =MAX(Vulnerability!E24) -> 8 | F22: =MIN(Vulnerability!F24) -> 0.55 | G22: =MAX(Vulnerability!F24) -> 0.55 | H22: =MAX(Vulnerability!F24) -> 0.55 | I22: =COUNTA(Vulnerability!A24) -> 1 | J22: =Vulnerability!B24 -> Spawning/Rearing (fluvial) & Resident
A23: =Vulnerability!A27 -> Bull Trout | B23: =Vulnerability!C27 -> Spawning & Resident | C23: =Vulnerability!D27 -> Floodplain Condition | D23: =MIN(Vulnerability!E27) -> 11 | E23: =MAX(Vulnerability!E27) -> 11 | F23: =MIN(Vulnerability!F27) -> 0.35714286 | G23: =MAX(Vulnerability!F27) -> 0.35714286 | H23: =MAX(Vulnerability!F27) -> 0.35714286 | I23: =COUNTA(Vulnerability!A27) -> 1 | J23: =Vulnerability!B27 -> Spawning/Rearing (fluvial) & Resident
A24: =Vulnerability!A22 -> Bull Trout | B24: =Vulnerability!C22 -> Spawning & Resident | C24: =Vulnerability!D22 -> Increased Sediment Quantity | D24: =MIN(Vulnerability!E22) -> 6 | E24: =MAX(Vulnerability!E22) -> 6 | F24: =MIN(Vulnerability!F22) -> 0.67857143 | G24: =MAX(Vulnerability!F22) -> 0.67857143 | H24: =MAX(Vulnerability!F22) -> 0.67857143 | I24: =COUNTA(Vulnerability!A22) -> 1 | J24: =Vulnerability!B22 -> Spawning/Rearing (fluvial) & Resident
A25: =Vulnerability!A18 -> Bull Trout | B25: =Vulnerability!C18 -> Spawning & Resident | C25: =Vulnerability!D18 -> Non-Native Species Interactions and Competition | D25: =MIN(Vulnerability!E18) -> 2 | E25: =MAX(Vulnerability!E18) -> 2 | F25: =MIN(Vulnerability!F18) -> 0.93571429 | G25: =MAX(Vulnerability!F18) -> 0.93571429 | H25: =MAX(Vulnerability!F18) -> 0.93571429 | I25: =COUNTA(Vulnerability!A18) -> 1 | J25: =Vulnerability!B18 -> Spawning/Rearing (fluvial) & Resident
A26: =Vulnerability!A25 -> Bull Trout | B26: =Vulnerability!C25 -> Spawning & Resident | C26: =Vulnerability!D25 -> Predation | D26: =MIN(Vulnerability!E25) -> 9 | E26: =MAX(Vulnerability!E25) -> 9 | F26: =MIN(Vulnerability!F25) -> 0.48571429 | G26: =MAX(Vulnerability!F25) -> 0.48571429 | H26: =MAX(Vulnerability!F25) -> 0.48571429 | I26: =COUNTA(Vulnerability!A25) -> 1 | J26: =Vulnerability!B25 -> Spawning/Rearing (fluvial) & Resident
A27: =Vulnerability!A20 -> Bull Trout | B27: =Vulnerability!C20 -> Spawning & Resident | C27: =Vulnerability!D20 -> Riparian Condition | D27: =MIN(Vulnerability!E20) -> 4 | E27: =MAX(Vulnerability!E20) -> 4 | F27: =MIN(Vulnerability!F20) -> 0.80714286 | G27: =MAX(Vulnerability!F20) -> 0.80714286 | H27: =MAX(Vulnerability!F20) -> 0.80714286 | I27: =COUNTA(Vulnerability!A20) -> 1 | J27: =Vulnerability!B20 -> Spawning/Rearing (fluvial) & Resident
A28: =Vulnerability!A23 -> Bull Trout | B28: =Vulnerability!C23 -> Spawning & Resident | C28: =Vulnerability!D23 -> Side Channel and Wetland Habitat | D28: =MIN(Vulnerability!E23) -> 7 | E28: =MAX(Vulnerability!E23) -> 7 | F28: =MIN(Vulnerability!F23) -> 0.61428571 | G28: =MAX(Vulnerability!F23) -> 0.61428571 | H28: =MAX(Vulnerability!F23) -> 0.61428571 | I28: =COUNTA(Vulnerability!A23) -> 1 | J28: =Vulnerability!B23 -> Spawning/Rearing (fluvial) & Resident
A29: =Vulnerability!A17 -> Bull Trout | B29: =Vulnerability!C17 -> Spawning & Resident | C29: =Vulnerability!D17 -> Summer Water Temperature | D29: =MIN(Vulnerability!E17) -> 1 | E29: =MAX(Vulnerability!E17) -> 1 | F29: =MIN(Vulnerability!F17) -> 1 | G29: =MAX(Vulnerability!F17) -> 1 | H29: =MAX(Vulnerability!F17) -> 1 | I29: =COUNTA(Vulnerability!A17) -> 1 | J29: =Vulnerability!B17 -> Spawning/Rearing (fluvial) & Resident
A30: =Vulnerability!A31 -> Bull Trout | B30: =Vulnerability!C31 -> Spawning & Resident | C30: =Vulnerability!D31 -> Water Quality | D30: =MIN(Vulnerability!E31) -> 15 | E30: =MAX(Vulnerability!E31) -> 15 | F30: =MIN(Vulnerability!F31) -> 0.1 | G30: =MAX(Vulnerability!F31) -> 0.1 | H30: =MAX(Vulnerability!F31) -> 0.1 | I30: =COUNTA(Vulnerability!A31) -> 1 | J30: =Vulnerability!B31 -> Spawning/Rearing (fluvial) & Resident
A31: =Vulnerability!A28 -> Bull Trout | B31: =Vulnerability!C28 -> Spawning & Resident | C31: =Vulnerability!D28 -> Winter Water Temperature | D31: =MIN(Vulnerability!E28) -> 12 | E31: =MAX(Vulnerability!E28) -> 12 | F31: =MIN(Vulnerability!F28) -> 0.29285714 | G31: =MAX(Vulnerability!F28) -> 0.29285714 | H31: =MAX(Vulnerability!F28) -> 0.29285714 | I31: =COUNTA(Vulnerability!A28) -> 1 | J31: =Vulnerability!B28 -> Spawning/Rearing (fluvial) & Resident
A32: =Vulnerability!A35 -> Chinook | B32: =Vulnerability!C35 -> Migration | C32: =Vulnerability!D35 -> Altered Flow Timing | D32: =MIN(Vulnerability!E35,Vulnerability!E50) -> 4 | E32: =MAX(Vulnerability!E35,Vulnerability!E50) -> 4 | F32: =MIN(Vulnerability!F35,Vulnerability!F50) -> 0.80714286 | G32: =MAX(Vulnerability!F35,Vulnerability!F50) -> 0.80714286 | H32: =MAX(Vulnerability!F35,Vulnerability!F50) -> 0.80714286 | I32: =COUNTA(Vulnerability!A35,Vulnerability!A50) -> 2 | J32: =Vulnerability!B35&" | "&Vulnerability!B50 -> Adult Migration & Holding | Juvenile Emigration
A33: =Vulnerability!A44 -> Chinook | B33: =Vulnerability!C44 -> Migration | C33: =Vulnerability!D44 -> Altered Primary Productivity | D33: =MIN(Vulnerability!E44,Vulnerability!E56) -> 10 | E33: =MAX(Vulnerability!E44,Vulnerability!E56) -> 13 | F33: =MIN(Vulnerability!F44,Vulnerability!F56) -> 0.22857143 | G33: =MAX(Vulnerability!F44,Vulnerability!F56) -> 0.42142857 | H33: =MAX(Vulnerability!F44,Vulnerability!F56) -> 0.42142857 | I33: =COUNTA(Vulnerability!A44,Vulnerability!A56) -> 2 | J33: =Vulnerability!B44&" | "&Vulnerability!B56 -> Adult Migration & Holding | Juvenile Emigration
A34: =Vulnerability!A33 -> Chinook | B34: =Vulnerability!C33 -> Migration | C34: =Vulnerability!D33 -> Anthropogenic Barriers | D34: =MIN(Vulnerability!E33,Vulnerability!E59) -> 2 | E34: =MAX(Vulnerability!E33,Vulnerability!E59) -> 13 | F34: =MIN(Vulnerability!F33,Vulnerability!F59) -> 0.22857143 | G34: =MAX(Vulnerability!F33,Vulnerability!F59) -> 0.93571429 | H34: =MAX(Vulnerability!F33,Vulnerability!F59) -> 0.93571429 | I34: =COUNTA(Vulnerability!A33,Vulnerability!A59) -> 2 | J34: =Vulnerability!B33&" | "&Vulnerability!B59 -> Adult Migration & Holding | Juvenile Emigration
A35: =Vulnerability!A36 -> Chinook | B35: =Vulnerability!C36 -> Migration | C35: =Vulnerability!D36 -> Channel and Habitat Structure | D35: =MIN(Vulnerability!E36,Vulnerability!E49) -> 3 | E35: =MAX(Vulnerability!E36,Vulnerability!E49) -> 5 | F35: =MIN(Vulnerability!F36,Vulnerability!F49) -> 0.74285714 | G35: =MAX(Vulnerability!F36,Vulnerability!F49) -> 0.87142857 | H35: =MAX(Vulnerability!F36,Vulnerability!F49) -> 0.87142857 | I35: =COUNTA(Vulnerability!A36,Vulnerability!A49) -> 2 | J35: =Vulnerability!B36&" | "&Vulnerability!B49 -> Adult Migration & Holding | Juvenile Emigration
A36: =Vulnerability!A42 -> Chinook | B36: =Vulnerability!C42 -> Migration | C36: =Vulnerability!D42 -> Decreased Sediment Quantity | D36: =MIN(Vulnerability!E42,Vulnerability!E58) -> 11 | E36: =MAX(Vulnerability!E42,Vulnerability!E58) -> 12 | F36: =MIN(Vulnerability!F42,Vulnerability!F58) -> 0.29285714 | G36: =MAX(Vulnerability!F42,Vulnerability!F58) -> 0.35714286 | H36: =MAX(Vulnerability!F42,Vulnerability!F58) -> 0.35714286 | I36: =COUNTA(Vulnerability!A42,Vulnerability!A58) -> 2 | J36: =Vulnerability!B42&" | "&Vulnerability!B58 -> Adult Migration & Holding | Juvenile Emigration
A37: =Vulnerability!A34 -> Chinook | B37: =Vulnerability!C34 -> Migration | C37: =Vulnerability!D34 -> Decreased Water Quantity | D37: =MIN(Vulnerability!E34,Vulnerability!E48) -> 2 | E37: =MAX(Vulnerability!E34,Vulnerability!E48) -> 3 | F37: =MIN(Vulnerability!F34,Vulnerability!F48) -> 0.87142857 | G37: =MAX(Vulnerability!F34,Vulnerability!F48) -> 0.93571429 | H37: =MAX(Vulnerability!F34,Vulnerability!F48) -> 0.93571429 | I37: =COUNTA(Vulnerability!A34,Vulnerability!A48) -> 2 | J37: =Vulnerability!B34&" | "&Vulnerability!B48 -> Adult Migration & Holding | Juvenile Emigration
A38: =Vulnerability!A39 -> Chinook | B38: =Vulnerability!C39 -> Migration | C38: =Vulnerability!D39 -> Floodplain Condition | D38: =MIN(Vulnerability!E39,Vulnerability!E52) -> 6 | E38: =MAX(Vulnerability!E39,Vulnerability!E52) -> 8 | F38: =MIN(Vulnerability!F39,Vulnerability!F52) -> 0.55 | G38: =MAX(Vulnerability!F39,Vulnerability!F52) -> 0.67857143 | H38: =MAX(Vulnerability!F39,Vulnerability!F52) -> 0.67857143 | I38: =COUNTA(Vulnerability!A39,Vulnerability!A52) -> 2 | J38: =Vulnerability!B39&" | "&Vulnerability!B52 -> Adult Migration & Holding | Juvenile Emigration
A39: =Vulnerability!A41 -> Chinook | B39: =Vulnerability!C41 -> Migration | C39: =Vulnerability!D41 -> Increased Sediment Quantity | D39: =MIN(Vulnerability!E41,Vulnerability!E57) -> 10 | E39: =MAX(Vulnerability!E41,Vulnerability!E57) -> 11 | F39: =MIN(Vulnerability!F41,Vulnerability!F57) -> 0.35714286 | G39: =MAX(Vulnerability!F41,Vulnerability!F57) -> 0.42142857 | H39: =MAX(Vulnerability!F41,Vulnerability!F57) -> 0.42142857 | I39: =COUNTA(Vulnerability!A41,Vulnerability!A57) -> 2 | J39: =Vulnerability!B41&" | "&Vulnerability!B57 -> Adult Migration & Holding | Juvenile Emigration
A40: =Vulnerability!A43 -> Chinook | B40: =Vulnerability!C43 -> Migration | C40: =Vulnerability!D43 -> Non-Native Species Interactions and Competition | D40: =MIN(Vulnerability!E43,Vulnerability!E54) -> 8 | E40: =MAX(Vulnerability!E43,Vulnerability!E54) -> 12 | F40: =MIN(Vulnerability!F43,Vulnerability!F54) -> 0.29285714 | G40: =MAX(Vulnerability!F43,Vulnerability!F54) -> 0.55 | H40: =MAX(Vulnerability!F43,Vulnerability!F54) -> 0.55 | I40: =COUNTA(Vulnerability!A43,Vulnerability!A54) -> 2 | J40: =Vulnerability!B43&" | "&Vulnerability!B54 -> Adult Migration & Holding | Juvenile Emigration
...

Sheet L1 Calculation Grid
A1: bsr | B1: basin | C1: species | D1: life_stage | E1: limiting_factor | F1: fish_use_score | G1: population_priority | H1: condition_score_raw_1_5 | I1: condition_score | J1: vulnerability_rank_min | K1: vulnerability_rank_max | L1: vulnerability_score | M1: impact_component | N1: risk_component
A2: ='Fish Use'!A2 -> CC1 | B2: ='Fish Use'!B2 -> Catherine Creek | C2: ='Fish Use'!D2 -> Chinook | D2: ='Fish Use'!E2 -> Spawning | E2: ='Vulnerability Mapped'!C49 -> Anthropogenic Barriers | F2: ='Fish Use'!F2 -> 0.4162 | G2: =Population!D2 -> 0.12 | H2: ='Limiting Factors'!C8 -> 3.68 | I2: ='Limiting Factors'!D8 -> 0.703 | J2: ='Vulnerability Mapped'!D49 -> 15 | K2: ='Vulnerability Mapped'!E49 -> 15 | L2: ='Vulnerability Mapped'!H49 -> 0.1 | M2: =F2*I2*L2 -> 0.02925886 | N2: =M2*G2 -> 0.0035110632
A3: ='Fish Use'!A2 -> CC1 | B3: ='Fish Use'!B2 -> Catherine Creek | C3: ='Fish Use'!D2 -> Chinook | D3: ='Fish Use'!E2 -> Spawning | E3: ='Vulnerability Mapped'!C57 -> Riparian Condition | F3: ='Fish Use'!F2 -> 0.4162 | G3: =Population!D2 -> 0.12 | H3: ='Limiting Factors'!C2 -> 4.57 | I3: ='Limiting Factors'!D2 -> 0.90325 | J3: ='Vulnerability Mapped'!D57 -> 13 | K3: ='Vulnerability Mapped'!E57 -> 13 | L3: ='Vulnerability Mapped'!H57 -> 0.22857143 | M3: =F3*I3*L3 -> 0.085927463 | N3: =M3*G3 -> 0.010311296
A4: ='Fish Use'!A2 -> CC1 | B4: ='Fish Use'!B2 -> Catherine Creek | C4: ='Fish Use'!D2 -> Chinook | D4: ='Fish Use'!E2 -> Spawning | E4: ='Vulnerability Mapped'!C53 -> Floodplain Condition | F4: ='Fish Use'!F2 -> 0.4162 | G4: =Population!D2 -> 0.12 | H4: ='Limiting Factors'!C3 -> 4.78 | I4: ='Limiting Factors'!D3 -> 0.9505 | J4: ='Vulnerability Mapped'!D53 -> 6 | K4: ='Vulnerability Mapped'!E53 -> 6 | L4: ='Vulnerability Mapped'!H53 -> 0.67857143 | M4: =F4*I4*L4 -> 0.26844157 | N4: =M4*G4 -> 0.032212988
A5: ='Fish Use'!A2 -> CC1 | B5: ='Fish Use'!B2 -> Catherine Creek | C5: ='Fish Use'!D2 -> Chinook | D5: ='Fish Use'!E2 -> Spawning | E5: ='Vulnerability Mapped'!C58 -> Side Channel and Wetland Habitat | F5: ='Fish Use'!F2 -> 0.4162 | G5: =Population!D2 -> 0.12 | H5: ='Limiting Factors'!C4 -> 4.08 | I5: ='Limiting Factors'!D4 -> 0.793 | J5: ='Vulnerability Mapped'!D58 -> 7 | K5: ='Vulnerability Mapped'!E58 -> 7 | L5: ='Vulnerability Mapped'!H58 -> 0.61428571 | M5: =F5*I5*L5 -> 0.20274291 | N5: =M5*G5 -> 0.024329149
A6: ='Fish Use'!A2 -> CC1 | B6: ='Fish Use'!B2 -> Catherine Creek | C6: ='Fish Use'!D2 -> Chinook | D6: ='Fish Use'!E2 -> Spawning | E6: ='Vulnerability Mapped'!C50 -> Channel and Habitat Structure | F6: ='Fish Use'!F2 -> 0.4162 | G6: =Population!D2 -> 0.12 | H6: ='Limiting Factors'!C5 -> 4.57 | I6: ='Limiting Factors'!D5 -> 0.90325 | J6: ='Vulnerability Mapped'!D50 -> 5 | K6: ='Vulnerability Mapped'!E50 -> 5 | L6: ='Vulnerability Mapped'!H50 -> 0.74285714 | M6: =F6*I6*L6 -> 0.27926425 | N6: =M6*G6 -> 0.033511711
A7: ='Fish Use'!A2 -> CC1 | B7: ='Fish Use'!B2 -> Catherine Creek | C7: ='Fish Use'!D2 -> Chinook | D7: ='Fish Use'!E2 -> Spawning | E7: ='Vulnerability Mapped'!C52 -> Decreased Water Quantity | F7: ='Fish Use'!F2 -> 0.4162 | G7: =Population!D2 -> 0.12 | H7: ='Limiting Factors'!C12 -> 5 | I7: ='Limiting Factors'!D12 -> 1 | J7: ='Vulnerability Mapped'!D52 -> 2 | K7: ='Vulnerability Mapped'!E52 -> 2 | L7: ='Vulnerability Mapped'!H52 -> 0.93571429 | M7: =F7*I7*L7 -> 0.38944429 | N7: =M7*G7 -> 0.046733314
A8: ='Fish Use'!A2 -> CC1 | B8: ='Fish Use'!B2 -> Catherine Creek | C8: ='Fish Use'!D2 -> Chinook | D8: ='Fish Use'!E2 -> Spawning | E8: ='Vulnerability Mapped'!C47 -> Altered Flow Timing | F8: ='Fish Use'!F2 -> 0.4162 | G8: =Population!D2 -> 0.12 | H8: ='Limiting Factors'!C13 -> 4.31 | I8: ='Limiting Factors'!D13 -> 0.84475 | J8: ='Vulnerability Mapped'!D47 -> 10 | K8: ='Vulnerability Mapped'!E47 -> 10 | L8: ='Vulnerability Mapped'!H47 -> 0.42142857 | M8: =F8*I8*L8 -> 0.14816794 | N8: =M8*G8 -> 0.017780153
A9: ='Fish Use'!A2 -> CC1 | B9: ='Fish Use'!B2 -> Catherine Creek | C9: ='Fish Use'!D2 -> Chinook | D9: ='Fish Use'!E2 -> Spawning | E9: ='Vulnerability Mapped'!C51 -> Decreased Sediment Quantity | F9: ='Fish Use'!F2 -> 0.4162 | G9: =Population!D2 -> 0.12 | H9: ='Limiting Factors'!C6 -> 2.95 | I9: ='Limiting Factors'!D6 -> 0.53875 | J9: ='Vulnerability Mapped'!D51 -> 3 | K9: ='Vulnerability Mapped'!E51 -> 3 | L9: ='Vulnerability Mapped'!H51 -> 0.87142857 | M9: =F9*I9*L9 -> 0.19539847 | N9: =M9*G9 -> 0.023447816
A10: ='Fish Use'!A2 -> CC1 | B10: ='Fish Use'!B2 -> Catherine Creek | C10: ='Fish Use'!D2 -> Chinook | D10: ='Fish Use'!E2 -> Spawning | E10: ='Vulnerability Mapped'!C54 -> Increased Sediment Quantity | F10: ='Fish Use'!F2 -> 0.4162 | G10: =Population!D2 -> 0.12 | H10: ='Limiting Factors'!C7 -> 4.51 | I10: ='Limiting Factors'!D7 -> 0.88975 | J10: ='Vulnerability Mapped'!D54 -> 11 | K10: ='Vulnerability Mapped'!E54 -> 11 | L10: ='Vulnerability Mapped'!H54 -> 0.35714286 | M10: =F10*I10*L10 -> 0.13225498 | N10: =M10*G10 -> 0.015870598
A11: ='Fish Use'!A2 -> CC1 | B11: ='Fish Use'!B2 -> Catherine Creek | C11: ='Fish Use'!D2 -> Chinook | D11: ='Fish Use'!E2 -> Spawning | E11: ='Vulnerability Mapped'!C59 -> Summer Water Temperature | F11: ='Fish Use'!F2 -> 0.4162 | G11: =Population!D2 -> 0.12 | H11: ='Limiting Factors'!C14 -> 4.64 | I11: ='Limiting Factors'!D14 -> 0.919 | J11: ='Vulnerability Mapped'!D59 -> 1 | K11: ='Vulnerability Mapped'!E59 -> 1 | L11: ='Vulnerability Mapped'!H59 -> 1 | M11: =F11*I11*L11 -> 0.3824878 | N11: =M11*G11 -> 0.045898536
A12: ='Fish Use'!A2 -> CC1 | B12: ='Fish Use'!B2 -> Catherine Creek | C12: ='Fish Use'!D2 -> Chinook | D12: ='Fish Use'!E2 -> Spawning | E12: ='Vulnerability Mapped'!C61 -> Winter Water Temperature | F12: ='Fish Use'!F2 -> 0.4162 | G12: =Population!D2 -> 0.12 | H12: ='Limiting Factors'!C15 -> 3.91 | I12: ='Limiting Factors'!D15 -> 0.75475 | J12: ='Vulnerability Mapped'!D61 -> 4 | K12: ='Vulnerability Mapped'!E61 -> 4 | L12: ='Vulnerability Mapped'!H61 -> 0.80714286 | M12: =F12*I12*L12 -> 0.25354532 | N12: =M12*G12 -> 0.030425439
A13: ='Fish Use'!A2 -> CC1 | B13: ='Fish Use'!B2 -> Catherine Creek | C13: ='Fish Use'!D2 -> Chinook | D13: ='Fish Use'!E2 -> Spawning | E13: ='Vulnerability Mapped'!C60 -> Water Quality | F13: ='Fish Use'!F2 -> 0.4162 | G13: =Population!D2 -> 0.12 | H13: ='Limiting Factors'!C16 -> 5 | I13: ='Limiting Factors'!D16 -> 1 | J13: ='Vulnerability Mapped'!D60 -> 8 | K13: ='Vulnerability Mapped'!E60 -> 8 | L13: ='Vulnerability Mapped'!H60 -> 0.55 | M13: =F13*I13*L13 -> 0.22891 | N13: =M13*G13 -> 0.0274692
A14: ='Fish Use'!A2 -> CC1 | B14: ='Fish Use'!B2 -> Catherine Creek | C14: ='Fish Use'!D2 -> Chinook | D14: ='Fish Use'!E2 -> Spawning | E14: ='Vulnerability Mapped'!C56 -> Predation | F14: ='Fish Use'!F2 -> 0.4162 | G14: =Population!D2 -> 0.12 | H14: ='Limiting Factors'!C9 -> 4.22 | I14: ='Limiting Factors'!D9 -> 0.8245 | J14: ='Vulnerability Mapped'!D56 -> 9 | K14: ='Vulnerability Mapped'!E56 -> 9 | L14: ='Vulnerability Mapped'!H56 -> 0.48571429 | M14: =F14*I14*L14 -> 0.16667621 | N14: =M14*G14 -> 0.020001145
A15: ='Fish Use'!A2 -> CC1 | B15: ='Fish Use'!B2 -> Catherine Creek | C15: ='Fish Use'!D2 -> Chinook | D15: ='Fish Use'!E2 -> Spawning | E15: ='Vulnerability Mapped'!C48 -> Altered Primary Productivity | F15: ='Fish Use'!F2 -> 0.4162 | G15: =Population!D2 -> 0.12 | H15: ='Limiting Factors'!C10 -> 4.31 | I15: ='Limiting Factors'!D10 -> 0.84475 | J15: ='Vulnerability Mapped'!D48 -> 14 | K15: ='Vulnerability Mapped'!E48 -> 14 | L15: ='Vulnerability Mapped'!H48 -> 0.16428571 | M15: =F15*I15*L15 -> 0.057760385 | N15: =M15*G15 -> 0.0069312461
A16: ='Fish Use'!A2 -> CC1 | B16: ='Fish Use'!B2 -> Catherine Creek | C16: ='Fish Use'!D2 -> Chinook | D16: ='Fish Use'!E2 -> Spawning | E16: ='Vulnerability Mapped'!C55 -> Non-Native Species Interactions and Competition | F16: ='Fish Use'!F2 -> 0.4162 | G16: =Population!D2 -> 0.12 | H16: ='Limiting Factors'!C11 -> 4.64 | I16: ='Limiting Factors'!D11 -> 0.919 | J16: ='Vulnerability Mapped'!D55 -> 12 | K16: ='Vulnerability Mapped'!E55 -> 12 | L16: ='Vulnerability Mapped'!H55 -> 0.29285714 | M16: =F16*I16*L16 -> 0.11201428 | N16: =M16*G16 -> 0.013441714
A17: ='Fish Use'!A3 -> CC1 | B17: ='Fish Use'!B3 -> Catherine Creek | C17: ='Fish Use'!D3 -> Chinook | D17: ='Fish Use'!E3 -> Winter Rearing | E17: ='Vulnerability Mapped'!C79 -> Anthropogenic Barriers | F17: ='Fish Use'!F3 -> 0.4162 | G17: =Population!D6 -> 0.36 | H17: ='Limiting Factors'!C8 -> 3.68 | I17: ='Limiting Factors'!D8 -> 0.703 | J17: ='Vulnerability Mapped'!D79 -> 14 | K17: ='Vulnerability Mapped'!E79 -> 14 | L17: ='Vulnerability Mapped'!H79 -> 0.16428571 | M17: =F17*I17*L17 -> 0.048068127 | N17: =M17*G17 -> 0.017304526
A18: ='Fish Use'!A3 -> CC1 | B18: ='Fish Use'!B3 -> Catherine Creek | C18: ='Fish Use'!D3 -> Chinook | D18: ='Fish Use'!E3 -> Winter Rearing | E18: ='Vulnerability Mapped'!C87 -> Riparian Condition | F18: ='Fish Use'!F3 -> 0.4162 | G18: =Population!D6 -> 0.36 | H18: ='Limiting Factors'!C2 -> 4.57 | I18: ='Limiting Factors'!D2 -> 0.90325 | J18: ='Vulnerability Mapped'!D87 -> 6 | K18: ='Vulnerability Mapped'!E87 -> 6 | L18: ='Vulnerability Mapped'!H87 -> 0.67857143 | M18: =F18*I18*L18 -> 0.25509716 | N18: =M18*G18 -> 0.091834976
A19: ='Fish Use'!A3 -> CC1 | B19: ='Fish Use'!B3 -> Catherine Creek | C19: ='Fish Use'!D3 -> Chinook | D19: ='Fish Use'!E3 -> Winter Rearing | E19: ='Vulnerability Mapped'!C83 -> Floodplain Condition | F19: ='Fish Use'!F3 -> 0.4162 | G19: =Population!D6 -> 0.36 | H19: ='Limiting Factors'!C3 -> 4.78 | I19: ='Limiting Factors'!D3 -> 0.9505 | J19: ='Vulnerability Mapped'!D83 -> 5 | K19: ='Vulnerability Mapped'!E83 -> 5 | L19: ='Vulnerability Mapped'!H83 -> 0.74285714 | M19: =F19*I19*L19 -> 0.29387287 | N19: =M19*G19 -> 0.10579423
A20: ='Fish Use'!A3 -> CC1 | B20: ='Fish Use'!B3 -> Catherine Creek | C20: ='Fish Use'!D3 -> Chinook | D20: ='Fish Use'!E3 -> Winter Rearing | E20: ='Vulnerability Mapped'!C88 -> Side Channel and Wetland Habitat | F20: ='Fish Use'!F3 -> 0.4162 | G20: =Population!D6 -> 0.36 | H20: ='Limiting Factors'!C4 -> 4.08 | I20: ='Limiting Factors'!D4 -> 0.793 | J20: ='Vulnerability Mapped'!D88 -> 3 | K20: ='Vulnerability Mapped'!E88 -> 3 | L20: ='Vulnerability Mapped'!H88 -> 0.87142857 | M20: =F20*I20*L20 -> 0.28761204 | N20: =M20*G20 -> 0.10354033
A21: ='Fish Use'!A3 -> CC1 | B21: ='Fish Use'!B3 -> Catherine Creek | C21: ='Fish Use'!D3 -> Chinook | D21: ='Fish Use'!E3 -> Winter Rearing | E21: ='Vulnerability Mapped'!C80 -> Channel and Habitat Structure | F21: ='Fish Use'!F3 -> 0.4162 | G21: =Population!D6 -> 0.36 | H21: ='Limiting Factors'!C5 -> 4.57 | I21: ='Limiting Factors'!D5 -> 0.90325 | J21: ='Vulnerability Mapped'!D80 -> 1 | K21: ='Vulnerability Mapped'!E80 -> 1 | L21: ='Vulnerability Mapped'!H80 -> 1 | M21: =F21*I21*L21 -> 0.37593265 | N21: =M21*G21 -> 0.13533575
A22: ='Fish Use'!A3 -> CC1 | B22: ='Fish Use'!B3 -> Catherine Creek | C22: ='Fish Use'!D3 -> Chinook | D22: ='Fish Use'!E3 -> Winter Rearing | E22: ='Vulnerability Mapped'!C82 -> Decreased Water Quantity | F22: ='Fish Use'!F3 -> 0.4162 | G22: =Population!D6 -> 0.36 | H22: ='Limiting Factors'!C12 -> 5 | I22: ='Limiting Factors'!D12 -> 1 | J22: ='Vulnerability Mapped'!D82 -> 9 | K22: ='Vulnerability Mapped'!E82 -> 9 | L22: ='Vulnerability Mapped'!H82 -> 0.48571429 | M22: =F22*I22*L22 -> 0.20215429 | N22: =M22*G22 -> 0.072775543
A23: ='Fish Use'!A3 -> CC1 | B23: ='Fish Use'!B3 -> Catherine Creek | C23: ='Fish Use'!D3 -> Chinook | D23: ='Fish Use'!E3 -> Winter Rearing | E23: ='Vulnerability Mapped'!C77 -> Altered Flow Timing | F23: ='Fish Use'!F3 -> 0.4162 | G23: =Population!D6 -> 0.36 | H23: ='Limiting Factors'!C13 -> 4.31 | I23: ='Limiting Factors'!D13 -> 0.84475 | J23: ='Vulnerability Mapped'!D77 -> 13 | K23: ='Vulnerability Mapped'!E77 -> 13 | L23: ='Vulnerability Mapped'!H77 -> 0.22857143 | M23: =F23*I23*L23 -> 0.080362274 | N23: =M23*G23 -> 0.028930419
A24: ='Fish Use'!A3 -> CC1 | B24: ='Fish Use'!B3 -> Catherine Creek | C24: ='Fish Use'!D3 -> Chinook | D24: ='Fish Use'!E3 -> Winter Rearing | E24: ='Vulnerability Mapped'!C81 -> Decreased Sediment Quantity | F24: ='Fish Use'!F3 -> 0.4162 | G24: =Population!D6 -> 0.36 | H24: ='Limiting Factors'!C6 -> 2.95 | I24: ='Limiting Factors'!D6 -> 0.53875 | J24: ='Vulnerability Mapped'!D81 -> 4 | K24: ='Vulnerability Mapped'!E81 -> 4 | L24: ='Vulnerability Mapped'!H81 -> 0.80714286 | M24: =F24*I24*L24 -> 0.18098383 | N24: =M24*G24 -> 0.065154178
A25: ='Fish Use'!A3 -> CC1 | B25: ='Fish Use'!B3 -> Catherine Creek | C25: ='Fish Use'!D3 -> Chinook | D25: ='Fish Use'!E3 -> Winter Rearing | E25: ='Vulnerability Mapped'!C84 -> Increased Sediment Quantity | F25: ='Fish Use'!F3 -> 0.4162 | G25: =Population!D6 -> 0.36 | H25: ='Limiting Factors'!C7 -> 4.51 | I25: ='Limiting Factors'!D7 -> 0.88975 | J25: ='Vulnerability Mapped'!D84 -> 8 | K25: ='Vulnerability Mapped'!E84 -> 8 | L25: ='Vulnerability Mapped'!H84 -> 0.55 | M25: =F25*I25*L25 -> 0.20367267 | N25: =M25*G25 -> 0.073322162
A26: ='Fish Use'!A3 -> CC1 | B26: ='Fish Use'!B3 -> Catherine Creek | C26: ='Fish Use'!D3 -> Chinook | D26: ='Fish Use'!E3 -> Winter Rearing | E26: ='Vulnerability Mapped'!C89 -> Summer Water Temperature | F26: ='Fish Use'!F3 -> 0.4162 | G26: =Population!D6 -> 0.36 | H26: ='Limiting Factors'!C14 -> 4.64 | I26: ='Limiting Factors'!D14 -> 0.919 | J26: ='Vulnerability Mapped'!D89 -> 15 | K26: ='Vulnerability Mapped'!E89 -> 15 | L26: ='Vulnerability Mapped'!H89 -> 0.1 | M26: =F26*I26*L26 -> 0.03824878 | N26: =M26*G26 -> 0.013769561
A27: ='Fish Use'!A3 -> CC1 | B27: ='Fish Use'!B3 -> Catherine Creek | C27: ='Fish Use'!D3 -> Chinook | D27: ='Fish Use'!E3 -> Winter Rearing | E27: ='Vulnerability Mapped'!C91 -> Winter Water Temperature | F27: ='Fish Use'!F3 -> 0.4162 | G27: =Population!D6 -> 0.36 | H27: ='Limiting Factors'!C15 -> 3.91 | I27: ='Limiting Factors'!D15 -> 0.75475 | J27: ='Vulnerability Mapped'!D91 -> 2 | K27: ='Vulnerability Mapped'!E91 -> 2 | L27: ='Vulnerability Mapped'!H91 -> 0.93571429 | M27: =F27*I27*L27 -> 0.29393307 | N27: =M27*G27 -> 0.10581591
A28: ='Fish Use'!A3 -> CC1 | B28: ='Fish Use'!B3 -> Catherine Creek | C28: ='Fish Use'!D3 -> Chinook | D28: ='Fish Use'!E3 -> Winter Rearing | E28: ='Vulnerability Mapped'!C90 -> Water Quality | F28: ='Fish Use'!F3 -> 0.4162 | G28: =Population!D6 -> 0.36 | H28: ='Limiting Factors'!C16 -> 5 | I28: ='Limiting Factors'!D16 -> 1 | J28: ='Vulnerability Mapped'!D90 -> 7 | K28: ='Vulnerability Mapped'!E90 -> 7 | L28: ='Vulnerability Mapped'!H90 -> 0.61428571 | M28: =F28*I28*L28 -> 0.25566571 | N28: =M28*G28 -> 0.092039657
A29: ='Fish Use'!A3 -> CC1 | B29: ='Fish Use'!B3 -> Catherine Creek | C29: ='Fish Use'!D3 -> Chinook | D29: ='Fish Use'!E3 -> Winter Rearing | E29: ='Vulnerability Mapped'!C86 -> Predation | F29: ='Fish Use'!F3 -> 0.4162 | G29: =Population!D6 -> 0.36 | H29: ='Limiting Factors'!C9 -> 4.22 | I29: ='Limiting Factors'!D9 -> 0.8245 | J29: ='Vulnerability Mapped'!D86 -> 11 | K29: ='Vulnerability Mapped'!E86 -> 11 | L29: ='Vulnerability Mapped'!H86 -> 0.35714286 | M29: =F29*I29*L29 -> 0.12255604 | N29: =M29*G29 -> 0.044120173
A30: ='Fish Use'!A3 -> CC1 | B30: ='Fish Use'!B3 -> Catherine Creek | C30: ='Fish Use'!D3 -> Chinook | D30: ='Fish Use'!E3 -> Winter Rearing | E30: ='Vulnerability Mapped'!C78 -> Altered Primary Productivity | F30: ='Fish Use'!F3 -> 0.4162 | G30: =Population!D6 -> 0.36 | H30: ='Limiting Factors'!C10 -> 4.31 | I30: ='Limiting Factors'!D10 -> 0.84475 | J30: ='Vulnerability Mapped'!D78 -> 12 | K30: ='Vulnerability Mapped'!E78 -> 12 | L30: ='Vulnerability Mapped'!H78 -> 0.29285714 | M30: =F30*I30*L30 -> 0.10296416 | N30: =M30*G30 -> 0.037067099
A31: ='Fish Use'!A3 -> CC1 | B31: ='Fish Use'!B3 -> Catherine Creek | C31: ='Fish Use'!D3 -> Chinook | D31: ='Fish Use'!E3 -> Winter Rearing | E31: ='Vulnerability Mapped'!C85 -> Non-Native Species Interactions and Competition | F31: ='Fish Use'!F3 -> 0.4162 | G31: =Population!D6 -> 0.36 | H31: ='Limiting Factors'!C11 -> 4.64 | I31: ='Limiting Factors'!D11 -> 0.919 | J31: ='Vulnerability Mapped'!D85 -> 12 | K31: ='Vulnerability Mapped'!E85 -> 12 | L31: ='Vulnerability Mapped'!H85 -> 0.29285714 | M31: =F31*I31*L31 -> 0.11201428 | N31: =M31*G31 -> 0.040325142
A32: ='Fish Use'!A4 -> CC1 | B32: ='Fish Use'!B4 -> Catherine Creek | C32: ='Fish Use'!D4 -> Chinook | D32: ='Fish Use'!E4 -> Summer Rearing | E32: ='Vulnerability Mapped'!C64 -> Anthropogenic Barriers | F32: ='Fish Use'!F4 -> 0.4162 | G32: =Population!D4 -> 0.21 | H32: ='Limiting Factors'!C8 -> 3.68 | I32: ='Limiting Factors'!D8 -> 0.703 | J32: ='Vulnerability Mapped'!D64 -> 7 | K32: ='Vulnerability Mapped'!E64 -> 7 | L32: ='Vulnerability Mapped'!H64 -> 0.61428571 | M32: =F32*I32*L32 -> 0.179733 | N32: =M32*G32 -> 0.037743929
A33: ='Fish Use'!A4 -> CC1 | B33: ='Fish Use'!B4 -> Catherine Creek | C33: ='Fish Use'!D4 -> Chinook | D33: ='Fish Use'!E4 -> Summer Rearing | E33: ='Vulnerability Mapped'!C72 -> Riparian Condition | F33: ='Fish Use'!F4 -> 0.4162 | G33: =Population!D4 -> 0.21 | H33: ='Limiting Factors'!C2 -> 4.57 | I33: ='Limiting Factors'!D2 -> 0.90325 | J33: ='Vulnerability Mapped'!D72 -> 5 | K33: ='Vulnerability Mapped'!E72 -> 5 | L33: ='Vulnerability Mapped'!H72 -> 0.74285714 | M33: =F33*I33*L33 -> 0.27926425 | N33: =M33*G33 -> 0.058645493
A34: ='Fish Use'!A4 -> CC1 | B34: ='Fish Use'!B4 -> Catherine Creek | C34: ='Fish Use'!D4 -> Chinook | D34: ='Fish Use'!E4 -> Summer Rearing | E34: ='Vulnerability Mapped'!C68 -> Floodplain Condition | F34: ='Fish Use'!F4 -> 0.4162 | G34: =Population!D4 -> 0.21 | H34: ='Limiting Factors'!C3 -> 4.78 | I34: ='Limiting Factors'!D3 -> 0.9505 | J34: ='Vulnerability Mapped'!D68 -> 10 | K34: ='Vulnerability Mapped'!E68 -> 10 | L34: ='Vulnerability Mapped'!H68 -> 0.42142857 | M34: =F34*I34*L34 -> 0.16671634 | N34: =M34*G34 -> 0.035010432
A35: ='Fish Use'!A4 -> CC1 | B35: ='Fish Use'!B4 -> Catherine Creek | C35: ='Fish Use'!D4 -> Chinook | D35: ='Fish Use'!E4 -> Summer Rearing | E35: ='Vulnerability Mapped'!C73 -> Side Channel and Wetland Habitat | F35: ='Fish Use'!F4 -> 0.4162 | G35: =Population!D4 -> 0.21 | H35: ='Limiting Factors'!C4 -> 4.08 | I35: ='Limiting Factors'!D4 -> 0.793 | J35: ='Vulnerability Mapped'!D73 -> 4 | K35: ='Vulnerability Mapped'!E73 -> 4 | L35: ='Vulnerability Mapped'!H73 -> 0.80714286 | M35: =F35*I35*L35 -> 0.26639476 | N35: =M35*G35 -> 0.055942899
A36: ='Fish Use'!A4 -> CC1 | B36: ='Fish Use'!B4 -> Catherine Creek | C36: ='Fish Use'!D4 -> Chinook | D36: ='Fish Use'!E4 -> Summer Rearing | E36: ='Vulnerability Mapped'!C65 -> Channel and Habitat Structure | F36: ='Fish Use'!F4 -> 0.4162 | G36: =Population!D4 -> 0.21 | H36: ='Limiting Factors'!C5 -> 4.57 | I36: ='Limiting Factors'!D5 -> 0.90325 | J36: ='Vulnerability Mapped'!D65 -> 3 | K36: ='Vulnerability Mapped'!E65 -> 3 | L36: ='Vulnerability Mapped'!H65 -> 0.87142857 | M36: =F36*I36*L36 -> 0.32759845 | N36: =M36*G36 -> 0.068795675
A37: ='Fish Use'!A4 -> CC1 | B37: ='Fish Use'!B4 -> Catherine Creek | C37: ='Fish Use'!D4 -> Chinook | D37: ='Fish Use'!E4 -> Summer Rearing | E37: ='Vulnerability Mapped'!C67 -> Decreased Water Quantity | F37: ='Fish Use'!F4 -> 0.4162 | G37: =Population!D4 -> 0.21 | H37: ='Limiting Factors'!C12 -> 5 | I37: ='Limiting Factors'!D12 -> 1 | J37: ='Vulnerability Mapped'!D67 -> 2 | K37: ='Vulnerability Mapped'!E67 -> 2 | L37: ='Vulnerability Mapped'!H67 -> 0.93571429 | M37: =F37*I37*L37 -> 0.38944429 | N37: =M37*G37 -> 0.0817833
A38: ='Fish Use'!A4 -> CC1 | B38: ='Fish Use'!B4 -> Catherine Creek | C38: ='Fish Use'!D4 -> Chinook | D38: ='Fish Use'!E4 -> Summer Rearing | E38: ='Vulnerability Mapped'!C62 -> Altered Flow Timing | F38: ='Fish Use'!F4 -> 0.4162 | G38: =Population!D4 -> 0.21 | H38: ='Limiting Factors'!C13 -> 4.31 | I38: ='Limiting Factors'!D13 -> 0.84475 | J38: ='Vulnerability Mapped'!D62 -> 6 | K38: ='Vulnerability Mapped'!E62 -> 6 | L38: ='Vulnerability Mapped'!H62 -> 0.67857143 | M38: =F38*I38*L38 -> 0.2385755 | N38: =M38*G38 -> 0.050100855
A39: ='Fish Use'!A4 -> CC1 | B39: ='Fish Use'!B4 -> Catherine Creek | C39: ='Fish Use'!D4 -> Chinook | D39: ='Fish Use'!E4 -> Summer Rearing | E39: ='Vulnerability Mapped'!C66 -> Decreased Sediment Quantity | F39: ='Fish Use'!F4 -> 0.4162 | G39: =Population!D4 -> 0.21 | H39: ='Limiting Factors'!C6 -> 2.95 | I39: ='Limiting Factors'!D6 -> 0.53875 | J39: ='Vulnerability Mapped'!D66 -> 12 | K39: ='Vulnerability Mapped'!E66 -> 12 | L39: ='Vulnerability Mapped'!H66 -> 0.29285714 | M39: =F39*I39*L39 -> 0.065666698 | N39: =M39*G39 -> 0.013790007
A40: ='Fish Use'!A4 -> CC1 | B40: ='Fish Use'!B4 -> Catherine Creek | C40: ='Fish Use'!D4 -> Chinook | D40: ='Fish Use'!E4 -> Summer Rearing | E40: ='Vulnerability Mapped'!C69 -> Increased Sediment Quantity | F40: ='Fish Use'!F4 -> 0.4162 | G40: =Population!D4 -> 0.21 | H40: ='Limiting Factors'!C7 -> 4.51 | I40: ='Limiting Factors'!D7 -> 0.88975 | J40: ='Vulnerability Mapped'!D69 -> 14 | K40: ='Vulnerability Mapped'!E69 -> 14 | L40: ='Vulnerability Mapped'!H69 -> 0.16428571 | M40: =F40*I40*L40 -> 0.060837292 | N40: =M40*G40 -> 0.012775831
...

Sheet Life Stage Scores
A1: bsr | B1: basin | C1: species | D1: life_stage | E1: fish_use_score | F1: population_priority | G1: impact_score | H1: risk_score | I1: risk_rank_within_bsr | J1: priority_label
A2: ='Fish Use'!A11 -> CC1 | B2: ='Fish Use'!B11 -> Catherine Creek | C2: ='Fish Use'!D11 -> Bull Trout | D2: ='Fish Use'!E11 -> FMO | E2: ='Fish Use'!F11 -> 0.4162 | F2: =Population!D19 -> 0.4 | G2: =SUM('L1 Calculation Grid'!$M$137:$M$151) -> 3.0097124 | H2: =SUM('L1 Calculation Grid'!$N$137:$N$151) -> 1.203885 | I2: =1+IF($H$2>H2,1,0)+IF(AND($H$3>H2,COUNTIF($H$2:$H$2,$H$3)=0),1,0)+IF(AND($H$4>H2,COUNTIF($H$2:$H$3,$H$4)=0),1,0)+IF(AND($H$5>H2,COUNTIF($H$2:$H$4,$H$5)=0),1,0)+IF(AND($H$6>H2,COUNTIF($H$2:$H$5,$H$6)=0),1,0)+IF(AND($H$7>H2,COUNTIF($H$2:$H$6,$H$7)=0),1,0)+IF(AND($H$8>H2,COUNTIF($H$2:$H$7,$H$8)=0),1,0)+IF(AND($H$9>H2,COUNTIF($H$2:$H$8,$H$9)=0),1,0)+IF(AND($H$10>H2,COUNTIF($H$2:$H$9,$H$10)=0),1,0)+IF(AND($H$11>H2,COUNTIF($H$2:$H$10,$H$11)=0),1,0) -> 2 | J2: =C2&" | "&D2 -> Bull Trout | FMO
A3: ='Fish Use'!A10 -> CC1 | B3: ='Fish Use'!B10 -> Catherine Creek | C3: ='Fish Use'!D10 -> Bull Trout | D3: ='Fish Use'!E10 -> Spawning & Resident | E3: ='Fish Use'!F10 -> 0.4162 | F3: =Population!D18 -> 0.6 | G3: =SUM('L1 Calculation Grid'!$M$122:$M$136) -> 2.9239269 | H3: =SUM('L1 Calculation Grid'!$N$122:$N$136) -> 1.7543561 | I3: =1+IF($H$2>H3,1,0)+IF(AND($H$3>H3,COUNTIF($H$2:$H$2,$H$3)=0),1,0)+IF(AND($H$4>H3,COUNTIF($H$2:$H$3,$H$4)=0),1,0)+IF(AND($H$5>H3,COUNTIF($H$2:$H$4,$H$5)=0),1,0)+IF(AND($H$6>H3,COUNTIF($H$2:$H$5,$H$6)=0),1,0)+IF(AND($H$7>H3,COUNTIF($H$2:$H$6,$H$7)=0),1,0)+IF(AND($H$8>H3,COUNTIF($H$2:$H$7,$H$8)=0),1,0)+IF(AND($H$9>H3,COUNTIF($H$2:$H$8,$H$9)=0),1,0)+IF(AND($H$10>H3,COUNTIF($H$2:$H$9,$H$10)=0),1,0)+IF(AND($H$11>H3,COUNTIF($H$2:$H$10,$H$11)=0),1,0) -> 1 | J3: =C3&" | "&D3 -> Bull Trout | Spawning & Resident
A4: ='Fish Use'!A5 -> CC1 | B4: ='Fish Use'!B5 -> Catherine Creek | C4: ='Fish Use'!D5 -> Chinook | D4: ='Fish Use'!E5 -> Migration | E4: ='Fish Use'!F5 -> 0.4162 | F4: =Population!D8 -> 0.3 | G4: =SUM('L1 Calculation Grid'!$M$47:$M$61) -> 3.7104579 | H4: =SUM('L1 Calculation Grid'!$N$47:$N$61) -> 1.1131374 | I4: =1+IF($H$2>H4,1,0)+IF(AND($H$3>H4,COUNTIF($H$2:$H$2,$H$3)=0),1,0)+IF(AND($H$4>H4,COUNTIF($H$2:$H$3,$H$4)=0),1,0)+IF(AND($H$5>H4,COUNTIF($H$2:$H$4,$H$5)=0),1,0)+IF(AND($H$6>H4,COUNTIF($H$2:$H$5,$H$6)=0),1,0)+IF(AND($H$7>H4,COUNTIF($H$2:$H$6,$H$7)=0),1,0)+IF(AND($H$8>H4,COUNTIF($H$2:$H$7,$H$8)=0),1,0)+IF(AND($H$9>H4,COUNTIF($H$2:$H$8,$H$9)=0),1,0)+IF(AND($H$10>H4,COUNTIF($H$2:$H$9,$H$10)=0),1,0)+IF(AND($H$11>H4,COUNTIF($H$2:$H$10,$H$11)=0),1,0) -> 3 | J4: =C4&" | "&D4 -> Chinook | Migration
A5: ='Fish Use'!A2 -> CC1 | B5: ='Fish Use'!B2 -> Catherine Creek | C5: ='Fish Use'!D2 -> Chinook | D5: ='Fish Use'!E2 -> Spawning | E5: ='Fish Use'!F2 -> 0.4162 | F5: =Population!D2 -> 0.12 | G5: =SUM('L1 Calculation Grid'!$M$2:$M$16) -> 2.9322947 | H5: =SUM('L1 Calculation Grid'!$N$2:$N$16) -> 0.35187537 | I5: =1+IF($H$2>H5,1,0)+IF(AND($H$3>H5,COUNTIF($H$2:$H$2,$H$3)=0),1,0)+IF(AND($H$4>H5,COUNTIF($H$2:$H$3,$H$4)=0),1,0)+IF(AND($H$5>H5,COUNTIF($H$2:$H$4,$H$5)=0),1,0)+IF(AND($H$6>H5,COUNTIF($H$2:$H$5,$H$6)=0),1,0)+IF(AND($H$7>H5,COUNTIF($H$2:$H$6,$H$7)=0),1,0)+IF(AND($H$8>H5,COUNTIF($H$2:$H$7,$H$8)=0),1,0)+IF(AND($H$9>H5,COUNTIF($H$2:$H$8,$H$9)=0),1,0)+IF(AND($H$10>H5,COUNTIF($H$2:$H$9,$H$10)=0),1,0)+IF(AND($H$11>H5,COUNTIF($H$2:$H$10,$H$11)=0),1,0) -> 10 | J5: =C5&" | "&D5 -> Chinook | Spawning
A6: ='Fish Use'!A4 -> CC1 | B6: ='Fish Use'!B4 -> Catherine Creek | C6: ='Fish Use'!D4 -> Chinook | D6: ='Fish Use'!E4 -> Summer Rearing | E6: ='Fish Use'!F4 -> 0.4162 | F6: =Population!D4 -> 0.21 | G6: =SUM('L1 Calculation Grid'!$M$32:$M$46) -> 2.9986957 | H6: =SUM('L1 Calculation Grid'!$N$32:$N$46) -> 0.6297261 | I6: =1+IF($H$2>H6,1,0)+IF(AND($H$3>H6,COUNTIF($H$2:$H$2,$H$3)=0),1,0)+IF(AND($H$4>H6,COUNTIF($H$2:$H$3,$H$4)=0),1,0)+IF(AND($H$5>H6,COUNTIF($H$2:$H$4,$H$5)=0),1,0)+IF(AND($H$6>H6,COUNTIF($H$2:$H$5,$H$6)=0),1,0)+IF(AND($H$7>H6,COUNTIF($H$2:$H$6,$H$7)=0),1,0)+IF(AND($H$8>H6,COUNTIF($H$2:$H$7,$H$8)=0),1,0)+IF(AND($H$9>H6,COUNTIF($H$2:$H$8,$H$9)=0),1,0)+IF(AND($H$10>H6,COUNTIF($H$2:$H$9,$H$10)=0),1,0)+IF(AND($H$11>H6,COUNTIF($H$2:$H$10,$H$11)=0),1,0) -> 9 | J6: =C6&" | "&D6 -> Chinook | Summer Rearing
A7: ='Fish Use'!A3 -> CC1 | B7: ='Fish Use'!B3 -> Catherine Creek | C7: ='Fish Use'!D3 -> Chinook | D7: ='Fish Use'!E3 -> Winter Rearing | E7: ='Fish Use'!F3 -> 0.4162 | F7: =Population!D6 -> 0.36 | G7: =SUM('L1 Calculation Grid'!$M$17:$M$31) -> 2.853138 | H7: =SUM('L1 Calculation Grid'!$N$17:$N$31) -> 1.0271297 | I7: =1+IF($H$2>H7,1,0)+IF(AND($H$3>H7,COUNTIF($H$2:$H$2,$H$3)=0),1,0)+IF(AND($H$4>H7,COUNTIF($H$2:$H$3,$H$4)=0),1,0)+IF(AND($H$5>H7,COUNTIF($H$2:$H$4,$H$5)=0),1,0)+IF(AND($H$6>H7,COUNTIF($H$2:$H$5,$H$6)=0),1,0)+IF(AND($H$7>H7,COUNTIF($H$2:$H$6,$H$7)=0),1,0)+IF(AND($H$8>H7,COUNTIF($H$2:$H$7,$H$8)=0),1,0)+IF(AND($H$9>H7,COUNTIF($H$2:$H$8,$H$9)=0),1,0)+IF(AND($H$10>H7,COUNTIF($H$2:$H$9,$H$10)=0),1,0)+IF(AND($H$11>H7,COUNTIF($H$2:$H$10,$H$11)=0),1,0) -> 4 | J7: =C7&" | "&D7 -> Chinook | Winter Rearing
A8: ='Fish Use'!A9 -> CC1 | B8: ='Fish Use'!B9 -> Catherine Creek | C8: ='Fish Use'!D9 -> Steelhead | D8: ='Fish Use'!E9 -> Migration | E8: ='Fish Use'!F9 -> 0.4162 | F8: =Population!D9 -> 0.25 | G8: =SUM('L1 Calculation Grid'!$M$107:$M$121) -> 3.4164126 | H8: =SUM('L1 Calculation Grid'!$N$107:$N$121) -> 0.85410316 | I8: =1+IF($H$2>H8,1,0)+IF(AND($H$3>H8,COUNTIF($H$2:$H$2,$H$3)=0),1,0)+IF(AND($H$4>H8,COUNTIF($H$2:$H$3,$H$4)=0),1,0)+IF(AND($H$5>H8,COUNTIF($H$2:$H$4,$H$5)=0),1,0)+IF(AND($H$6>H8,COUNTIF($H$2:$H$5,$H$6)=0),1,0)+IF(AND($H$7>H8,COUNTIF($H$2:$H$6,$H$7)=0),1,0)+IF(AND($H$8>H8,COUNTIF($H$2:$H$7,$H$8)=0),1,0)+IF(AND($H$9>H8,COUNTIF($H$2:$H$8,$H$9)=0),1,0)+IF(AND($H$10>H8,COUNTIF($H$2:$H$9,$H$10)=0),1,0)+IF(AND($H$11>H8,COUNTIF($H$2:$H$10,$H$11)=0),1,0) -> 5 | J8: =C8&" | "&D8 -> Steelhead | Migration
A9: ='Fish Use'!A6 -> CC1 | B9: ='Fish Use'!B6 -> Catherine Creek | C9: ='Fish Use'!D6 -> Steelhead | D9: ='Fish Use'!E6 -> Spawning | E9: ='Fish Use'!F6 -> 0.4162 | F9: =Population!D3 -> 0.25 | G9: =SUM('L1 Calculation Grid'!$M$62:$M$76) -> 2.9179671 | H9: =SUM('L1 Calculation Grid'!$N$62:$N$76) -> 0.72949176 | I9: =1+IF($H$2>H9,1,0)+IF(AND($H$3>H9,COUNTIF($H$2:$H$2,$H$3)=0),1,0)+IF(AND($H$4>H9,COUNTIF($H$2:$H$3,$H$4)=0),1,0)+IF(AND($H$5>H9,COUNTIF($H$2:$H$4,$H$5)=0),1,0)+IF(AND($H$6>H9,COUNTIF($H$2:$H$5,$H$6)=0),1,0)+IF(AND($H$7>H9,COUNTIF($H$2:$H$6,$H$7)=0),1,0)+IF(AND($H$8>H9,COUNTIF($H$2:$H$7,$H$8)=0),1,0)+IF(AND($H$9>H9,COUNTIF($H$2:$H$8,$H$9)=0),1,0)+IF(AND($H$10>H9,COUNTIF($H$2:$H$9,$H$10)=0),1,0)+IF(AND($H$11>H9,COUNTIF($H$2:$H$10,$H$11)=0),1,0) -> 8 | J9: =C9&" | "&D9 -> Steelhead | Spawning
A10: ='Fish Use'!A8 -> CC1 | B10: ='Fish Use'!B8 -> Catherine Creek | C10: ='Fish Use'!D8 -> Steelhead | D10: ='Fish Use'!E8 -> Summer Rearing | E10: ='Fish Use'!F8 -> 0.4162 | F10: =Population!D5 -> 0.25 | G10: =SUM('L1 Calculation Grid'!$M$92:$M$106) -> 2.9731106 | H10: =SUM('L1 Calculation Grid'!$N$92:$N$106) -> 0.74327764 | I10: =1+IF($H$2>H10,1,0)+IF(AND($H$3>H10,COUNTIF($H$2:$H$2,$H$3)=0),1,0)+IF(AND($H$4>H10,COUNTIF($H$2:$H$3,$H$4)=0),1,0)+IF(AND($H$5>H10,COUNTIF($H$2:$H$4,$H$5)=0),1,0)+IF(AND($H$6>H10,COUNTIF($H$2:$H$5,$H$6)=0),1,0)+IF(AND($H$7>H10,COUNTIF($H$2:$H$6,$H$7)=0),1,0)+IF(AND($H$8>H10,COUNTIF($H$2:$H$7,$H$8)=0),1,0)+IF(AND($H$9>H10,COUNTIF($H$2:$H$8,$H$9)=0),1,0)+IF(AND($H$10>H10,COUNTIF($H$2:$H$9,$H$10)=0),1,0)+IF(AND($H$11>H10,COUNTIF($H$2:$H$10,$H$11)=0),1,0) -> 6 | J10: =C10&" | "&D10 -> Steelhead | Summer Rearing
A11: ='Fish Use'!A7 -> CC1 | B11: ='Fish Use'!B7 -> Catherine Creek | C11: ='Fish Use'!D7 -> Steelhead | D11: ='Fish Use'!E7 -> Winter Rearing | E11: ='Fish Use'!F7 -> 0.4162 | F11: =Population!D7 -> 0.25 | G11: =SUM('L1 Calculation Grid'!$M$77:$M$91) -> 2.9716056 | H11: =SUM('L1 Calculation Grid'!$N$77:$N$91) -> 0.74290139 | I11: =1+IF($H$2>H11,1,0)+IF(AND($H$3>H11,COUNTIF($H$2:$H$2,$H$3)=0),1,0)+IF(AND($H$4>H11,COUNTIF($H$2:$H$3,$H$4)=0),1,0)+IF(AND($H$5>H11,COUNTIF($H$2:$H$4,$H$5)=0),1,0)+IF(AND($H$6>H11,COUNTIF($H$2:$H$5,$H$6)=0),1,0)+IF(AND($H$7>H11,COUNTIF($H$2:$H$6,$H$7)=0),1,0)+IF(AND($H$8>H11,COUNTIF($H$2:$H$7,$H$8)=0),1,0)+IF(AND($H$9>H11,COUNTIF($H$2:$H$8,$H$9)=0),1,0)+IF(AND($H$10>H11,COUNTIF($H$2:$H$9,$H$10)=0),1,0)+IF(AND($H$11>H11,COUNTIF($H$2:$H$10,$H$11)=0),1,0) -> 7 | J11: =C11&" | "&D11 -> Steelhead | Winter Rearing
A12: ='Fish Use'!A21 -> CC2 | B12: ='Fish Use'!B21 -> Catherine Creek | C12: ='Fish Use'!D21 -> Bull Trout | D12: ='Fish Use'!E21 -> FMO | E12: ='Fish Use'!F21 -> 0.2803 | F12: =Population!D19 -> 0.4 | G12: =SUM('L1 Calculation Grid'!$M$287:$M$301) -> 1.840167 | H12: =SUM('L1 Calculation Grid'!$N$287:$N$301) -> 0.7360668 | I12: =1+IF($H$12>H12,1,0)+IF(AND($H$13>H12,COUNTIF($H$12:$H$12,$H$13)=0),1,0)+IF(AND($H$14>H12,COUNTIF($H$12:$H$13,$H$14)=0),1,0)+IF(AND($H$15>H12,COUNTIF($H$12:$H$14,$H$15)=0),1,0)+IF(AND($H$16>H12,COUNTIF($H$12:$H$15,$H$16)=0),1,0)+IF(AND($H$17>H12,COUNTIF($H$12:$H$16,$H$17)=0),1,0)+IF(AND($H$18>H12,COUNTIF($H$12:$H$17,$H$18)=0),1,0)+IF(AND($H$19>H12,COUNTIF($H$12:$H$18,$H$19)=0),1,0)+IF(AND($H$20>H12,COUNTIF($H$12:$H$19,$H$20)=0),1,0)+IF(AND($H$21>H12,COUNTIF($H$12:$H$20,$H$21)=0),1,0) -> 2 | J12: =C12&" | "&D12 -> Bull Trout | FMO
A13: ='Fish Use'!A20 -> CC2 | B13: ='Fish Use'!B20 -> Catherine Creek | C13: ='Fish Use'!D20 -> Bull Trout | D13: ='Fish Use'!E20 -> Spawning & Resident | E13: ='Fish Use'!F20 -> 0.2803 | F13: =Population!D18 -> 0.6 | G13: =SUM('L1 Calculation Grid'!$M$272:$M$286) -> 1.7428223 | H13: =SUM('L1 Calculation Grid'!$N$272:$N$286) -> 1.0456934 | I13: =1+IF($H$12>H13,1,0)+IF(AND($H$13>H13,COUNTIF($H$12:$H$12,$H$13)=0),1,0)+IF(AND($H$14>H13,COUNTIF($H$12:$H$13,$H$14)=0),1,0)+IF(AND($H$15>H13,COUNTIF($H$12:$H$14,$H$15)=0),1,0)+IF(AND($H$16>H13,COUNTIF($H$12:$H$15,$H$16)=0),1,0)+IF(AND($H$17>H13,COUNTIF($H$12:$H$16,$H$17)=0),1,0)+IF(AND($H$18>H13,COUNTIF($H$12:$H$17,$H$18)=0),1,0)+IF(AND($H$19>H13,COUNTIF($H$12:$H$18,$H$19)=0),1,0)+IF(AND($H$20>H13,COUNTIF($H$12:$H$19,$H$20)=0),1,0)+IF(AND($H$21>H13,COUNTIF($H$12:$H$20,$H$21)=0),1,0) -> 1 | J13: =C13&" | "&D13 -> Bull Trout | Spawning & Resident
