Workbook

Sheet Rank Comparison
D1: Original Atlas | H1: Normalized
A2: BSR | B2: BSR Description | C2: Tier | D2: U-Score | E2: P-Score | F2: Combined Fish Score (Old) | G2: RANK Combined Fish Score (Old) | H2: Fish Use Score | I2: Rank | J2: Old vs New (Normalized)
A3: CC2B | B3: State Ditch to Old FR River Confluence | C3: 3 | D3: 13 | E3: 8 | F3: =SUM(D3:E3) -> 21 | G3: =RANK(F3,($F$3:$F$4,$F$7:$F$31)) -> 20 | H3: ='Fish Use Scores - Normalized'!F2 -> 1.8587229 | I3: =RANK(H3,$H$3:$H$31) -> 16 | J3: =$G3-I3 -> 4
A4: CC2C1 | B4: Old GR River Confluence to Pyles Creek | C4: 2 | D4: 13 | E4: 8 | F4: =SUM(D4:E4) -> 21 | G4: =RANK(F4,($F$3:$F$4,$F$7:$F$31)) -> 20 | H4: ='Fish Use Scores - Normalized'!F3 -> 1.2962402 | I4: =RANK(H4,$H$3:$H$31) -> 20 | J4: =$G4-I4 -> 0
A5: CC2C2 | B5: Ladd Creek | C5: − | D5: − | E5: − | F5: − | G5: − | H5: ='Fish Use Scores - Normalized'!F4 -> 0.75754442 | I5: =RANK(H5,$H$3:$H$31) -> 28 | J5: −
A6: CC2C3 | B6: Little Creek | C6: − | D6: − | E6: − | F6: − | G6: − | H6: ='Fish Use Scores - Normalized'!F5 -> 1.0176603 | I6: =RANK(H6,$H$3:$H$31) -> 23 | J6: −
A7: CC3A | B7: Pyles Creek to Swackhammer Diversion | C7: 1 | D7: 19 | E7: 12 | F7: =SUM(D7:E7) -> 31 | G7: =RANK(F7,($F$3:$F$4,$F$7:$F$31)) -> 11 | H7: ='Fish Use Scores - Normalized'!F6 -> 1.9136917 | I7: =RANK(H7,$H$3:$H$31) -> 15 | J7: =$G7-I7 -> -4
A8: CC3B1 | B8: Downstream of swackhammer to BOR T/A reach break 4 (river mile 47.2) | C8: 1 | D8: 21 | E8: 14 | F8: =SUM(D8:E8) -> 35 | G8: =RANK(F8,($F$3:$F$4,$F$7:$F$31)) -> 9 | H8: ='Fish Use Scores - Normalized'!F7 -> 2.5278929 | I8: =RANK(H8,$H$3:$H$31) -> 10 | J8: =$G8-I8 -> -1
A9: CC3B2 | B9: BOR T/A reach break 4 (river mile 47.2) to north and south forks | C9: 1 | D9: 17 | E9: 14 | F9: =SUM(D9:E9) -> 31 | G9: =RANK(F9,($F$3:$F$4,$F$7:$F$31)) -> 11 | H9: ='Fish Use Scores - Normalized'!F8 -> 4.0469121 | I9: =RANK(H9,$H$3:$H$31) -> 1 | J9: =$G9-I9 -> 10
A10: CC4 | B10: Lower and Middle Catherine Creek Tribs | C10: 3 | D10: 13 | E10: 14 | F10: =SUM(D10:E10) -> 27 | G10: =RANK(F10,($F$3:$F$4,$F$7:$F$31)) -> 15 | H10: ='Fish Use Scores - Normalized'!F9 -> 0.89501066 | I10: =RANK(H10,$H$3:$H$31) -> 25 | J10: =$G10-I10 -> -10
A11: CC5 | B11: North and South Forks Catherine Creek | C11: 3 | D11: 15 | E11: 18 | F11: =SUM(D11:E11) -> 33 | G11: =RANK(F11,($F$3:$F$4,$F$7:$F$31)) -> 10 | H11: ='Fish Use Scores - Normalized'!F10 -> 3.6863249 | I11: =RANK(H11,$H$3:$H$31) -> 2 | J11: =$G11-I11 -> 8
A12: UGR1 | B12: Lookingglass Creek | C12: 3 | D12: 5 | E12: 17 | F12: =SUM(D12:E12) -> 22 | G12: =RANK(F12,($F$3:$F$4,$F$7:$F$31)) -> 19 | H12: ='Fish Use Scores - Normalized'!F11 -> 3.6350273 | I12: =RANK(H12,$H$3:$H$31) -> 3 | J12: =$G12-I12 -> 16
A13: UGR2 | B13: Gordon Creek, Cabin Creek and Phillips Creek | C13: 3 | D13: 7 | E13: 8 | F13: =SUM(D13:E13) -> 15 | G13: =RANK(F13,($F$3:$F$4,$F$7:$F$31)) -> 25 | H13: ='Fish Use Scores - Normalized'!F12 -> 0.79231839 | I13: =RANK(H13,$H$3:$H$31) -> 26 | J13: =$G13-I13 -> -1
A14: UGR3 | B14: Mainstem from Rondowa to Clark Creek | C14: 3 | D14: 12 | E14: 14 | F14: =SUM(D14:E14) -> 26 | G14: =RANK(F14,($F$3:$F$4,$F$7:$F$31)) -> 17 | H14: ='Fish Use Scores - Normalized'!F13 -> 2.8345969 | I14: =RANK(H14,$H$3:$H$31) -> 8 | J14: =$G14-I14 -> 9
A15: UGR4 | B15: Willow Creek | C15: 3 | D15: 8 | E15: 9 | F15: =SUM(D15:E15) -> 17 | G15: =RANK(F15,($F$3:$F$4,$F$7:$F$31)) -> 23 | H15: ='Fish Use Scores - Normalized'!F14 -> 0.77525894 | I15: =RANK(H15,$H$3:$H$31) -> 27 | J15: =$G15-I15 -> -4
A16: UGR5 | B16: Mainsteam from Clark Creek to State Ditch | C16: 3 | D16: 13 | E16: 14 | F16: =SUM(D16:E16) -> 27 | G16: =RANK(F16,($F$3:$F$4,$F$7:$F$31)) -> 15 | H16: ='Fish Use Scores - Normalized'!F15 -> 2.4040279 | I16: =RANK(H16,$H$3:$H$31) -> 12 | J16: =$G16-I16 -> 3
A17: UGR6 | B17: Clark Creek, Indian Creek, Rysdam Canyon and Duncan Canyon | C17: 2 | D17: 16 | E17: 25 | F17: =SUM(D17:E17) -> 41 | G17: =RANK(F17,($F$3:$F$4,$F$7:$F$31)) -> 5 | H17: ='Fish Use Scores - Normalized'!F16 -> 3.0600587 | I17: =RANK(H17,$H$3:$H$31) -> 6 | J17: =$G17-I17 -> -1
A18: UGR7 | B18: Mainstem from State Ditch to Orodell | C18: 3 | D18: 16 | E18: 14 | F18: =SUM(D18:E18) -> 30 | G18: =RANK(F18,($F$3:$F$4,$F$7:$F$31)) -> 13 | H18: ='Fish Use Scores - Normalized'!F17 -> 1.5661945 | I18: =RANK(H18,$H$3:$H$31) -> 17 | J18: =$G18-I18 -> -4
... A31: UGR20 | B31: Mainstem from Meadowbrook Creek to Headwaters | C31: 1 | D31: 21 | E31: 25 | F31: =SUM(D31:E31) -> 46 | G31: =RANK(F31,($F$3:$F$4,$F$7:$F$31)) -> 2 | H31: ='Fish Use Scores - Normalized'!F30 -> 3.4727892 | I31: =RANK(H31,$H$3:$H$31) -> 4 | J31: =$G31-I31 -> -2

Sheet Fish Use Scores - Normalized
A1: BSR | C1: Chinook | D1: Steelhead | E1: Bull Trout | F1: Fish Use Score | G1: Rank | H1: Fish Use Score /100
A2: CC2B | B2: State Ditch to Old FR River Confluence | C2: =$L$5*'Normalized Score Calculator'!C3 +$L$7*'Normalized Score Calculator'!E3 +$L$6*'Normalized Score Calculator'!G3 +$L$8*'Normalized Score Calculator'!I3 -> 0.91015476 | D2: =$M$5*'Normalized Score Calculator'!K3 +$M$7*'Normalized Score Calculator'!M3 +$M$6*'Normalized Score Calculator'!O3 +$M$8*'Normalized Score Calculator'!Q3 -> 0.57806123 | E2: =$P$5*'Normalized Score Calculator'!S3 +$P$6*'Normalized Score Calculator'!U3 -> 0.37050691 | F2: =C2*$L$17+D2*$L$18+E2*$L$19 -> 1.8587229 | G2: =RANK(F2,$F$2:$F$30) -> 16 | H2: =F2*(100/F$35) -> 45.929411
A3: CC2C1 | B3: Old GR River Confluence to Pyles Creek | C3: =$L$5*'Normalized Score Calculator'!C4 +$L$7*'Normalized Score Calculator'!E4 +$L$6*'Normalized Score Calculator'!G4 +$L$8*'Normalized Score Calculator'!I4 -> 0.59346474 | D3: =$M$5*'Normalized Score Calculator'!K4 +$M$7*'Normalized Score Calculator'!M4 +$M$6*'Normalized Score Calculator'!O4 +$M$8*'Normalized Score Calculator'!Q4 -> 0.33226857 | E3: =$P$5*'Normalized Score Calculator'!S4 +$P$6*'Normalized Score Calculator'!U4 -> 0.37050691 | F3: =C3*$L$17+D3*$L$18+E3*$L$19 -> 1.2962402 | G3: =RANK(F3,$F$2:$F$30) -> 20 | H3: =F3*(100/F$35) -> 32.030353 | K3: Population Level Score
A4: CC2C2 | B4: Ladd Creek | C4: =$L$5*'Normalized Score Calculator'!C5 +$L$7*'Normalized Score Calculator'!E5 +$L$6*'Normalized Score Calculator'!G5 +$L$8*'Normalized Score Calculator'!I5 -> 0.16859679 | D4: =$M$5*'Normalized Score Calculator'!K5 +$M$7*'Normalized Score Calculator'!M5 +$M$6*'Normalized Score Calculator'!O5 +$M$8*'Normalized Score Calculator'!Q5 -> 0.58894763 | E4: =$P$5*'Normalized Score Calculator'!S5 +$P$6*'Normalized Score Calculator'!U5 -> 0 | F4: =C4*$L$17+D4*$L$18+E4*$L$19 -> 0.75754442 | G4: =RANK(F4,$F$2:$F$30) -> 28 | H4: =F4*(100/F$35) -> 18.719073 | J4: Basin | K4: Life Stage | L4: Chinook | M4: Steelhead | N4: Bull Trout | O4: BT Life Stage | P4: BT Weight
A5: CC2C3 | B5: Little Creek | C5: =$L$5*'Normalized Score Calculator'!C6 +$L$7*'Normalized Score Calculator'!E6 +$L$6*'Normalized Score Calculator'!G6 +$L$8*'Normalized Score Calculator'!I6 -> 0.27256003 | D5: =$M$5*'Normalized Score Calculator'!K6 +$M$7*'Normalized Score Calculator'!M6 +$M$6*'Normalized Score Calculator'!O6 +$M$8*'Normalized Score Calculator'!Q6 -> 0.74510025 | E5: =$P$5*'Normalized Score Calculator'!S6 +$P$6*'Normalized Score Calculator'!U6 -> 0 | F5: =C5*$L$17+D5*$L$18+E5*$L$19 -> 1.0176603 | G5: =RANK(F5,$F$2:$F$30) -> 23 | H5: =F5*(100/F$35) -> 25.146587 | J5: Catherine Creek | K5: Spawning | L5: 0.12121212 | M5: 0.25 | N5: Both Basins | O5: Spawning/Resident | P5: 0.6
A6: CC3A | B6: Pyles Creek to Swackhammer Diversion | C6: =$L$5*'Normalized Score Calculator'!C7 +$L$7*'Normalized Score Calculator'!E7 +$L$6*'Normalized Score Calculator'!G7 +$L$8*'Normalized Score Calculator'!I7 -> 0.90966403 | D6: =$M$5*'Normalized Score Calculator'!K7 +$M$7*'Normalized Score Calculator'!M7 +$M$6*'Normalized Score Calculator'!O7 +$M$8*'Normalized Score Calculator'!Q7 -> 0.63352075 | E6: =$P$5*'Normalized Score Calculator'!S7 +$P$6*'Normalized Score Calculator'!U7 -> 0.37050691 | F6: =C6*$L$17+D6*$L$18+E6*$L$19 -> 1.9136917 | G6: =RANK(F6,$F$2:$F$30) -> 15 | H6: =F6*(100/F$35) -> 47.287701 | J6: Catherine Creek | K6: Summer Rearing | L6: 0.21212121 | M6: 0.25 | N6: Both Basins | O6: FMO/Subadult | P6: 0.4
A7: CC3B1 | B7: Downstream of swackhammer to BOR T/A reach break 4 (river mile 47.2) | C7: =$L$5*'Normalized Score Calculator'!C8 +$L$7*'Normalized Score Calculator'!E8 +$L$6*'Normalized Score Calculator'!G8 +$L$8*'Normalized Score Calculator'!I8 -> 1.1692167 | D7: =$M$5*'Normalized Score Calculator'!K8 +$M$7*'Normalized Score Calculator'!M8 +$M$6*'Normalized Score Calculator'!O8 +$M$8*'Normalized Score Calculator'!Q8 -> 0.80568076 | E7: =$P$5*'Normalized Score Calculator'!S8 +$P$6*'Normalized Score Calculator'!U8 -> 0.55299539 | F7: =C7*$L$17+D7*$L$18+E7*$L$19 -> 2.5278929 | G7: =RANK(F7,$F$2:$F$30) -> 10 | H7: =F7*(100/F$35) -> 62.464734 | J7: Catherine Creek | K7: Winter Rearing | L7: 0.36363636 | M7: 0.25
A8: CC3B2 | B8: BOR T/A reach break 4 (river mile 47.2) to north and south forks | C8: =$L$5*'Normalized Score Calculator'!C9 +$L$7*'Normalized Score Calculator'!E9 +$L$6*'Normalized Score Calculator'!G9 +$L$8*'Normalized Score Calculator'!I9 -> 1.0999425 | D8: =$M$5*'Normalized Score Calculator'!K9 +$M$7*'Normalized Score Calculator'!M9 +$M$6*'Normalized Score Calculator'!O9 +$M$8*'Normalized Score Calculator'!Q9 -> 0.9496628 | E8: =$P$5*'Normalized Score Calculator'!S9 +$P$6*'Normalized Score Calculator'!U9 -> 1.9973068 | F8: =C8*$L$17+D8*$L$18+E8*$L$19 -> 4.0469121 | G8: =RANK(F8,$F$2:$F$30) -> 1 | H8: =F8*(100/F$35) -> 100 | J8: Catherine Creek | K8: Migration | L8: 0.3030303 | M8: 0.25
A9: CC4 | B9: Lower and Middle Catherine Creek Tribs | C9: =$L$5*'Normalized Score Calculator'!C10 +$L$7*'Normalized Score Calculator'!E10 +$L$6*'Normalized Score Calculator'!G10 +$L$8*'Normalized Score Calculator'!I10 -> 0.2380448 | D9: =$M$5*'Normalized Score Calculator'!K10 +$M$7*'Normalized Score Calculator'!M10 +$M$6*'Normalized Score Calculator'!O10 +$M$8*'Normalized Score Calculator'!Q10 -> 0.65696586 | E9: =$P$5*'Normalized Score Calculator'!S10 +$P$6*'Normalized Score Calculator'!U10 -> 0 | F9: =C9*$L$17+D9*$L$18+E9*$L$19 -> 0.89501066 | G9: =RANK(F9,$F$2:$F$30) -> 25 | H9: =F9*(100/F$35) -> 22.115891 | J9: Upper Grande Ronde | K9: Spawning | L9: 0.078947368 | M9: 0.25
A10: CC5 | B10: North and South Forks Catherine Creek | C10: =$L$5*'Normalized Score Calculator'!C11 +$L$7*'Normalized Score Calculator'!E11 +$L$6*'Normalized Score Calculator'!G11 +$L$8*'Normalized Score Calculator'!I11 -> 0.63835564 | D10: =$M$5*'Normalized Score Calculator'!K11 +$M$7*'Normalized Score Calculator'!M11 +$M$6*'Normalized Score Calculator'!O11 +$M$8*'Normalized Score Calculator'!Q11 -> 0.70979215 | E10: =$P$5*'Normalized Score Calculator'!S11 +$P$6*'Normalized Score Calculator'!U11 -> 2.3381771 | F10: =C10*$L$17+D10*$L$18+E10*$L$19 -> 3.6863249 | G10: =RANK(F10,$F$2:$F$30) -> 2 | H10: =F10*(100/F$35) -> 91.089819 | J10: Upper Grande Ronde | K10: Summer Rearing | L10: 0.23684211 | M10: 0.25
A11: UGR1 | B11: Lookingglass Creek | C11: =$L$9*'Normalized Score Calculator'!C19 +$L$11*'Normalized Score Calculator'!E19 +$L$10*'Normalized Score Calculator'!G19 +$L$12*'Normalized Score Calculator'!I19 -> 0.99372985 | D11: =$M$9*'Normalized Score Calculator'!K19 +$M$11*'Normalized Score Calculator'!M19 +$M$10*'Normalized Score Calculator'!O19 +$M$12*'Normalized Score Calculator'!Q19 -> 0.71537154 | E11: =$P$5*'Normalized Score Calculator'!S19 +$P$6*'Normalized Score Calculator'!U19 -> 1.9259259 | F11: =C11*$L$17+D11*$L$18+E11*$L$19 -> 3.6350273 | G11: =RANK(F11,$F$2:$F$30) -> 3 | H11: =F11*(100/F$35) -> 89.822245 | J11: Upper Grande Ronde | K11: Winter Rearing | L11: 0.34210526 | M11: 0.25
A12: UGR2 | B12: Gordon Creek, Cabin Cree and Phillips Creek | C12: =$L$9*'Normalized Score Calculator'!C20 +$L$11*'Normalized Score Calculator'!E20 +$L$10*'Normalized Score Calculator'!G20 +$L$12*'Normalized Score Calculator'!I20 -> 0.001960523 | D12: =$M$9*'Normalized Score Calculator'!K20 +$M$11*'Normalized Score Calculator'!M20 +$M$10*'Normalized Score Calculator'!O20 +$M$12*'Normalized Score Calculator'!Q20 -> 0.79035787 | E12: =$P$5*'Normalized Score Calculator'!S20 +$P$6*'Normalized Score Calculator'!U20 -> 0 | F12: =C12*$L$17+D12*$L$18+E12*$L$19 -> 0.79231839 | G12: =RANK(F12,$F$2:$F$30) -> 26 | H12: =F12*(100/F$35) -> 19.578344 | J12: Upper Grande Ronde | K12: Migration | L12: 0.34210526 | M12: 0.25
A13: UGR3 | B13: Mainstem from Rondowa to Clark Creek | C13: =$L$9*'Normalized Score Calculator'!C21 +$L$11*'Normalized Score Calculator'!E21 +$L$10*'Normalized Score Calculator'!G21 +$L$12*'Normalized Score Calculator'!I21 -> 1.2193204 | D13: =$M$9*'Normalized Score Calculator'!K21 +$M$11*'Normalized Score Calculator'!M21 +$M$10*'Normalized Score Calculator'!O21 +$M$12*'Normalized Score Calculator'!Q21 -> 1.0226839 | E13: =$P$5*'Normalized Score Calculator'!S21 +$P$6*'Normalized Score Calculator'!U21 -> 0.59259259 | F13: =C13*$L$17+D13*$L$18+E13*$L$19 -> 2.8345969 | G13: =RANK(F13,$F$2:$F$30) -> 8 | H13: =F13*(100/F$35) -> 70.043453
A14: UGR4 | B14: Willow Creek | C14: =$L$9*'Normalized Score Calculator'!C22 +$L$11*'Normalized Score Calculator'!E22 +$L$10*'Normalized Score Calculator'!G22 +$L$12*'Normalized Score Calculator'!I22 -> 0.0013073551 | D14: =$M$9*'Normalized Score Calculator'!K22 +$M$11*'Normalized Score Calculator'!M22 +$M$10*'Normalized Score Calculator'!O22 +$M$12*'Normalized Score Calculator'!Q22 -> 0.77395158 | E14: =$P$5*'Normalized Score Calculator'!S22 +$P$6*'Normalized Score Calculator'!U22 -> 0 | F14: =C14*$L$17+D14*$L$18+E14*$L$19 -> 0.77525894 | G14: =RANK(F14,$F$2:$F$30) -> 27 | H14: =F14*(100/F$35) -> 19.156802
A15: UGR5 | B15: Mainsteam from Clark Creek to State Ditch | C15: =$L$9*'Normalized Score Calculator'!C23 +$L$11*'Normalized Score Calculator'!E23 +$L$10*'Normalized Score Calculator'!G23 +$L$12*'Normalized Score Calculator'!I23 -> 1.3927453 | D15: =$M$9*'Normalized Score Calculator'!K23 +$M$11*'Normalized Score Calculator'!M23 +$M$10*'Normalized Score Calculator'!O23 +$M$12*'Normalized Score Calculator'!Q23 -> 0.81572701 | E15: =$P$5*'Normalized Score Calculator'!S23 +$P$6*'Normalized Score Calculator'!U23 -> 0.19555556 | F15: =C15*$L$17+D15*$L$18+E15*$L$19 -> 2.4040279 | G15: =RANK(F15,$F$2:$F$30) -> 12 | H15: =F15*(100/F$35) -> 59.404005
A16: UGR6 | B16: Clark Creek, Indian Creek, Rysdam Canyon and Duncan Canyon | C16: =$L$9*'Normalized Score Calculator'!C24 +$L$11*'Normalized Score Calculator'!E24 +$L$10*'Normalized Score Calculator'!G24 +$L$12*'Normalized Score Calculator'!I24 -> 0.51458564 | D16: =$M$9*'Normalized Score Calculator'!K24 +$M$11*'Normalized Score Calculator'!M24 +$M$10*'Normalized Score Calculator'!O24 +$M$12*'Normalized Score Calculator'!Q24 -> 0.8151027 | E16: =$P$5*'Normalized Score Calculator'!S24 +$P$6*'Normalized Score Calculator'!U24 -> 1.7303704 | F16: =C16*$L$17+D16*$L$18+E16*$L$19 -> 3.0600587 | G16: =RANK(F16,$F$2:$F$30) -> 6 | H16: =F16*(100/F$35) -> 75.614658 | K16: Species Weighting
A17: UGR7 | B17: Mainstem from State Ditch to Orodell | C17: =$L$9*'Normalized Score Calculator'!C25 +$L$11*'Normalized Score Calculator'!E25 +$L$10*'Normalized Score Calculator'!G25 +$L$12*'Normalized Score Calculator'!I25 -> 0.82021376 | D17: =$M$9*'Normalized Score Calculator'!K25 +$M$11*'Normalized Score Calculator'!M25 +$M$10*'Normalized Score Calculator'!O25 +$M$12*'Normalized Score Calculator'!Q25 -> 0.5504252 | E17: =$P$5*'Normalized Score Calculator'!S25 +$P$6*'Normalized Score Calculator'!U25 -> 0.19555556 | F17: =C17*$L$17+D17*$L$18+E17*$L$19 -> 1.5661945 | G17: =RANK(F17,$F$2:$F$30) -> 17 | H17: =F17*(100/F$35) -> 38.700977 | K17: Chinook | L17: 1
A18: UGR8 | B18: Old Grande Ronde Channel | C18: =$L$9*'Normalized Score Calculator'!C26 +$L$11*'Normalized Score Calculator'!E26 +$L$10*'Normalized Score Calculator'!G26 +$L$12*'Normalized Score Calculator'!I26 -> 0.020267356 | D18: =$M$9*'Normalized Score Calculator'!K26 +$M$11*'Normalized Score Calculator'!M26 +$M$10*'Normalized Score Calculator'!O26 +$M$12*'Normalized Score Calculator'!Q26 -> 0.00012065325 | E18: =$P$5*'Normalized Score Calculator'!S26 +$P$6*'Normalized Score Calculator'!U26 -> 0 | F18: =C18*$L$17+D18*$L$18+E18*$L$19 -> 0.020388009 | G18: =RANK(F18,$F$2:$F$30) -> 29 | H18: =F18*(100/F$35) -> 0.50379174 | K18: Steelhead | L18: 1
A19: UGR9 | B19: Mainstem from Orodell to Five Points Creek | C19: =$L$9*'Normalized Score Calculator'!C27 +$L$11*'Normalized Score Calculator'!E27 +$L$10*'Normalized Score Calculator'!G27 +$L$12*'Normalized Score Calculator'!I27 -> 0.74973055 | D19: =$M$9*'Normalized Score Calculator'!K27 +$M$11*'Normalized Score Calculator'!M27 +$M$10*'Normalized Score Calculator'!O27 +$M$12*'Normalized Score Calculator'!Q27 -> 0.53385871 | E19: =$P$5*'Normalized Score Calculator'!S27 +$P$6*'Normalized Score Calculator'!U27 -> 0.19555556 | F19: =C19*$L$17+D19*$L$18+E19*$L$19 -> 1.4791448 | G19: =RANK(F19,$F$2:$F$30) -> 18 | H19: =F19*(100/F$35) -> 36.549962 | K19: Bull Trout | L19: 1
A20: UGR10 | B20: Five Points Creek | C20: =$L$9*'Normalized Score Calculator'!C28 +$L$11*'Normalized Score Calculator'!E28 +$L$10*'Normalized Score Calculator'!G28 +$L$12*'Normalized Score Calculator'!I28 -> 0.2619247 | D20: =$M$9*'Normalized Score Calculator'!K28 +$M$11*'Normalized Score Calculator'!M28 +$M$10*'Normalized Score Calculator'!O28 +$M$12*'Normalized Score Calculator'!Q28 -> 0.77868722 | E20: =$P$5*'Normalized Score Calculator'!S28 +$P$6*'Normalized Score Calculator'!U28 -> 0 | F20: =C20*$L$17+D20*$L$18+E20*$L$19 -> 1.0406119 | G20: =RANK(F20,$F$2:$F$30) -> 22 | H20: =F20*(100/F$35) -> 25.713727
A21: UGR11 | B21: Mainstem from Five Points Creek to Meadow Creek | C21: =$L$9*'Normalized Score Calculator'!C29 +$L$11*'Normalized Score Calculator'!E29 +$L$10*'Normalized Score Calculator'!G29 +$L$12*'Normalized Score Calculator'!I29 -> 0.97242762 | D21: =$M$9*'Normalized Score Calculator'!K29 +$M$11*'Normalized Score Calculator'!M29 +$M$10*'Normalized Score Calculator'!O29 +$M$12*'Normalized Score Calculator'!Q29 -> 0.64070373 | E21: =$P$5*'Normalized Score Calculator'!S29 +$P$6*'Normalized Score Calculator'!U29 -> 0.39703704 | F21: =C21*$L$17+D21*$L$18+E21*$L$19 -> 2.0101684 | G21: =RANK(F21,$F$2:$F$30) -> 14 | H21: =F21*(100/F$35) -> 49.671659
A22: UGR12 | B22: Rock Creek, Spring Creek, Whiskey Creek, Bear Creek and Jordan Creek | C22: =$L$9*'Normalized Score Calculator'!C30 +$L$11*'Normalized Score Calculator'!E30 +$L$10*'Normalized Score Calculator'!G30 +$L$12*'Normalized Score Calculator'!I30 -> 0.26323236 | D22: =$M$9*'Normalized Score Calculator'!K30 +$M$11*'Normalized Score Calculator'!M30 +$M$10*'Normalized Score Calculator'!O30 +$M$12*'Normalized Score Calculator'!Q30 -> 0.6699455 | E22: =$P$5*'Normalized Score Calculator'!S30 +$P$6*'Normalized Score Calculator'!U30 -> 0 | F22: =C22*$L$17+D22*$L$18+E22*$L$19 -> 0.93317786 | G22: =RANK(F22,$F$2:$F$30) -> 24 | H22: =F22*(100/F$35) -> 23.05901
A23: UGR13 | B23: Meadow, McCoy, McIntyre and Dark Canyon Creeks | C23: =$L$9*'Normalized Score Calculator'!C31 +$L$11*'Normalized Score Calculator'!E31 +$L$10*'Normalized Score Calculator'!G31 +$L$12*'Normalized Score Calculator'!I31 -> 0.32534112 | D23: =$M$9*'Normalized Score Calculator'!K31 +$M$11*'Normalized Score Calculator'!M31 +$M$10*'Normalized Score Calculator'!O31 +$M$12*'Normalized Score Calculator'!Q31 -> 0.84255946 | E23: =$P$5*'Normalized Score Calculator'!S31 +$P$6*'Normalized Score Calculator'!U31 -> 0 | F23: =C23*$L$17+D23*$L$18+E23*$L$19 -> 1.1679006 | G23: =RANK(F23,$F$2:$F$30) -> 21 | H23: =F23*(100/F$35) -> 28.859055
A24: UGR14 | B24: Beaver Creek | C24: =$L$9*'Normalized Score Calculator'!C32 +$L$11*'Normalized Score Calculator'!E32 +$L$10*'Normalized Score Calculator'!G32 +$L$12*'Normalized Score Calculator'!I32 -> 0.4485519 | D24: =$M$9*'Normalized Score Calculator'!K32 +$M$11*'Normalized Score Calculator'!M32 +$M$10*'Normalized Score Calculator'!O32 +$M$12*'Normalized Score Calculator'!Q32 -> 0.69306525 | E24: =$P$5*'Normalized Score Calculator'!S32 +$P$6*'Normalized Score Calculator'!U32 -> 1.7303704 | F24: =C24*$L$17+D24*$L$18+E24*$L$19 -> 2.8719875 | G24: =RANK(F24,$F$2:$F$30) -> 7 | H24: =F24*(100/F$35) -> 70.967381 | K24: Population Level Score
A25: UGR15 | B25: Mainstem from Meadow Creek to Splash Dam | C25: =$L$9*'Normalized Score Calculator'!C33 +$L$11*'Normalized Score Calculator'!E33 +$L$10*'Normalized Score Calculator'!G33 +$L$12*'Normalized Score Calculator'!I33 -> 1.2530527 | D25: =$M$9*'Normalized Score Calculator'!K33 +$M$11*'Normalized Score Calculator'!M33 +$M$10*'Normalized Score Calculator'!O33 +$M$12*'Normalized Score Calculator'!Q33 -> 0.58807315 | E25: =$P$5*'Normalized Score Calculator'!S33 +$P$6*'Normalized Score Calculator'!U33 -> 0.59259259 | F25: =C25*$L$17+D25*$L$18+E25*$L$19 -> 2.4337184 | G25: =RANK(F25,$F$2:$F$30) -> 11 | H25: =F25*(100/F$35) -> 60.137665 | K25: Variable | L25: Score
A26: UGR16 | B26: Fly Creek | C26: =$L$9*'Normalized Score Calculator'!C34 +$L$11*'Normalized Score Calculator'!E34 +$L$10*'Normalized Score Calculator'!G34 +$L$12*'Normalized Score Calculator'!I34 -> 0.60370891 | D26: =$M$9*'Normalized Score Calculator'!K34 +$M$11*'Normalized Score Calculator'!M34 +$M$10*'Normalized Score Calculator'!O34 +$M$12*'Normalized Score Calculator'!Q34 -> 0.6960823 | E26: =$P$5*'Normalized Score Calculator'!S34 +$P$6*'Normalized Score Calculator'!U34 -> 0 | F26: =C26*$L$17+D26*$L$18+E26*$L$19 -> 1.2997912 | G26: =RANK(F26,$F$2:$F$30) -> 19 | H26: =F26*(100/F$35) -> 32.118098 | K26: High | L26: 1
A27: UGR17 | B27: Mainstem from Splash Dam to Meadowbrook Creek | C27: =$L$9*'Normalized Score Calculator'!C35 +$L$11*'Normalized Score Calculator'!E35 +$L$10*'Normalized Score Calculator'!G35 +$L$12*'Normalized Score Calculator'!I35 -> 1.1687136 | D27: =$M$9*'Normalized Score Calculator'!K35 +$M$11*'Normalized Score Calculator'!M35 +$M$10*'Normalized Score Calculator'!O35 +$M$12*'Normalized Score Calculator'!Q35 -> 0.6270782 | E27: =$P$5*'Normalized Score Calculator'!S35 +$P$6*'Normalized Score Calculator'!U35 -> 0.59259259 | F27: =C27*$L$17+D27*$L$18+E27*$L$19 -> 2.3883844 | G27: =RANK(F27,$F$2:$F$30) -> 13 | H27: =F27*(100/F$35) -> 59.017452 | K27: Medium | L27: 0.67
A28: UGR18 | B28: Limber Jim Creek | C28: =$L$9*'Normalized Score Calculator'!C36 +$L$11*'Normalized Score Calculator'!E36 +$L$10*'Normalized Score Calculator'!G36 +$L$12*'Normalized Score Calculator'!I36 -> 0.61089945 | D28: =$M$9*'Normalized Score Calculator'!K36 +$M$11*'Normalized Score Calculator'!M36 +$M$10*'Normalized Score Calculator'!O36 +$M$12*'Normalized Score Calculator'!Q36 -> 0.50177584 | E28: =$P$5*'Normalized Score Calculator'!S36 +$P$6*'Normalized Score Calculator'!U36 -> 1.5288889 | F28: =C28*$L$17+D28*$L$18+E28*$L$19 -> 2.6415642 | G28: =RANK(F28,$F$2:$F$30) -> 9 | H28: =F28*(100/F$35) -> 65.273574 | K28: Low | L28: 0.33
A29: UGR19 | B29: Sheep Creek to Chicken Creek | C29: =$L$9*'Normalized Score Calculator'!C37 +$L$11*'Normalized Score Calculator'!E37 +$L$10*'Normalized Score Calculator'!G37 +$L$12*'Normalized Score Calculator'!I37 -> 0.67474331 | D29: =$M$9*'Normalized Score Calculator'!K37 +$M$11*'Normalized Score Calculator'!M37 +$M$10*'Normalized Score Calculator'!O37 +$M$12*'Normalized Score Calculator'!Q37 -> 0.76777716 | E29: =$P$5*'Normalized Score Calculator'!S37 +$P$6*'Normalized Score Calculator'!U37 -> 1.7303704 | F29: =C29*$L$17+D29*$L$18+E29*$L$19 -> 3.1728908 | G29: =RANK(F29,$F$2:$F$30) -> 5 | H29: =F29*(100/F$35) -> 78.402762 | K29: Negligible | L29: 0
A30: UGR20 | B30: Mainstem from Meadowbrook Creek to Headwaters | C30: =$L$9*'Normalized Score Calculator'!C38 +$L$11*'Normalized Score Calculator'!E38 +$L$10*'Normalized Score Calculator'!G38 +$L$12*'Normalized Score Calculator'!I38 -> 1.0368769 | D30: =$M$9*'Normalized Score Calculator'!K38 +$M$11*'Normalized Score Calculator'!M38 +$M$10*'Normalized Score Calculator'!O38 +$M$12*'Normalized Score Calculator'!Q38 -> 0.50998633 | E30: =$P$5*'Normalized Score Calculator'!S38 +$P$6*'Normalized Score Calculator'!U38 -> 1.9259259 | F30: =C30*$L$17+D30*$L$18+E30*$L$19 -> 3.4727892 | G30: =RANK(F30,$F$2:$F$30) -> 4 | H30: =F30*(100/F$35) -> 85.813309 | K30: Not Evaluated | L30: 0
B31: SUM | C31: 19.333333 | D31: =SUM(D2:D30) -> 19.333333 | E31: =SUM(E2:E30) -> 19.333333 | F31: =SUM(F2:F30) -> 58.203453
C32: =C31/$F$31 -> 0.33216815 | D32: =D31/$F$31 -> 0.33216815 | E32: =E31/$F$31 -> 0.33216815
F35: =MAX(F2:F30) -> 4.0469121

Sheet Normalized Score Calculator
B1: Chinook | J1: Steelhead | R1: Bull Trout
A2: BSR | B2: Spawning | C2: Corrected Spawning | D2: Winter Rearing | E2: Corrected Winter Rearing | F2: Summer Rearing | G2: Corrected Summer Rearing | H2: Migration | I2: Corrected Migration | J2: Spawning | K2: Corrected Spawning | L2: Winter Rearing | M2: Corrected Winter Rearing | N2: Summer Rearing | O2: Corrected Summer Rearing | P2: Migration | Q2: Corrected Migration | R2: Spawning & Resident | S2: Corrected Spawning & Resident | T2: FMO | U2: Corrected FMO | W2: Total Score | X2: Rank
A3: CC2B | B3: =_xlfn.XLOOKUP(_xlfn.XLOOKUP($A3, Chinook!$A$3:$A$31, Chinook!$B$3:$B$31),$A$47:$A$51,$B$47:$B$51) -> 0 | C3: =B3/$B$13*$B$14 -> 0 | D3: =_xlfn.XLOOKUP(_xlfn.XLOOKUP($A3, Chinook!$A$3:$A$31, Chinook!$E$3:$E$31),$A$47:$A$51,$B$47:$B$51) -> 1 | E3: =D3/$D$13*$B$14 -> 0.9009009 | F3: =_xlfn.XLOOKUP(_xlfn.XLOOKUP($A3, Chinook!$A$3:$A$31, Chinook!$H$3:$H$31),$A$47:$A$51,$B$47:$B$51) -> 0 | G3: =F3/$F$13*$B$14 -> 0 | H3: ='Migration Score Calcs'!E2 -> 0.33817751 | I3: =H3/$H$13*$B$14 -> 1.9224296 | J3: =_xlfn.XLOOKUP(_xlfn.XLOOKUP($A3, Steelhead!$A$3:$A$31, Steelhead!$C$3:$C$31),$A$47:$A$51,$B$47:$B$51) -> 0 | K3: =J3/$J$13*$B$14 -> 0 | L3: =_xlfn.XLOOKUP(_xlfn.XLOOKUP($A3, Steelhead!$A$3:$A$31, Steelhead!$F$3:$F$31),$A$47:$A$51,$B$47:$B$51) -> 0.33 | M3: =L3/$L$13*$B$14 -> 0.37148218 | N3: =_xlfn.XLOOKUP(_xlfn.XLOOKUP($A3, Steelhead!$A$3:$A$31, Steelhead!$I$3:$I$31),$A$47:$A$51,$B$47:$B$51) -> 0 | O3: =N3/$N$13*$B$14 -> 0 | P3: ='Migration Score Calcs'!F2 -> 0.16661934 | Q3: =P3/$P$13*$B$14 -> 1.9407627 | R3: =_xlfn.XLOOKUP(_xlfn.XLOOKUP($A3, 'Bull Trout'!$A$3:$A$31, 'Bull Trout'!$C$3:$C$31),$A$47:$A$51,$B$47:$B$51) -> 0 | S3: =R3/$R$13*$B$14 -> 0 | T3: =_xlfn.XLOOKUP(_xlfn.XLOOKUP($A3, 'Bull Trout'!$A$3:$A$31, 'Bull Trout'!$F$3:$F$31),$A$47:$A$51,$B$47:$B$51) -> 0.67 | U3: =T3/$T$13*$B$14 -> 0.92626728 | W3: =SUM(C3,E3,G3,K3, I3,M3,O3,Q3,S3,U3) -> 6.0618427 | X3: =RANK(W3,$W$3:$W$38) -> 16
A4: CC2C1 | B4: =_xlfn.XLOOKUP(_xlfn.XLOOKUP($A4, Chinook!$A$3:$A$31, Chinook!$B$3:$B$31),$A$47:$A$51,$B$47:$B$51) -> 0 | C4: =B4/$B$13*$B$14 -> 0 | D4: =_xlfn.XLOOKUP(_xlfn.XLOOKUP($A4, Chinook!$A$3:$A$31, Chinook!$E$3:$E$31),$A$47:$A$51,$B$47:$B$51) -> 1 | E4: =D4/$D$13*$B$14 -> 0.9009009 | F4: =_xlfn.XLOOKUP(_xlfn.XLOOKUP($A4, Chinook!$A$3:$A$31, Chinook!$H$3:$H$31),$A$47:$A$51,$B$47:$B$51) -> 0 | G4: =F4/$F$13*$B$14 -> 0 | H4: ='Migration Score Calcs'!E3 -> 0.15433642 | I4: =H4/$H$13*$B$14 -> 0.87735257 | J4: =_xlfn.XLOOKUP(_xlfn.XLOOKUP($A4, Steelhead!$A$3:$A$31, Steelhead!$C$3:$C$31),$A$47:$A$51,$B$47:$B$51) -> 0 | K4: =J4/$J$13*$B$14 -> 0 | L4: =_xlfn.XLOOKUP(_xlfn.XLOOKUP($A4, Steelhead!$A$3:$A$31, Steelhead!$F$3:$F$31),$A$47:$A$51,$B$47:$B$51) -> 0.33 | M4: =L4/$L$13*$B$14 -> 0.37148218 | N4: =_xlfn.XLOOKUP(_xlfn.XLOOKUP($A4, Steelhead!$A$3:$A$31, Steelhead!$I$3:$I$31),$A$47:$A$51,$B$47:$B$51) -> 0 | O4: =N4/$N$13*$B$14 -> 0 | P4: ='Migration Score Calcs'!F3 -> 0.082211681 | Q4: =P4/$P$13*$B$14 -> 0.95759209 | R4: =_xlfn.XLOOKUP(_xlfn.XLOOKUP($A4, 'Bull Trout'!$A$3:$A$31, 'Bull Trout'!$C$3:$C$31),$A$47:$A$51,$B$47:$B$51) -> 0 | S4: =R4/$R$13*$B$14 -> 0 | T4: =_xlfn.XLOOKUP(_xlfn.XLOOKUP($A4, 'Bull Trout'!$A$3:$A$31, 'Bull Trout'!$F$3:$F$31),$A$47:$A$51,$B$47:$B$51) -> 0.67 | U4: =T4/$T$13*$B$14 -> 0.92626728 | W4: =SUM(C4,E4,G4,K4, I4,M4,O4,Q4,S4,U4) -> 4.033595 | X4: =RANK(W4,$W$3:$W$38) -> 22
A5: CC2C2 | B5: =_xlfn.XLOOKUP(_xlfn.XLOOKUP($A5, Chinook!$A$3:$A$31, Chinook!$B$3:$B$31),$A$47:$A$51,$B$47:$B$51) -> 0 | C5: =B5/$B$13*$B$14 -> 0 | D5: =_xlfn.XLOOKUP(_xlfn.XLOOKUP($A5, Chinook!$A$3:$A$31, Chinook!$E$3:$E$31),$A$47:$A$51,$B$47:$B$51) -> 0.33 | E5: =D5/$D$13*$B$14 -> 0.2972973 | F5: =_xlfn.XLOOKUP(_xlfn.XLOOKUP($A5, Chinook!$A$3:$A$31, Chinook!$H$3:$H$31),$A$47:$A$51,$B$47:$B$51) -> 0 | G5: =F5/$F$13*$B$14 -> 0 | H5: ='Migration Score Calcs'!E4 -> 0.035114164 | I5: =H5/$H$13*$B$14 -> 0.19961265 | J5: =_xlfn.XLOOKUP(_xlfn.XLOOKUP($A5, Steelhead!$A$3:$A$31, Steelhead!$C$3:$C$31),$A$47:$A$51,$B$47:$B$51) -> 0.67 | K5: =J5/$J$13*$B$14 -> 0.70899471 | L5: =_xlfn.XLOOKUP(_xlfn.XLOOKUP($A5, Steelhead!$A$3:$A$31, Steelhead!$F$3:$F$31),$A$47:$A$51,$B$47:$B$51) -> 0.67 | M5: =L5/$L$13*$B$14 -> 0.75422139 | N5: =_xlfn.XLOOKUP(_xlfn.XLOOKUP($A5, Steelhead!$A$3:$A$31, Steelhead!$I$3:$I$31),$A$47:$A$51,$B$47:$B$51) -> 0.33 | O5: =N5/$N$13*$B$14 -> 0.34920635 | P5: ='Migration Score Calcs'!F4 -> 0.04664951 | Q5: =P5/$P$13*$B$14 -> 0.54336807 | R5: =_xlfn.XLOOKUP(_xlfn.XLOOKUP($A5, 'Bull Trout'!$A$3:$A$31, 'Bull Trout'!$C$3:$C$31),$A$47:$A$51,$B$47:$B$51) -> 0 | S5: =R5/$R$13*$B$14 -> 0 | T5: =_xlfn.XLOOKUP(_xlfn.XLOOKUP($A5, 'Bull Trout'!$A$3:$A$31, 'Bull Trout'!$F$3:$F$31),$A$47:$A$51,$B$47:$B$51) -> 0 | U5: =T5/$T$13*$B$14 -> 0 | W5: =SUM(C5,E5,G5,K5, I5,M5,O5,Q5,S5,U5) -> 2.8527005 | X5: =RANK(W5,$W$3:$W$38) -> 28
A6: CC2C3 | B6: =_xlfn.XLOOKUP(_xlfn.XLOOKUP($A6, Chinook!$A$3:$A$31, Chinook!$B$3:$B$31),$A$47:$A$51,$B$47:$B$51) -> 0 | C6: =B6/$B$13*$B$14 -> 0 | D6: =_xlfn.XLOOKUP(_xlfn.XLOOKUP($A6, Chinook!$A$3:$A$31, Chinook!$E$3:$E$31),$A$47:$A$51,$B$47:$B$51) -> 0.33 | E6: =D6/$D$13*$B$14 -> 0.2972973 | F6: =_xlfn.XLOOKUP(_xlfn.XLOOKUP($A6, Chinook!$A$3:$A$31, Chinook!$H$3:$H$31),$A$47:$A$51,$B$47:$B$51) -> 0.33 | G6: =F6/$F$13*$B$14 -> 0.495 | H6: ='Migration Score Calcs'!E5 -> 0.034512314 | I6: =H6/$H$13*$B$14 -> 0.19619133 | J6: =_xlfn.XLOOKUP(_xlfn.XLOOKUP($A6, Steelhead!$A$3:$A$31, Steelhead!$C$3:$C$31),$A$47:$A$51,$B$47:$B$51) -> 1 | K6: =J6/$J$13*$B$14 -> 1.0582011 | L6: =_xlfn.XLOOKUP(_xlfn.XLOOKUP($A6, Steelhead!$A$3:$A$31, Steelhead!$F$3:$F$31),$A$47:$A$51,$B$47:$B$51) -> 0.67 | M6: =L6/$L$13*$B$14 -> 0.75422139 | N6: =_xlfn.XLOOKUP(_xlfn.XLOOKUP($A6, Steelhead!$A$3:$A$31, Steelhead!$I$3:$I$31),$A$47:$A$51,$B$47:$B$51) -> 1 | O6: =N6/$N$13*$B$14 -> 1.0582011 | P6: ='Migration Score Calcs'!F5 -> 0.0094246747 | Q6: =P6/$P$13*$B$14 -> 0.10977751 | R6: =_xlfn.XLOOKUP(_xlfn.XLOOKUP($A6, 'Bull Trout'!$A$3:$A$31, 'Bull Trout'!$C$3:$C$31),$A$47:$A$51,$B$47:$B$51) -> 0 | S6: =R6/$R$13*$B$14 -> 0 | T6: =_xlfn.XLOOKUP(_xlfn.XLOOKUP($A6, 'Bull Trout'!$A$3:$A$31, 'Bull Trout'!$F$3:$F$31),$A$47:$A$51,$B$47:$B$51) -> 0 | U6: =T6/$T$13*$B$14 -> 0 | W6: =SUM(C6,E6,G6,K6, I6,M6,O6,Q6,S6,U6) -> 3.9688896 | X6: =RANK(W6,$W$3:$W$38) -> 23
A7: CC3A | B7: =_xlfn.XLOOKUP(_xlfn.XLOOKUP($A7, Chinook!$A$3:$A$31, Chinook!$B$3:$B$31),$A$47:$A$51,$B$47:$B$51) -> 0.33 | C7: =B7/$B$13*$B$14 -> 0.7443609 | D7: =_xlfn.XLOOKUP(_xlfn.XLOOKUP($A7, Chinook!$A$3:$A$31, Chinook!$E$3:$E$31),$A$47:$A$51,$B$47:$B$51) -> 1 | E7: =D7/$D$13*$B$14 -> 0.9009009 | F7: =_xlfn.XLOOKUP(_xlfn.XLOOKUP($A7, Chinook!$A$3:$A$31, Chinook!$H$3:$H$31),$A$47:$A$51,$B$47:$B$51) -> 0.67 | G7: =F7/$F$13*$B$14 -> 1.005 | H7: ='Migration Score Calcs'!E6 -> 0.16176222 | I7: =H7/$H$13*$B$14 -> 0.91956586 | J7: =_xlfn.XLOOKUP(_xlfn.XLOOKUP($A7, Steelhead!$A$3:$A$31, Steelhead!$C$3:$C$31),$A$47:$A$51,$B$47:$B$51) -> 0.67 | K7: =J7/$J$13*$B$14 -> 0.70899471 | L7: =_xlfn.XLOOKUP(_xlfn.XLOOKUP($A7, Steelhead!$A$3:$A$31, Steelhead!$F$3:$F$31),$A$47:$A$51,$B$47:$B$51) -> 0.33 | M7: =L7/$L$13*$B$14 -> 0.37148218 | N7: =_xlfn.XLOOKUP(_xlfn.XLOOKUP($A7, Steelhead!$A$3:$A$31, Steelhead!$I$3:$I$31),$A$47:$A$51,$B$47:$B$51) -> 0.67 | O7: =N7/$N$13*$B$14 -> 0.70899471 | P7: ='Migration Score Calcs'!F6 -> 0.063926756 | Q7: =P7/$P$13*$B$14 -> 0.74461142 | R7: =_xlfn.XLOOKUP(_xlfn.XLOOKUP($A7, 'Bull Trout'!$A$3:$A$31, 'Bull Trout'!$C$3:$C$31),$A$47:$A$51,$B$47:$B$51) -> 0 | S7: =R7/$R$13*$B$14 -> 0 | T7: =_xlfn.XLOOKUP(_xlfn.XLOOKUP($A7, 'Bull Trout'!$A$3:$A$31, 'Bull Trout'!$F$3:$F$31),$A$47:$A$51,$B$47:$B$51) -> 0.67 | U7: =T7/$T$13*$B$14 -> 0.92626728 | W7: =SUM(C7,E7,G7,K7, I7,M7,O7,Q7,S7,U7) -> 7.030178 | X7: =RANK(W7,$W$3:$W$38) -> 14
A8: CC3B1 | B8: =_xlfn.XLOOKUP(_xlfn.XLOOKUP($A8, Chinook!$A$3:$A$31, Chinook!$B$3:$B$31),$A$47:$A$51,$B$47:$B$51) -> 1 | C8: =B8/$B$13*$B$14 -> 2.2556391 | D8: =_xlfn.XLOOKUP(_xlfn.XLOOKUP($A8, Chinook!$A$3:$A$31, Chinook!$E$3:$E$31),$A$47:$A$51,$B$47:$B$51) -> 1 | E8: =D8/$D$13*$B$14 -> 0.9009009 | F8: =_xlfn.XLOOKUP(_xlfn.XLOOKUP($A8, Chinook!$A$3:$A$31, Chinook!$H$3:$H$31),$A$47:$A$51,$B$47:$B$51) -> 1 | G8: =F8/$F$13*$B$14 -> 1.5 | H8: ='Migration Score Calcs'!E7 -> 0.14514079 | I8: =H8/$H$13*$B$14 -> 0.8250784 | J8: =_xlfn.XLOOKUP(_xlfn.XLOOKUP($A8, Steelhead!$A$3:$A$31, Steelhead!$C$3:$C$31),$A$47:$A$51,$B$47:$B$51) -> 0.33 | K8: =J8/$J$13*$B$14 -> 0.34920635 | L8: =_xlfn.XLOOKUP(_xlfn.XLOOKUP($A8, Steelhead!$A$3:$A$31, Steelhead!$F$3:$F$31),$A$47:$A$51,$B$47:$B$51) -> 1 | M8: =L8/$L$13*$B$14 -> 1.1257036 | N8: =_xlfn.XLOOKUP(_xlfn.XLOOKUP($A8, Steelhead!$A$3:$A$31, Steelhead!$I$3:$I$31),$A$47:$A$51,$B$47:$B$51) -> 1 | O8: =N8/$N$13*$B$14 -> 1.0582011 | P8: ='Migration Score Calcs'!F7 -> 0.059204923 | Q8: =P8/$P$13*$B$14 -> 0.68961206 | R8: =_xlfn.XLOOKUP(_xlfn.XLOOKUP($A8, 'Bull Trout'!$A$3:$A$31, 'Bull Trout'!$C$3:$C$31),$A$47:$A$51,$B$47:$B$51) -> 0 | S8: =R8/$R$13*$B$14 -> 0 | T8: =_xlfn.XLOOKUP(_xlfn.XLOOKUP($A8, 'Bull Trout'!$A$3:$A$31, 'Bull Trout'!$F$3:$F$31),$A$47:$A$51,$B$47:$B$51) -> 1 | U8: =T8/$T$13*$B$14 -> 1.3824885 | W8: =SUM(C8,E8,G8,K8, I8,M8,O8,Q8,S8,U8) -> 10.08683 | X8: =RANK(W8,$W$3:$W$38) -> 4
A9: CC3B2 | B9: =_xlfn.XLOOKUP(_xlfn.XLOOKUP($A9, Chinook!$A$3:$A$31, Chinook!$B$3:$B$31),$A$47:$A$51,$B$47:$B$51) -> 1 | C9: =B9/$B$13*$B$14 -> 2.2556391 | D9: =_xlfn.XLOOKUP(_xlfn.XLOOKUP($A9, Chinook!$A$3:$A$31, Chinook!$E$3:$E$31),$A$47:$A$51,$B$47:$B$51) -> 1 | E9: =D9/$D$13*$B$14 -> 0.9009009 | F9: =_xlfn.XLOOKUP(_xlfn.XLOOKUP($A9, Chinook!$A$3:$A$31, Chinook!$H$3:$H$31),$A$47:$A$51,$B$47:$B$51) -> 1 | G9: =F9/$F$13*$B$14 -> 1.5 | H9: ='Migration Score Calcs'!E8 -> 0.10492657 | I9: =H9/$H$13*$B$14 -> 0.59647359 | J9: =_xlfn.XLOOKUP(_xlfn.XLOOKUP($A9, Steelhead!$A$3:$A$31, Steelhead!$C$3:$C$31),$A$47:$A$51,$B$47:$B$51) -> 1 | K9: =J9/$J$13*$B$14 -> 1.0582011 | L9: =_xlfn.XLOOKUP(_xlfn.XLOOKUP($A9, Steelhead!$A$3:$A$31, Steelhead!$F$3:$F$31),$A$47:$A$51,$B$47:$B$51) -> 1 | M9: =L9/$L$13*$B$14 -> 1.1257036 | N9: =_xlfn.XLOOKUP(_xlfn.XLOOKUP($A9, Steelhead!$A$3:$A$31, Steelhead!$I$3:$I$31),$A$47:$A$51,$B$47:$B$51) -> 1 | O9: =N9/$N$13*$B$14 -> 1.0582011 | P9: ='Migration Score Calcs'!F8 -> 0.047780828 | Q9: =P9/$P$13*$B$14 -> 0.55654552 | R9: =_xlfn.XLOOKUP(_xlfn.XLOOKUP($A9, 'Bull Trout'!$A$3:$A$31, 'Bull Trout'!$C$3:$C$31),$A$47:$A$51,$B$47:$B$51) -> 0.67 | S9: =R9/$R$13*$B$14 -> 2.4071856 | T9: =_xlfn.XLOOKUP(_xlfn.XLOOKUP($A9, 'Bull Trout'!$A$3:$A$31, 'Bull Trout'!$F$3:$F$31),$A$47:$A$51,$B$47:$B$51) -> 1 | U9: =T9/$T$13*$B$14 -> 1.3824885 | W9: =SUM(C9,E9,G9,K9, I9,M9,O9,Q9,S9,U9) -> 12.841339 | X9: =RANK(W9,$W$3:$W$38) -> 1
A10: CC4 | B10: =_xlfn.XLOOKUP(_xlfn.XLOOKUP($A10, Chinook!$A$3:$A$31, Chinook!$B$3:$B$31),$A$47:$A$51,$B$47:$B$51) -> 0 | C10: =B10/$B$13*$B$14 -> 0 | D10: =_xlfn.XLOOKUP(_xlfn.XLOOKUP($A10, Chinook!$A$3:$A$31, Chinook!$E$3:$E$31),$A$47:$A$51,$B$47:$B$51) -> 0.33 | E10: =D10/$D$13*$B$14 -> 0.2972973 | F10: =_xlfn.XLOOKUP(_xlfn.XLOOKUP($A10, Chinook!$A$3:$A$31, Chinook!$H$3:$H$31),$A$47:$A$51,$B$47:$B$51) -> 0.33 | G10: =F10/$F$13*$B$14 -> 0.495 | H10: ='Migration Score Calcs'!E9 -> 0.014475947 | I10: =H10/$H$13*$B$14 -> 0.08229107 | J10: =_xlfn.XLOOKUP(_xlfn.XLOOKUP($A10, Steelhead!$A$3:$A$31, Steelhead!$C$3:$C$31),$A$47:$A$51,$B$47:$B$51) -> 1 | K10: =J10/$J$13*$B$14 -> 1.0582011 | L10: =_xlfn.XLOOKUP(_xlfn.XLOOKUP($A10, Steelhead!$A$3:$A$31, Steelhead!$F$3:$F$31),$A$47:$A$51,$B$47:$B$51) -> 0.67 | M10: =L10/$L$13*$B$14 -> 0.75422139 | N10: =_xlfn.XLOOKUP(_xlfn.XLOOKUP($A10, Steelhead!$A$3:$A$31, Steelhead!$I$3:$I$31),$A$47:$A$51,$B$47:$B$51) -> 0.67 | O10: =N10/$N$13*$B$14 -> 0.70899471 | P10: ='Migration Score Calcs'!F9 -> 0.0091386818 | Q10: =P10/$P$13*$B$14 -> 0.1064463 | R10: =_xlfn.XLOOKUP(_xlfn.XLOOKUP($A10, 'Bull Trout'!$A$3:$A$31, 'Bull Trout'!$C$3:$C$31),$A$47:$A$51,$B$47:$B$51) -> 0 | S10: =R10/$R$13*$B$14 -> 0 | T10: =_xlfn.XLOOKUP(_xlfn.XLOOKUP($A10, 'Bull Trout'!$A$3:$A$31, 'Bull Trout'!$F$3:$F$31),$A$47:$A$51,$B$47:$B$51) -> 0 | U10: =T10/$T$13*$B$14 -> 0 | W10: =SUM(C10,E10,G10,K10, I10,M10,O10,Q10,S10,U10) -> 3.5024518 | X10: =RANK(W10,$W$3:$W$38) -> 25
A11: CC5 | B11: =_xlfn.XLOOKUP(_xlfn.XLOOKUP($A11, Chinook!$A$3:$A$31, Chinook!$B$3:$B$31),$A$47:$A$51,$B$47:$B$51) -> 0.33 | C11: =B11/$B$13*$B$14 -> 0.7443609 | D11: =_xlfn.XLOOKUP(_xlfn.XLOOKUP($A11, Chinook!$A$3:$A$31, Chinook!$E$3:$E$31),$A$47:$A$51,$B$47:$B$51) -> 0.67 | E11: =D11/$D$13*$B$14 -> 0.6036036 | F11: =_xlfn.XLOOKUP(_xlfn.XLOOKUP($A11, Chinook!$A$3:$A$31, Chinook!$H$3:$H$31),$A$47:$A$51,$B$47:$B$51) -> 0.67 | G11: =F11/$F$13*$B$14 -> 1.005 | H11: ='Migration Score Calcs'!E10 -> 0.067023151 | I11: =H11/$H$13*$B$14 -> 0.38100491 | J11: =_xlfn.XLOOKUP(_xlfn.XLOOKUP($A11, Steelhead!$A$3:$A$31, Steelhead!$C$3:$C$31),$A$47:$A$51,$B$47:$B$51) -> 1 | K11: =J11/$J$13*$B$14 -> 1.0582011 | L11: =_xlfn.XLOOKUP(_xlfn.XLOOKUP($A11, Steelhead!$A$3:$A$31, Steelhead!$F$3:$F$31),$A$47:$A$51,$B$47:$B$51) -> 0.33 | M11: =L11/$L$13*$B$14 -> 0.37148218 | N11: =_xlfn.XLOOKUP(_xlfn.XLOOKUP($A11, Steelhead!$A$3:$A$31, Steelhead!$I$3:$I$31),$A$47:$A$51,$B$47:$B$51) -> 1 | O11: =N11/$N$13*$B$14 -> 1.0582011 | P11: ='Migration Score Calcs'!F10 -> 0.030158637 | Q11: =P11/$P$13*$B$14 -> 0.35128429 | R11: =_xlfn.XLOOKUP(_xlfn.XLOOKUP($A11, 'Bull Trout'!$A$3:$A$31, 'Bull Trout'!$C$3:$C$31),$A$47:$A$51,$B$47:$B$51) -> 1 | S11: =R11/$R$13*$B$14 -> 3.5928144 | T11: =_xlfn.XLOOKUP(_xlfn.XLOOKUP($A11, 'Bull Trout'!$A$3:$A$31, 'Bull Trout'!$F$3:$F$31),$A$47:$A$51,$B$47:$B$51) -> 0.33 | U11: =T11/$T$13*$B$14 -> 0.4562212 | W11: =SUM(C11,E11,G11,K11, I11,M11,O11,Q11,S11,U11) -> 9.6221736 | X11: =RANK(W11,$W$3:$W$38) -> 7
A13: Total | B13: =SUM(B3:B11) -> 2.66 | C13: =SUM(C3:C11) -> 6 | D13: =SUM(D3:D11) -> 6.66 | E13: =SUM(E3:E11) -> 6 | F13: =SUM(F3:F11) -> 4 | G13: =SUM(G3:G11) -> 6 | H13: =SUM(H3:H11) -> 1.0554691 | I13: =SUM(I3:I11) -> 6 | ... U13: =SUM(U3:U11) -> 6
A14: Theoretical Total | B14: =COUNT(B3:B11)/3*1+COUNT(B3:B11)/3*0.67+COUNT(B3:B11)/3*0.33 -> 6
A16: Scaling Factor | B16: =1-(B13/$B$14) -> 0.55666667 | D16: =1-(D13/$B$14) -> -0.11 | F16: =1-(F13/$B$14) -> 0.33333333 | J16: =1-(J13/$B$14) -> 0.055 | L16: =1-(L13/$B$14) -> 0.11166667 | N16: =1-(N13/$B$14) -> 0.055 | P16: =1-(P13/$B$14) -> 0.91414749 | R16: =1-(R13/$B$14) -> 0.72166667 | T16: =1-(T13/$B$14) -> 0.27666667
A19: UGR1 | B19: =_xlfn.XLOOKUP(_xlfn.XLOOKUP($A19, Chinook!$A$3:$A$31, Chinook!$B$3:$B$31),$A$47:$A$51,$B$47:$B$51) -> 1 | C19: =B19/$B$40*$B$41 -> 2.359882 | D19: =_xlfn.XLOOKUP(_xlfn.XLOOKUP($A19, Chinook!$A$3:$A$31, Chinook!$E$3:$E$31),$A$47:$A$51,$B$47:$B$51) -> 1 | E19: =D19/$D$40*$B$41 -> 1.2496095 | F19: =_xlfn.XLOOKUP(_xlfn.XLOOKUP($A19, Chinook!$A$3:$A$31, Chinook!$H$3:$H$31),$A$47:$A$51,$B$47:$B$51) -> 1 | G19: =F19/$F$40*$B$41 -> 1.53787 | H19: ='Migration Score Calcs'!E11 -> 0.012870288 | I19: =H19/$H$40*$B$41 -> 0.045871861 | J19: =_xlfn.XLOOKUP(_xlfn.XLOOKUP($A19, Steelhead!$A$3:$A$31, Steelhead!$C$3:$C$31),$A$47:$A$51,$B$47:$B$51) -> 1 | K19: =J19/$J$40*$B$41 -> 1.025641 | L19: =_xlfn.XLOOKUP(_xlfn.XLOOKUP($A19, Steelhead!$A$3:$A$31, Steelhead!$F$3:$F$31),$A$47:$A$51,$B$47:$B$51) -> 0.67 | M19: =L19/$L$40*$B$41 -> 0.58159722 | N19: =_xlfn.XLOOKUP(_xlfn.XLOOKUP($A19, Steelhead!$A$3:$A$31, Steelhead!$I$3:$I$31),$A$47:$A$51,$B$47:$B$51) -> 1 | O19: =N19/$N$40*$B$41 -> 1.0515247 | P19: ='Migration Score Calcs'!F11 -> 0.063936878 | Q19: =P19/$P$40*$B$41 -> 0.20272319 | R19: =_xlfn.XLOOKUP(_xlfn.XLOOKUP($A19, 'Bull Trout'!$A$3:$A$31, 'Bull Trout'!$C$3:$C$31),$A$47:$A$51,$B$47:$B$51) -> 1 | S19: =R19/$R$40*$B$41 -> 2.2222222 | T19: =_xlfn.XLOOKUP(_xlfn.XLOOKUP($A19, 'Bull Trout'!$A$3:$A$31, 'Bull Trout'!$F$3:$F$31),$A$47:$A$51,$B$47:$B$51) -> 1 | U19: =T19/$T$40*$B$41 -> 1.4814815 | W19: =SUM(C19,E19,G19,K19, I19,M19,O19,Q19,S19,U19) -> 11.758423 | X19: =RANK(W19,$W$3:$W$38) -> 2
A20: UGR2 | B20: =_xlfn.XLOOKUP(_xlfn.XLOOKUP($A20, Chinook!$A$3:$A$31, Chinook!$B$3:$B$31),$A$47:$A$51,$B$47:$B$51) -> 0 | C20: =B20/$B$40*$B$41 -> 0 | D20: =_xlfn.XLOOKUP(_xlfn.XLOOKUP($A20, Chinook!$A$3:$A$31, Chinook!$E$3:$E$31),$A$47:$A$51,$B$47:$B$51) -> 0 | E20: =D20/$D$40*$B$41 -> 0 | F20: =_xlfn.XLOOKUP(_xlfn.XLOOKUP($A20, Chinook!$A$3:$A$31, Chinook!$H$3:$H$31),$A$47:$A$51,$B$47:$B$51) -> 0 | G20: =F20/$F$40*$B$41 -> 0 | H20: ='Migration Score Calcs'!E12 -> 0.0016078817 | I20: =H20/$H$40*$B$41 -> 0.0057307596 | J20: =_xlfn.XLOOKUP(_xlfn.XLOOKUP($A20, Steelhead!$A$3:$A$31, Steelhead!$C$3:$C$31),$A$47:$A$51,$B$47:$B$51) -> 1 | K20: =J20/$J$40*$B$41 -> 1.025641 | L20: =_xlfn.XLOOKUP(_xlfn.XLOOKUP($A20, Steelhead!$A$3:$A$31, Steelhead!$F$3:$F$31),$A$47:$A$51,$B$47:$B$51) -> 1 | M20: =L20/$L$40*$B$41 -> 0.86805556 | N20: =_xlfn.XLOOKUP(_xlfn.XLOOKUP($A20, Steelhead!$A$3:$A$31, Steelhead!$I$3:$I$31),$A$47:$A$51,$B$47:$B$51) -> 1 | O20: =N20/$N$40*$B$41 -> 1.0515247 | P20: ='Migration Score Calcs'!F12 -> 0.068190538 | Q20: =P20/$P$40*$B$41 -> 0.21621017 | R20: =_xlfn.XLOOKUP(_xlfn.XLOOKUP($A20, 'Bull Trout'!$A$3:$A$31, 'Bull Trout'!$C$3:$C$31),$A$47:$A$51,$B$47:$B$51) -> 0 | S20: =R20/$R$40*$B$41 -> 0 | T20: =_xlfn.XLOOKUP(_xlfn.XLOOKUP($A20, 'Bull Trout'!$A$3:$A$31, 'Bull Trout'!$F$3:$F$31),$A$47:$A$51,$B$47:$B$51) -> 0 | U20: =T20/$T$40*$B$41 -> 0 | W20: =SUM(C20,E20,G20,K20, I20,M20,O20,Q20,S20,U20) -> 3.1671622 | X20: =RANK(W20,$W$3:$W$38) -> 26
A21: UGR3 | B21: =_xlfn.XLOOKUP(_xlfn.XLOOKUP($A21, Chinook!$A$3:$A$31, Chinook!$B$3:$B$31),$A$47:$A$51,$B$47:$B$51) -> 0 | C21: =B21/$B$40*$B$41 -> 0 | D21: =_xlfn.XLOOKUP(_xlfn.XLOOKUP($A21, Chinook!$A$3:$A$31, Chinook!$E$3:$E$31),$A$47:$A$51,$B$47:$B$51) -> 0 | E21: =D21/$D$40*$B$41 -> 0 | F21: =_xlfn.XLOOKUP(_xlfn.XLOOKUP($A21, Chinook!$A$3:$A$31, Chinook!$H$3:$H$31),$A$47:$A$51,$B$47:$B$51) -> 0 | G21: =F21/$F$40*$B$41 -> 0 | H21: ='Migration Score Calcs'!E13 -> 1 | I21: =H21/$H$40*$B$41 -> 3.5641673 | J21: =_xlfn.XLOOKUP(_xlfn.XLOOKUP($A21, Steelhead!$A$3:$A$31, Steelhead!$C$3:$C$31),$A$47:$A$51,$B$47:$B$51) -> 0.33 | K21: =J21/$J$40*$B$41 -> 0.33846154 | L21: =_xlfn.XLOOKUP(_xlfn.XLOOKUP($A21, Steelhead!$A$3:$A$31, Steelhead!$F$3:$F$31),$A$47:$A$51,$B$47:$B$51) -> 0.67 | M21: =L21/$L$40*$B$41 -> 0.58159722 | N21: =_xlfn.XLOOKUP(_xlfn.XLOOKUP($A21, Steelhead!$A$3:$A$31, Steelhead!$I$3:$I$31),$A$47:$A$51,$B$47:$B$51) -> 0 | O21: =N21/$N$40*$B$41 -> 0 | P21: ='Migration Score Calcs'!F13 -> 1 | Q21: =P21/$P$40*$B$41 -> 3.170677 | R21: =_xlfn.XLOOKUP(_xlfn.XLOOKUP($A21, 'Bull Trout'!$A$3:$A$31, 'Bull Trout'!$C$3:$C$31),$A$47:$A$51,$B$47:$B$51) -> 0 | S21: =R21/$R$40*$B$41 -> 0 | T21: =_xlfn.XLOOKUP(_xlfn.XLOOKUP($A21, 'Bull Trout'!$A$3:$A$31, 'Bull Trout'!$F$3:$F$31),$A$47:$A$51,$B$47:$B$51) -> 1 | U21: =T21/$T$40*$B$41 -> 1.4814815 | W21: =SUM(C21,E21,G21,K21, I21,M21,O21,Q21,S21,U21) -> 9.1363846 | X21: =RANK(W21,$W$3:$W$38) -> 9
A22: UGR4 | B22: =_xlfn.XLOOKUP(_xlfn.XLOOKUP($A22, Chinook!$A$3:$A$31, Chinook!$B$3:$B$31),$A$47:$A$51,$B$47:$B$51) -> 0 | C22: =B22/$B$40*$B$41 -> 0 | D22: =_xlfn.XLOOKUP(_xlfn.XLOOKUP($A22, Chinook!$A$3:$A$31, Chinook!$E$3:$E$31),$A$47:$A$51,$B$47:$B$51) -> 0 | E22: =D22/$D$40*$B$41 -> 0 | F22: =_xlfn.XLOOKUP(_xlfn.XLOOKUP($A22, Chinook!$A$3:$A$31, Chinook!$H$3:$H$31),$A$47:$A$51,$B$47:$B$51) -> 0 | G22: =F22/$F$40*$B$41 -> 0 | H22: ='Migration Score Calcs'!E14 -> 0.0010721998 | I22: =H22/$H$40*$B$41 -> 0.0038214995 | J22: =_xlfn.XLOOKUP(_xlfn.XLOOKUP($A22, Steelhead!$A$3:$A$31, Steelhead!$C$3:$C$31),$A$47:$A$51,$B$47:$B$51) -> 1 | K22: =J22/$J$40*$B$41 -> 1.025641 | L22: =_xlfn.XLOOKUP(_xlfn.XLOOKUP($A22, Steelhead!$A$3:$A$31, Steelhead!$F$3:$F$31),$A$47:$A$51,$B$47:$B$51) -> 1 | M22: =L22/$L$40*$B$41 -> 0.86805556 | N22: =_xlfn.XLOOKUP(_xlfn.XLOOKUP($A22, Steelhead!$A$3:$A$31, Steelhead!$I$3:$I$31),$A$47:$A$51,$B$47:$B$51) -> 1 | O22: =N22/$N$40*$B$41 -> 1.0515247 | P22: ='Migration Score Calcs'!F14 -> 0.047493026 | Q22: =P22/$P$40*$B$41 -> 0.15058505 | R22: =_xlfn.XLOOKUP(_xlfn.XLOOKUP($A22, 'Bull Trout'!$A$3:$A$31, 'Bull Trout'!$C$3:$C$31),$A$47:$A$51,$B$47:$B$51) -> 0 | S22: =R22/$R$40*$B$41 -> 0 | T22: =_xlfn.XLOOKUP(_xlfn.XLOOKUP($A22, 'Bull Trout'!$A$3:$A$31, 'Bull Trout'!$F$3:$F$31),$A$47:$A$51,$B$47:$B$51) -> 0 | U22: =T22/$T$40*$B$41 -> 0 | W22: =SUM(C22,E22,G22,K22, I22,M22,O22,Q22,S22,U22) -> 3.0996278 | X22: =RANK(W22,$W$3:$W$38) -> 27
A23: UGR5 | B23: =_xlfn.XLOOKUP(_xlfn.XLOOKUP($A23, Chinook!$A$3:$A$31, Chinook!$B$3:$B$31),$A$47:$A$51,$B$47:$B$51) -> 0 | C23: =B23/$B$40*$B$41 -> 0 | D23: =_xlfn.XLOOKUP(_xlfn.XLOOKUP($A23, Chinook!$A$3:$A$31, Chinook!$E$3:$E$31),$A$47:$A$51,$B$47:$B$51) -> 0.67 | E23: =D23/$D$40*$B$41 -> 0.83723836 | F23: =_xlfn.XLOOKUP(_xlfn.XLOOKUP($A23, Chinook!$A$3:$A$31, Chinook!$H$3:$H$31),$A$47:$A$51,$B$47:$B$51) -> 0 | G23: =F23/$F$40*$B$41 -> 0 | H23: ='Migration Score Calcs'!E15 -> 0.90732644 | I23: =H23/$H$40*$B$41 -> 3.2338633 | J23: =_xlfn.XLOOKUP(_xlfn.XLOOKUP($A23, Steelhead!$A$3:$A$31, Steelhead!$C$3:$C$31),$A$47:$A$51,$B$47:$B$51) -> 0 | K23: =J23/$J$40*$B$41 -> 0 | L23: =_xlfn.XLOOKUP(_xlfn.XLOOKUP($A23, Steelhead!$A$3:$A$31, Steelhead!$F$3:$F$31),$A$47:$A$51,$B$47:$B$51) -> 0.67 | M23: =L23/$L$40*$B$41 -> 0.58159722 | N23: =_xlfn.XLOOKUP(_xlfn.XLOOKUP($A23, Steelhead!$A$3:$A$31, Steelhead!$I$3:$I$31),$A$47:$A$51,$B$47:$B$51) -> 0 | O23: =N23/$N$40*$B$41 -> 0 | P23: ='Migration Score Calcs'!F15 -> 0.84565876 | Q23: =P23/$P$40*$B$41 -> 2.6813108 | R23: =_xlfn.XLOOKUP(_xlfn.XLOOKUP($A23, 'Bull Trout'!$A$3:$A$31, 'Bull Trout'!$C$3:$C$31),$A$47:$A$51,$B$47:$B$51) -> 0 | S23: =R23/$R$40*$B$41 -> 0 | T23: =_xlfn.XLOOKUP(_xlfn.XLOOKUP($A23, 'Bull Trout'!$A$3:$A$31, 'Bull Trout'!$F$3:$F$31),$A$47:$A$51,$B$47:$B$51) -> 0.33 | U23: =T23/$T$40*$B$41 -> 0.48888889 | W23: =SUM(C23,E23,G23,K23, I23,M23,O23,Q23,S23,U23) -> 7.8228986 | X23: =RANK(W23,$W$3:$W$38) -> 12
A24: UGR6 | B24: =_xlfn.XLOOKUP(_xlfn.XLOOKUP($A24, Chinook!$A$3:$A$31, Chinook!$B$3:$B$31),$A$47:$A$51,$B$47:$B$51) -> 0.33 | C24: =B24/$B$40*$B$41 -> 0.77876106 | D24: =_xlfn.XLOOKUP(_xlfn.XLOOKUP($A24, Chinook!$A$3:$A$31, Chinook!$E$3:$E$31),$A$47:$A$51,$B$47:$B$51) -> 0.33 | E24: =D24/$D$40*$B$41 -> 0.41237113 | F24: =_xlfn.XLOOKUP(_xlfn.XLOOKUP($A24, Chinook!$A$3:$A$31, Chinook!$H$3:$H$31),$A$47:$A$51,$B$47:$B$51) -> 0.67 | G24: =F24/$F$40*$B$41 -> 1.0303729 | H24: ='Migration Score Calcs'!E16 -> 0.055764239 | I24: =H24/$H$40*$B$41 -> 0.19875308 | J24: =_xlfn.XLOOKUP(_xlfn.XLOOKUP($A24, Steelhead!$A$3:$A$31, Steelhead!$C$3:$C$31),$A$47:$A$51,$B$47:$B$51) -> 1 | K24: =J24/$J$40*$B$41 -> 1.025641 | L24: =_xlfn.XLOOKUP(_xlfn.XLOOKUP($A24, Steelhead!$A$3:$A$31, Steelhead!$F$3:$F$31),$A$47:$A$51,$B$47:$B$51) -> 1 | M24: =L24/$L$40*$B$41 -> 0.86805556 | N24: =_xlfn.XLOOKUP(_xlfn.XLOOKUP($A24, Steelhead!$A$3:$A$31, Steelhead!$I$3:$I$31),$A$47:$A$51,$B$47:$B$51) -> 1 | O24: =N24/$N$40*$B$41 -> 1.0515247 | P24: ='Migration Score Calcs'!F16 -> 0.099407642 | Q24: =P24/$P$40*$B$41 -> 0.31518953 | R24: =_xlfn.XLOOKUP(_xlfn.XLOOKUP($A24, 'Bull Trout'!$A$3:$A$31, 'Bull Trout'!$C$3:$C$31),$A$47:$A$51,$B$47:$B$51) -> 1 | S24: =R24/$R$40*$B$41 -> 2.2222222 | T24: =_xlfn.XLOOKUP(_xlfn.XLOOKUP($A24, 'Bull Trout'!$A$3:$A$31, 'Bull Trout'!$F$3:$F$31),$A$47:$A$51,$B$47:$B$51) -> 0.67 | U24: =T24/$T$40*$B$41 -> 0.99259259 | W24: =SUM(C24,E24,G24,K24, I24,M24,O24,Q24,S24,U24) -> 8.8954838 | X24: =RANK(W24,$W$3:$W$38) -> 10
A25: UGR7 | B25: =_xlfn.XLOOKUP(_xlfn.XLOOKUP($A25, Chinook!$A$3:$A$31, Chinook!$B$3:$B$31),$A$47:$A$51,$B$47:$B$51) -> 0 | C25: =B25/$B$40*$B$41 -> 0 | D25: =_xlfn.XLOOKUP(_xlfn.XLOOKUP($A25, Chinook!$A$3:$A$31, Chinook!$E$3:$E$31),$A$47:$A$51,$B$47:$B$51) -> 0.67 | E25: =D25/$D$40*$B$41 -> 0.83723836 | F25: =_xlfn.XLOOKUP(_xlfn.XLOOKUP($A25, Chinook!$A$3:$A$31, Chinook!$H$3:$H$31),$A$47:$A$51,$B$47:$B$51) -> 0 | G25: =F25/$F$40*$B$41 -> 0 | H25: ='Migration Score Calcs'!E17 -> 0.43777674 | I25: =H25/$H$40*$B$41 -> 1.5603096 | J25: =_xlfn.XLOOKUP(_xlfn.XLOOKUP($A25, Steelhead!$A$3:$A$31, Steelhead!$C$3:$C$31),$A$47:$A$51,$B$47:$B$51) -> 0 | K25: =J25/$J$40*$B$41 -> 0 | L25: =_xlfn.XLOOKUP(_xlfn.XLOOKUP($A25, Steelhead!$A$3:$A$31, Steelhead!$F$3:$F$31),$A$47:$A$51,$B$47:$B$51) -> 0.67 | M25: =L25/$L$40*$B$41 -> 0.58159722 | N25: =_xlfn.XLOOKUP(_xlfn.XLOOKUP($A25, Steelhead!$A$3:$A$31, Steelhead!$I$3:$I$31),$A$47:$A$51,$B$47:$B$51) -> 0 | O25: =N25/$N$40*$B$41 -> 0 | P25: ='Migration Score Calcs'!F17 -> 0.51096455 | Q25: =P25/$P$40*$B$41 -> 1.6201036 | R25: =_xlfn.XLOOKUP(_xlfn.XLOOKUP($A25, 'Bull Trout'!$A$3:$A$31, 'Bull Trout'!$C$3:$C$31),$A$47:$A$51,$B$47:$B$51) -> 0 | S25: =R25/$R$40*$B$41 -> 0 | T25: =_xlfn.XLOOKUP(_xlfn.XLOOKUP($A25, 'Bull Trout'!$A$3:$A$31, 'Bull Trout'!$F$3:$F$31),$A$47:$A$51,$B$47:$B$51) -> 0.33 | U25: =T25/$T$40*$B$41 -> 0.48888889 | W25: =SUM(C25,E25,G25,K25, I25,M25,O25,Q25,S25,U25) -> 5.0881376 | X25: =RANK(W25,$W$3:$W$38) -> 18
A26: UGR8 | B26: =_xlfn.XLOOKUP(_xlfn.XLOOKUP($A26, Chinook!$A$3:$A$31, Chinook!$B$3:$B$31),$A$47:$A$51,$B$47:$B$51) -> 0 | C26: =B26/$B$40*$B$41 -> 0 | D26: =_xlfn.XLOOKUP(_xlfn.XLOOKUP($A26, Chinook!$A$3:$A$31, Chinook!$E$3:$E$31),$A$47:$A$51,$B$47:$B$51) -> 0 | E26: =D26/$D$40*$B$41 -> 0 | F26: =_xlfn.XLOOKUP(_xlfn.XLOOKUP($A26, Chinook!$A$3:$A$31, Chinook!$H$3:$H$31),$A$47:$A$51,$B$47:$B$51) -> 0 | G26: =F26/$F$40*$B$41 -> 0 | H26: ='Migration Score Calcs'!E18 -> 0.016621846 | I26: =H26/$H$40*$B$41 -> 0.05924304 | J26: =_xlfn.XLOOKUP(_xlfn.XLOOKUP($A26, Steelhead!$A$3:$A$31, Steelhead!$C$3:$C$31),$A$47:$A$51,$B$47:$B$51) -> 0 | K26: =J26/$J$40*$B$41 -> 0 | L26: =_xlfn.XLOOKUP(_xlfn.XLOOKUP($A26, Steelhead!$A$3:$A$31, Steelhead!$F$3:$F$31),$A$47:$A$51,$B$47:$B$51) -> 0 | M26: =L26/$L$40*$B$41 -> 0 | N26: =_xlfn.XLOOKUP(_xlfn.XLOOKUP($A26, Steelhead!$A$3:$A$31, Steelhead!$I$3:$I$31),$A$47:$A$51,$B$47:$B$51) -> 0 | O26: =N26/$N$40*$B$41 -> 0 | P26: ='Migration Score Calcs'!F18 -> 0.00015221134 | Q26: =P26/$P$40*$B$41 -> 0.00048261301 | R26: =_xlfn.XLOOKUP(_xlfn.XLOOKUP($A26, 'Bull Trout'!$A$3:$A$31, 'Bull Trout'!$C$3:$C$31),$A$47:$A$51,$B$47:$B$51) -> 0 | S26: =R26/$R$40*$B$41 -> 0 | T26: =_xlfn.XLOOKUP(_xlfn.XLOOKUP($A26, 'Bull Trout'!$A$3:$A$31, 'Bull Trout'!$F$3:$F$31),$A$47:$A$51,$B$47:$B$51) -> 0 | U26: =T26/$T$40*$B$41 -> 0 | W26: =SUM(C26,E26,G26,K26, I26,M26,O26,Q26,S26,U26) -> 0.059725653 | X26: =RANK(W26,$W$3:$W$38) -> 29
A27: UGR9 | B27: =_xlfn.XLOOKUP(_xlfn.XLOOKUP($A27, Chinook!$A$3:$A$31, Chinook!$B$3:$B$31),$A$47:$A$51,$B$47:$B$51) -> 0 | C27: =B27/$B$40*$B$41 -> 0 | D27: =_xlfn.XLOOKUP(_xlfn.XLOOKUP($A27, Chinook!$A$3:$A$31, Chinook!$E$3:$E$31),$A$47:$A$51,$B$47:$B$51) -> 0.67 | E27: =D27/$D$40*$B$41 -> 0.83723836 | F27: =_xlfn.XLOOKUP(_xlfn.XLOOKUP($A27, Chinook!$A$3:$A$31, Chinook!$H$3:$H$31),$A$47:$A$51,$B$47:$B$51) -> 0 | G27: =F27/$F$40*$B$41 -> 0 | H27: ='Migration Score Calcs'!E19 -> 0.37997141 | I27: =H27/$H$40*$B$41 -> 1.3542817 | J27: =_xlfn.XLOOKUP(_xlfn.XLOOKUP($A27, Steelhead!$A$3:$A$31, Steelhead!$C$3:$C$31),$A$47:$A$51,$B$47:$B$51) -> 0 | K27: =J27/$J$40*$B$41 -> 0 | L27: =_xlfn.XLOOKUP(_xlfn.XLOOKUP($A27, Steelhead!$A$3:$A$31, Steelhead!$F$3:$F$31),$A$47:$A$51,$B$47:$B$51) -> 0.67 | M27: =L27/$L$40*$B$41 -> 0.58159722 | N27: =_xlfn.XLOOKUP(_xlfn.XLOOKUP($A27, Steelhead!$A$3:$A$31, Steelhead!$I$3:$I$31),$A$47:$A$51,$B$47:$B$51) -> 0 | O27: =N27/$N$40*$B$41 -> 0 | P27: ='Migration Score Calcs'!F19 -> 0.49006493 | Q27: =P27/$P$40*$B$41 -> 1.5538376 | R27: =_xlfn.XLOOKUP(_xlfn.XLOOKUP($A27, 'Bull Trout'!$A$3:$A$31, 'Bull Trout'!$C$3:$C$31),$A$47:$A$51,$B$47:$B$51) -> 0 | S27: =R27/$R$40*$B$41 -> 0 | T27: =_xlfn.XLOOKUP(_xlfn.XLOOKUP($A27, 'Bull Trout'!$A$3:$A$31, 'Bull Trout'!$F$3:$F$31),$A$47:$A$51,$B$47:$B$51) -> 0.33 | U27: =T27/$T$40*$B$41 -> 0.48888889 | W27: =SUM(C27,E27,G27,K27, I27,M27,O27,Q27,S27,U27) -> 4.8158438 | X27: =RANK(W27,$W$3:$W$38) -> 19
A28: UGR10 | B28: =_xlfn.XLOOKUP(_xlfn.XLOOKUP($A28, Chinook!$A$3:$A$31, Chinook!$B$3:$B$31),$A$47:$A$51,$B$47:$B$51) -> 0 | C28: =B28/$B$40*$B$41 -> 0 | D28: =_xlfn.XLOOKUP(_xlfn.XLOOKUP($A28, Chinook!$A$3:$A$31, Chinook!$E$3:$E$31),$A$47:$A$51,$B$47:$B$51) -> 0.33 | E28: =D28/$D$40*$B$41 -> 0.41237113 | F28: =_xlfn.XLOOKUP(_xlfn.XLOOKUP($A28, Chinook!$A$3:$A$31, Chinook!$H$3:$H$31),$A$47:$A$51,$B$47:$B$51) -> 0.33 | G28: =F28/$F$40*$B$41 -> 0.50749712 | H28: ='Migration Score Calcs'!E20 -> 0.0005361042 | I28: =H28/$H$40*$B$41 -> 0.0019107651 | J28: =_xlfn.XLOOKUP(_xlfn.XLOOKUP($A28, Steelhead!$A$3:$A$31, Steelhead!$C$3:$C$31),$A$47:$A$51,$B$47:$B$51) -> 1 | K28: =J28/$J$40*$B$41 -> 1.025641 | L28: =_xlfn.XLOOKUP(_xlfn.XLOOKUP($A28, Steelhead!$A$3:$A$31, Steelhead!$F$3:$F$31),$A$47:$A$51,$B$47:$B$51) -> 1 | M28: =L28/$L$40*$B$41 -> 0.86805556 | N28: =_xlfn.XLOOKUP(_xlfn.XLOOKUP($A28, Steelhead!$A$3:$A$31, Steelhead!$I$3:$I$31),$A$47:$A$51,$B$47:$B$51) -> 1 | O28: =N28/$N$40*$B$41 -> 1.0515247 | P28: ='Migration Score Calcs'!F20 -> 0.05346731 | Q28: =P28/$P$40*$B$41 -> 0.16952757 | R28: =_xlfn.XLOOKUP(_xlfn.XLOOKUP($A28, 'Bull Trout'!$A$3:$A$31, 'Bull Trout'!$C$3:$C$31),$A$47:$A$51,$B$47:$B$51) -> 0 | S28: =R28/$R$40*$B$41 -> 0 | T28: =_xlfn.XLOOKUP(_xlfn.XLOOKUP($A28, 'Bull Trout'!$A$3:$A$31, 'Bull Trout'!$F$3:$F$31),$A$47:$A$51,$B$47:$B$51) -> 0 | U28: =T28/$T$40*$B$41 -> 0 | W28: =SUM(C28,E28,G28,K28, I28,M28,O28,Q28,S28,U28) -> 4.0365279 | X28: =RANK(W28,$W$3:$W$38) -> 21
A29: UGR11 | B29: =_xlfn.XLOOKUP(_xlfn.XLOOKUP($A29, Chinook!$A$3:$A$31, Chinook!$B$3:$B$31),$A$47:$A$51,$B$47:$B$51) -> 0 | C29: =B29/$B$40*$B$41 -> 0 | D29: =_xlfn.XLOOKUP(_xlfn.XLOOKUP($A29, Chinook!$A$3:$A$31, Chinook!$E$3:$E$31),$A$47:$A$51,$B$47:$B$51) -> 1 | E29: =D29/$D$40*$B$41 -> 1.2496095 | F29: =_xlfn.XLOOKUP(_xlfn.XLOOKUP($A29, Chinook!$A$3:$A$31, Chinook!$H$3:$H$31),$A$47:$A$51,$B$47:$B$51) -> 0.33 | G29: =F29/$F$40*$B$41 -> 0.50749712 | H29: ='Migration Score Calcs'!E21 -> 0.3483358 | I29: =H29/$H$40*$B$41 -> 1.2415271 | J29: =_xlfn.XLOOKUP(_xlfn.XLOOKUP($A29, Steelhead!$A$3:$A$31, Steelhead!$C$3:$C$31),$A$47:$A$51,$B$47:$B$51) -> 0.33 | K29: =J29/$J$40*$B$41 -> 0.33846154 | L29: =_xlfn.XLOOKUP(_xlfn.XLOOKUP($A29, Steelhead!$A$3:$A$31, Steelhead!$F$3:$F$31),$A$47:$A$51,$B$47:$B$51) -> 1 | M29: =L29/$L$40*$B$41 -> 0.86805556 | N29: =_xlfn.XLOOKUP(_xlfn.XLOOKUP($A29, Steelhead!$A$3:$A$31, Steelhead!$I$3:$I$31),$A$47:$A$51,$B$47:$B$51) -> 0 | O29: =N29/$N$40*$B$41 -> 0 | P29: ='Migration Score Calcs'!F21 -> 0.42776284 | Q29: =P29/$P$40*$B$41 -> 1.3562978 | R29: =_xlfn.XLOOKUP(_xlfn.XLOOKUP($A29, 'Bull Trout'!$A$3:$A$31, 'Bull Trout'!$C$3:$C$31),$A$47:$A$51,$B$47:$B$51) -> 0 | S29: =R29/$R$40*$B$41 -> 0 | T29: =_xlfn.XLOOKUP(_xlfn.XLOOKUP($A29, 'Bull Trout'!$A$3:$A$31, 'Bull Trout'!$F$3:$F$31),$A$47:$A$51,$B$47:$B$51) -> 0.67 | U29: =T29/$T$40*$B$41 -> 0.99259259 | W29: =SUM(C29,E29,G29,K29, I29,M29,O29,Q29,S29,U29) -> 6.5540412 | X29: =RANK(W29,$W$3:$W$38) -> 15
A30: UGR12 | B30: =_xlfn.XLOOKUP(_xlfn.XLOOKUP($A30, Chinook!$A$3:$A$31, Chinook!$B$3:$B$31),$A$47:$A$51,$B$47:$B$51) -> 0 | C30: =B30/$B$40*$B$41 -> 0 | D30: =_xlfn.XLOOKUP(_xlfn.XLOOKUP($A30, Chinook!$A$3:$A$31, Chinook!$E$3:$E$31),$A$47:$A$51,$B$47:$B$51) -> 0.33 | E30: =D30/$D$40*$B$41 -> 0.41237113 | F30: =_xlfn.XLOOKUP(_xlfn.XLOOKUP($A30, Chinook!$A$3:$A$31, Chinook!$H$3:$H$31),$A$47:$A$51,$B$47:$B$51) -> 0.33 | G30: =F30/$F$40*$B$41 -> 0.50749712 | H30: ='Migration Score Calcs'!E22 -> 0.0016085496 | I30: =H30/$H$40*$B$41 -> 0.0057331399 | J30: =_xlfn.XLOOKUP(_xlfn.XLOOKUP($A30, Steelhead!$A$3:$A$31, Steelhead!$C$3:$C$31),$A$47:$A$51,$B$47:$B$51) -> 1 | K30: =J30/$J$40*$B$41 -> 1.025641 | L30: =_xlfn.XLOOKUP(_xlfn.XLOOKUP($A30, Steelhead!$A$3:$A$31, Steelhead!$F$3:$F$31),$A$47:$A$51,$B$47:$B$51) -> 0.33 | M30: =L30/$L$40*$B$41 -> 0.28645833 | N30: =_xlfn.XLOOKUP(_xlfn.XLOOKUP($A30, Steelhead!$A$3:$A$31, Steelhead!$I$3:$I$31),$A$47:$A$51,$B$47:$B$51) -> 1 | O30: =N30/$N$40*$B$41 -> 1.0515247 | P30: ='Migration Score Calcs'!F22 -> 0.099713071 | Q30: =P30/$P$40*$B$41 -> 0.31615794 | R30: =_xlfn.XLOOKUP(_xlfn.XLOOKUP($A30, 'Bull Trout'!$A$3:$A$31, 'Bull Trout'!$C$3:$C$31),$A$47:$A$51,$B$47:$B$51) -> 0 | S30: =R30/$R$40*$B$41 -> 0 | T30: =_xlfn.XLOOKUP(_xlfn.XLOOKUP($A30, 'Bull Trout'!$A$3:$A$31, 'Bull Trout'!$F$3:$F$31),$A$47:$A$51,$B$47:$B$51) -> 0 | U30: =T30/$T$40*$B$41 -> 0 | W30: =SUM(C30,E30,G30,K30, I30,M30,O30,Q30,S30,U30) -> 3.6053834 | X30: =RANK(W30,$W$3:$W$38) -> 24
... A38: UGR20 | B38: =_xlfn.XLOOKUP(_xlfn.XLOOKUP($A38, Chinook!$A$3:$A$31, Chinook!$B$3:$B$31),$A$47:$A$51,$B$47:$B$51) -> 1 | C38: =B38/$B$40*$B$41 -> 2.359882 | D38: =_xlfn.XLOOKUP(_xlfn.XLOOKUP($A38, Chinook!$A$3:$A$31, Chinook!$E$3:$E$31),$A$47:$A$51,$B$47:$B$51) -> 1 | E38: =D38/$D$40*$B$41 -> 1.2496095 | F38: =_xlfn.XLOOKUP(_xlfn.XLOOKUP($A38, Chinook!$A$3:$A$31, Chinook!$H$3:$H$31),$A$47:$A$51,$B$47:$B$51) -> 1 | G38: =F38/$F$40*$B$41 -> 1.53787 | H38: ='Migration Score Calcs'!E30 -> 0.048256462 | I38: =H38/$H$40*$B$41 -> 0.17199411 | J38: =_xlfn.XLOOKUP(_xlfn.XLOOKUP($A38, Steelhead!$A$3:$A$31, Steelhead!$C$3:$C$31),$A$47:$A$51,$B$47:$B$51) -> 0.67 | K38: =J38/$J$40*$B$41 -> 0.68717949 | L38: =_xlfn.XLOOKUP(_xlfn.XLOOKUP($A38, Steelhead!$A$3:$A$31, Steelhead!$F$3:$F$31),$A$47:$A$51,$B$47:$B$51) -> 0.67 | M38: =L38/$L$40*$B$41 -> 0.58159722 | N38: =_xlfn.XLOOKUP(_xlfn.XLOOKUP($A38, Steelhead!$A$3:$A$31, Steelhead!$I$3:$I$31),$A$47:$A$51,$B$47:$B$51) -> 0.67 | O38: =N38/$N$40*$B$41 -> 0.70452156 | P38: ='Migration Score Calcs'!F30 -> 0.021019819 | Q38: =P38/$P$40*$B$41 -> 0.066647057 | R38: =_xlfn.XLOOKUP(_xlfn.XLOOKUP($A38, 'Bull Trout'!$A$3:$A$31, 'Bull Trout'!$C$3:$C$31),$A$47:$A$51,$B$47:$B$51) -> 1 | S38: =R38/$R$40*$B$41 -> 2.2222222 | T38: =_xlfn.XLOOKUP(_xlfn.XLOOKUP($A38, 'Bull Trout'!$A$3:$A$31, 'Bull Trout'!$F$3:$F$31),$A$47:$A$51,$B$47:$B$51) -> 1 | U38: =T38/$T$40*$B$41 -> 1.4814815 | W38: =SUM(C38,E38,G38,K38, I38,M38,O38,Q38,S38,U38) -> 11.063005 | X38: =RANK(W38,$W$3:$W$38) -> 3
A40: Total | B40: =SUM(B19:B38) -> 5.65 | C40: =SUM(C19:C38) -> 13.333333 | D40: =SUM(D19:D38) -> 10.67 | E40: =SUM(E19:E38) -> 13.333333 | F40: =SUM(F19:F38) -> 8.67 | G40: =SUM(G19:G38) -> 13.333333 | H40: =SUM(H19:H38) -> 3.7409392 | I40: =SUM(I19:I38) -> 13.333333 | ... U40: =SUM(U19:U38) -> 13.333333
A41: Theoretical Total | B41: =COUNT(B19:B38)/3*1+COUNT(B19:B38)/3*0.67+COUNT(B19:B38)/3*0.33 -> 13.333333
A43: Scaling Factor | B43: =1-(B40/$B$41) -> 0.57625 | D43: =1-(D40/$B$41) -> 0.19975 | F43: =1-(F40/$B$41) -> 0.34975 | J43: =1-(J40/$B$41) -> 0.025 | L43: =1-(L40/$B$41) -> -0.152 | N43: =1-(N40/$B$41) -> 0.049 | R43: =1-(R40/$B$41) -> 0.55 | T43: =1-(T40/$B$41) -> 0.325
A45: Population Level Score | E45: Normalization Weighting - UGR | O45: =0.33/0.77 -> 0.42857143
A46: Variable | B46: Score | E46: Life Stage | F46: Chinook | G46: Steelhead | J46: Bull Trout | O46: =1/2.33 -> 0.42918455
A47: High | B47: 1 | E47: Spawning | F47: =B16 -> 0.55666667 | G47: =J16 -> 0.055 | H47: Spawning/Resident | J47: =R16 -> 0.72166667
A48: Medium | B48: 0.67 | E48: Summer Rearing | F48: =F16 -> 0.33333333 | G48: =L16 -> 0.11166667 | H48: FMO/Subadult | J48: =T16 -> 0.27666667
A49: Low | B49: 0.33 | E49: Winter Rearing | F49: =D16 -> -0.11 | G49: =N16 -> 0.055
A50: Negligible | B50: 0 | E50: Migration
A51: Not Evaluated | B51: 0
E52: Normalization Weighting - UGR
E53: Life Stage | F53: Chinook | G53: Steelhead | J53: Bull Trout
E54: Spawning | F54: =B43 -> 0.57625 | G54: =J43 -> 0.025 | H54: Spawning/Resident | J54: =R43 -> 0.55
...

Sheet Chinook
B1: Spawning | E1: Winter Rearing | H1: Summer Rearing | K1: Migration
