Workbook

Sheet Action Type Definitions
C4: # | D4: New Activity Type | E4: Definition | F4: Original Activity Types Included (*former types included in multiple categories)
C5: 1 | D5: Protect Land (Easement and Acquisition)) | E5: Protect land and water with positive habitat value through conservation easements or title acquisition. Does not include water acquisition or leases. | F5: #1 Protect Land and Water
C6: 2 | D6: Instream Complexity Improvement | E6: Improve the complexity of the river below the ordinary high-water mark or bankfull stage. Action types may include placing large wood or boulders, gravel augmentation, riffle construction, pool construction, or channel reconstruction including channel remeandering and realignment, and developing new channels. | F6: #2 Channel Reconstruction
F7: #3 Pool Development
F8: #4 Riffle Construction
F9: #5 Meander/Oxbow Reconnection
F10: #6 Spawning Gravel Cleaning/Placement
F11: #11 Perennial Side Channel
F12: #12 Secondary Side Channel
F13: #14 Alcoves
F14: #16 Beaver Restoration and Management*
F15: #25 Rock Weirs
F16: #26 Boulder Placement
F17: #27 LWD Placement*
F18: #28 Modification or Removal of Bank Armoring*
F19: #29 Restore Banklines with LWD or Bioengineering*
C20: 3 | D20: Floodplain – Reconnect and Restore | E20: Actions that add complexity or improve connectivity within the current floodplain, or expand the floodplain area. Actions that improve the current floodplain may include vegetation or topography modifications, wetland enhancement, and beaver restoration. Actions that expand the floodplain may include levee modification and infrastructure modification/removal or instream modification intended to encourage floodplain reconnection. Actions may also add complexity to the floodplain through wood and other habitat feature additions. | F20: #7 Levee Modification/ Removal
F21: #8 Remove-Relocate Floodplain Infrastructure
F22: #9 Restore Topography and Vegetation
F23: #10 Floodplain Construction
F24: #13 Floodplain Pond/ Wetland Restoration
F25: #15 Hyporheic Off-Channel Habitat*
F26: #16 Beaver Restoration and Management*
F27: #27 LWD Placement*
F28: #28 Modification or Removal of Bank Armoring*
F29: #29 Restore Banklines with LWD or Bioengineering*
F30: #35 Road Decommissioning or Abandonment*
C31: 4 | D31: Riparian Vegetation Restoration | E31: Restoration of riparian vegetation through protection actions (e.g., riparian fencing, off-site stock water, non-native plant removal) or planting and establishment of new riparian or aquatic plants. | F31: #17 Riparian Fencing
F32: #18 Riparian Buffer Planting
F33: # 19 Thinning or Removal of Understory in Riparian Zone
F34: #20 Remove Non-Native Plants
C35: 5 | D35: Fish Passage – Barrier Removal and Replacement | E35: Removal or replacement of in-stream structures that impede fish passage and improve access for fish. Common examples include irrigation diversion structures and culvert removal or replacements. Actions in this category may address partial or full fish passage barriers | F35: #21 Dam Removal or Breaching
F36: #22 Barrier or culvert Replacement or Removal
F37: #23 Structure Passage at Diversions
C38: 6 | D38: Instream Flow Restoration | E38: Actions that increase flow amounts including actions such as acquiring/leasing instream flow rights or irrigation system upgrades that reduce irrigation withdrawal needs. | F38: #30 Acquire Instream Flow (Lease-Purchase)
C40: 7 | D40: Thermal Refuge Enhancement (reconnect, expand) | E40: Actions intended to reconnect or improve thermal refuge including spring reconnection and increase hyporheic connection. This work may also habitat enhancement like wood placement at thermal refuge features. | F40: #15 Hyporheic Off-Channel Habitat*
F41: #31 Improve Thermal Refuge (spring reconnect, other)
C42: 8 | D42: Water Quality Improvement (not including temperature) | E42: Actions that reduce pollutant inputs or improve water quality conditions, excluding temperature. Common sources include fine sediment from roads, agricultural runoff (e.g., nutrients, E. coli from livestock), and point source discharges. Specific action types may include road grading and drainage improvements, road decommissioning or abandonment, grazing management, and reduction or mitigation of point source impacts. | F42: #33 Reduce or Mitigate Point Sources
F43: #35 Road Decommissioning or Abandonment*
F44: #36 Road Grading or Drainage Improvements
...

Sheet Template
A1: Action-Limiting Factor Rating Sheet
B2: Action: ######
A3: Limiting Factor Category | B3: Directness of Benefit | C3: Frequency of Benefit | D3: Score (0-1)
B4: Rating | C4: Rating | D4: Calculated
A5: Anthropogenic Barriers | D5: =VLOOKUP(B5,$L$7:$M$9,2,FALSE)*VLOOKUP(C5,$L$11:$M$13,2,FALSE) -> #N/A
A6: Riparian Condition | D6: =VLOOKUP(B6,$L$7:$M$9,2,FALSE)*VLOOKUP(C6,$L$11:$M$13,2,FALSE) -> #N/A
A7: Floodplain Condition | D7: =VLOOKUP(B7,$L$7:$M$9,2,FALSE)*VLOOKUP(C7,$L$11:$M$13,2,FALSE) -> #N/A | K7: Direct | L7: D | M7: 1
A8: Side Channel and Wetland Habitat | D8: =VLOOKUP(B8,$L$7:$M$9,2,FALSE)*VLOOKUP(C8,$L$11:$M$13,2,FALSE) -> #N/A | K8: Indirect | L8: I | M8: 0.5
A9: Channel and Habitat Structure | D9: =VLOOKUP(B9,$L$7:$M$9,2,FALSE)*VLOOKUP(C9,$L$11:$M$13,2,FALSE) -> #N/A | K9: Negligible | L9: N | M9: 0.1
A10: Decreased Water Quantity | D10: =VLOOKUP(B10,$L$7:$M$9,2,FALSE)*VLOOKUP(C10,$L$11:$M$13,2,FALSE) -> #N/A
A11: Altered Flow Timing | D11: =VLOOKUP(B11,$L$7:$M$9,2,FALSE)*VLOOKUP(C11,$L$11:$M$13,2,FALSE) -> #N/A | K11: Common Benefit | L11: C | M11: 1
A12: Decreased Water Quantity | D12: =VLOOKUP(B12,$L$7:$M$9,2,FALSE)*VLOOKUP(C12,$L$11:$M$13,2,FALSE) -> #N/A | K12: Context-Dependant Benefit | L12: CD | M12: 0.5
A13: Decreased Sediment Quantity | D13: =VLOOKUP(B13,$L$7:$M$9,2,FALSE)*VLOOKUP(C13,$L$11:$M$13,2,FALSE) -> #N/A | K13: Rare Benefit | L13: R | M13: 0.1
A14: Increased Sediment Quantity (fines, embeddedness) | D14: =VLOOKUP(B14,$L$7:$M$9,2,FALSE)*VLOOKUP(C14,$L$11:$M$13,2,FALSE) -> #N/A
A15: Summer Water Temperature | D15: =VLOOKUP(B15,$L$7:$M$9,2,FALSE)*VLOOKUP(C15,$L$11:$M$13,2,FALSE) -> #N/A
A16: Winter Water Temperature | D16: =VLOOKUP(B16,$L$7:$M$9,2,FALSE)*VLOOKUP(C16,$L$11:$M$13,2,FALSE) -> #N/A
A17: Water Quality (DO, Toxics, Turbidity, Excess nutrients) | D17: =VLOOKUP(B17,$L$7:$M$9,2,FALSE)*VLOOKUP(C17,$L$11:$M$13,2,FALSE) -> #N/A
A18: Predation | D18: =VLOOKUP(B18,$L$7:$M$9,2,FALSE)*VLOOKUP(C18,$L$11:$M$13,2,FALSE) -> #N/A
A19: Altered Primary Productivity | D19: =VLOOKUP(B19,$L$7:$M$9,2,FALSE)*VLOOKUP(C19,$L$11:$M$13,2,FALSE) -> #N/A
A20: Non-Native Species Interactions & Competition | D20: =VLOOKUP(B20,$L$7:$M$9,2,FALSE)*VLOOKUP(C20,$L$11:$M$13,2,FALSE) -> #N/A
C21: Total | D21: =SUM(D5:D20) -> #N/A

Sheet Score
C3: TAC rates directness of benefit, and frequency of benefit, for each action type relative to a limiting factor
E6: Direct | F6: Indirect | G6: Negligible
D7: Numerical rating value | E7: 1 | F7: 0.5 | G7: 0.1
C8: Common Benefit | D8: 1 | E8: =$D8*E$7 -> 1 | F8: =$D8*F$7 -> 0.5 | G8: =$D8*G$7 -> 0.1
C9: Context-Dependant Benefit | D9: 0.5 | E9: =$D9*E$7 -> 0.5 | F9: =$D9*F$7 -> 0.25 | G9: =$D9*G$7 -> 0.05
C10: Rare Benefit | D10: 0.1 | E10: =$D10*E$7 -> 0.1 | F10: =$D10*F$7 -> 0.05 | G10: =$D10*G$7 -> 0.01
C13: Qualitative Rating | D13: Code | E13: Numerical Value (from Above) | F13: Definition
C14: Direct Benefit | D14: D | E14: =E7 -> 1 | F14: Action directly affects (benefits) a given limiting factor
C15: Indirect Benefit | D15: I | E15: =F7 -> 0.5 | F15: Action indirectly affects (benefits) a given limiting factor
C16: Negligible | D16: N | E16: =G7 -> 0.1 | F16: Action negligibly affects a given limiting factor
C18: Common Benefit | D18: C | E18: =D8 -> 1 | F18: Action commonly affects (benefits) a given limiting factor
C19: Context-Dependant Benefit | D19: CD | E19: =D9 -> 0.5 | F19: Action provides benefits to a limiting factor in certain contexts
C20: Rare Benefit | D20: R | E20: =D10 -> 0.1 | F20: Action rarely benefits a given limiting factor

Sheet Summary
C2: The following summary tables provide a relative sense of action type scoring based solely on their benefit to the collection of limiting factors considered.
C3: These scores would be most relevant if comparing two BSRs with identical fish use and limiting factor ratings.
C5: Table shows the relative likelihood of the limiting factors being addressed by the action types available | I5: Table shows the relative benefit of the action types based on their ability to address the collection of limiting factors considered.
C6: Limiting Factor | D6: Total | E6: Average | F6: Rank | I6: Action Type | K6: Total | L6: Average | M6: Rank
C7: Anthropogenic Barriers | D7: =E7*11 -> 1.58 | E7: =AVERAGE('1 - Protect'!D5,'2 - Inst. Complexity'!D5,'3 - Floodplain'!D5,'4 - Riparian Veg'!D5,'5 - Fish Passage'!D5,'6 - Instream Flow'!D5,'7 - Thermal Refuge'!D5,'8 - WQ Imp'!D5,'9 - Nutrient Enh'!D5,'10 - Upland'!D5,'11 - Species Manage.'!D5) -> 0.14363636 | F7: =RANK(D7,$D$7:$D$21,0) -> 14 | I7: 1 | J7: Protect Land (Easement and Acquisition)) | K7: ='1 - Protect'!D20 -> 3.2 | L7: =K7/COUNT($K$7:$K$17) -> 0.29090909 | M7: =RANK(K7,$K$7:$K$17,0) -> 5
C8: Riparian Condition | D8: =E8*11 -> 3.08 | E8: =AVERAGE('1 - Protect'!D6,'2 - Inst. Complexity'!D6,'3 - Floodplain'!D6,'4 - Riparian Veg'!D6,'5 - Fish Passage'!D6,'6 - Instream Flow'!D6,'7 - Thermal Refuge'!D6,'8 - WQ Imp'!D6,'9 - Nutrient Enh'!D6,'10 - Upland'!D6,'11 - Species Manage.'!D6) -> 0.28 | F8: =RANK(D8,$D$7:$D$21,0) -> 4 | I8: 2 | J8: Instream Complexity Improvement | K8: ='2 - Inst. Complexity'!D20 -> 4.59 | L8: =K8/COUNT($K$7:$K$17) -> 0.41727273 | M8: =RANK(K8,$K$7:$K$17,0) -> 3
C9: Floodplain Condition | D9: =E9*11 -> 3.62 | E9: =AVERAGE('1 - Protect'!D7,'2 - Inst. Complexity'!D7,'3 - Floodplain'!D7,'4 - Riparian Veg'!D7,'5 - Fish Passage'!D7,'6 - Instream Flow'!D7,'7 - Thermal Refuge'!D7,'8 - WQ Imp'!D7,'9 - Nutrient Enh'!D7,'10 - Upland'!D7,'11 - Species Manage.'!D7) -> 0.32909091 | F9: =RANK(D9,$D$7:$D$21,0) -> 2 | I9: 3 | J9: Floodplain – Reconnect and Restore | K9: ='3 - Floodplain'!D20 -> 6.82 | L9: =K9/COUNT($K$7:$K$17) -> 0.62 | M9: =RANK(K9,$K$7:$K$17,0) -> 1
C10: Side Channel and Wetland Habitat | D10: =E10*11 -> 3.59 | E10: =AVERAGE('1 - Protect'!D8,'2 - Inst. Complexity'!D8,'3 - Floodplain'!D8,'4 - Riparian Veg'!D8,'5 - Fish Passage'!D8,'6 - Instream Flow'!D8,'7 - Thermal Refuge'!D8,'8 - WQ Imp'!D8,'9 - Nutrient Enh'!D8,'10 - Upland'!D8,'11 - Species Manage.'!D8) -> 0.32636364 | F10: =RANK(D10,$D$7:$D$21,0) -> 3 | I10: 4 | J10: Riparian Vegetation Restoration | K10: ='4 - Riparian Veg'!D20 -> 5.68 | L10: =K10/COUNT($K$7:$K$17) -> 0.51636364 | M10: =RANK(K10,$K$7:$K$17,0) -> 2
C11: Channel and Habitat Structure | D11: =E11*11 -> 2.56 | E11: =AVERAGE('1 - Protect'!D9,'2 - Inst. Complexity'!D9,'3 - Floodplain'!D9,'4 - Riparian Veg'!D9,'5 - Fish Passage'!D9,'6 - Instream Flow'!D9,'7 - Thermal Refuge'!D9,'8 - WQ Imp'!D9,'9 - Nutrient Enh'!D9,'10 - Upland'!D9,'11 - Species Manage.'!D9) -> 0.23272727 | F11: =RANK(D11,$D$7:$D$21,0) -> 6 | I11: 5 | J11: Fish Passage – Barrier Removal and Replacement | K11: ='5 - Fish Passage'!D20 -> 2.38 | L11: =K11/COUNT($K$7:$K$17) -> 0.21636364 | M11: =RANK(K11,$K$7:$K$17,0) -> 7
C12: Decreased Water Quantity | D12: =E12*11 -> 1.86 | E12: =AVERAGE('1 - Protect'!D10,'2 - Inst. Complexity'!D10,'3 - Floodplain'!D10,'4 - Riparian Veg'!D10,'5 - Fish Passage'!D10,'6 - Instream Flow'!D10,'7 - Thermal Refuge'!D10,'8 - WQ Imp'!D10,'9 - Nutrient Enh'!D10,'10 - Upland'!D10,'11 - Species Manage.'!D10) -> 0.16909091 | F12: =RANK(D12,$D$7:$D$21,0) -> 10 | I12: 6 | J12: Instream Flow Restoration | K12: ='6 - Instream Flow'!D20 -> 4.32 | L12: =K12/COUNT($K$7:$K$17) -> 0.39272727 | M12: =RANK(K12,$K$7:$K$17,0) -> 4
C13: Altered Flow Timing | D13: =E13*11 -> 1.64 | E13: =AVERAGE('1 - Protect'!D11,'2 - Inst. Complexity'!D11,'3 - Floodplain'!D11,'4 - Riparian Veg'!D11,'5 - Fish Passage'!D11,'6 - Instream Flow'!D11,'7 - Thermal Refuge'!D11,'8 - WQ Imp'!D11,'9 - Nutrient Enh'!D11,'10 - Upland'!D11,'11 - Species Manage.'!D11) -> 0.14909091 | F13: =RANK(D13,$D$7:$D$21,0) -> 13 | I13: 7 | J13: Thermal Refuge Enhancement (reconnect, expand) | K13: ='7 - Thermal Refuge'!D20 -> 2.49 | L13: =K13/COUNT($K$7:$K$17) -> 0.22636364 | M13: =RANK(K13,$K$7:$K$17,0) -> 6
C14: Decreased Sediment Quantity | D14: =E14*11 -> 1.86 | E14: =AVERAGE('1 - Protect'!D12,'2 - Inst. Complexity'!D12,'3 - Floodplain'!D12,'4 - Riparian Veg'!D12,'5 - Fish Passage'!D12,'6 - Instream Flow'!D12,'7 - Thermal Refuge'!D12,'8 - WQ Imp'!D12,'9 - Nutrient Enh'!D12,'10 - Upland'!D12,'11 - Species Manage.'!D12) -> 0.16909091 | F14: =RANK(D14,$D$7:$D$21,0) -> 10 | I14: 8 | J14: Water Quality Improvement (not including temperature) | K14: ='8 - WQ Imp'!D21 -> 1.87 | L14: =K14/COUNT($K$7:$K$17) -> 0.17 | M14: =RANK(K14,$K$7:$K$17,0) -> 9
C15: Increased Sediment Quantity (fines, embeddedness) | D15: =E15*11 -> 2.3 | E15: =AVERAGE('1 - Protect'!D13,'2 - Inst. Complexity'!D13,'3 - Floodplain'!D13,'4 - Riparian Veg'!D13,'5 - Fish Passage'!D13,'6 - Instream Flow'!D13,'7 - Thermal Refuge'!D13,'8 - WQ Imp'!D13,'9 - Nutrient Enh'!D13,'10 - Upland'!D13,'11 - Species Manage.'!D13) -> 0.20909091 | F15: =RANK(D15,$D$7:$D$21,0) -> 8 | I15: 9 | J15: Nutrient Enhancement | K15: ='9 - Nutrient Enh'!D20 -> 1.42 | L15: =K15/COUNT($K$7:$K$17) -> 0.12909091 | M15: =RANK(K15,$K$7:$K$17,0) -> 11
C16: Summer Water Temperature | D16: =E16*11 -> 3.87 | E16: =AVERAGE('1 - Protect'!D14,'2 - Inst. Complexity'!D14,'3 - Floodplain'!D14,'4 - Riparian Veg'!D14,'5 - Fish Passage'!D14,'6 - Instream Flow'!D14,'7 - Thermal Refuge'!D14,'8 - WQ Imp'!D14,'9 - Nutrient Enh'!D14,'10 - Upland'!D14,'11 - Species Manage.'!D14) -> 0.35181818 | F16: =RANK(D16,$D$7:$D$21,0) -> 1 | I16: 10 | J16: Upland Treatments | K16: ='10 - Upland'!D20 -> 1.83 | L16: =K16/COUNT($K$7:$K$17) -> 0.16636364 | M16: =RANK(K16,$K$7:$K$17,0) -> 10
C17: Winter Water Temperature | D17: =E17*11 -> 1.91 | E17: =AVERAGE('1 - Protect'!D15,'2 - Inst. Complexity'!D15,'3 - Floodplain'!D15,'4 - Riparian Veg'!D15,'5 - Fish Passage'!D15,'6 - Instream Flow'!D15,'7 - Thermal Refuge'!D15,'8 - WQ Imp'!D15,'9 - Nutrient Enh'!D15,'10 - Upland'!D15,'11 - Species Manage.'!D15) -> 0.17363636 | F17: =RANK(D17,$D$7:$D$21,0) -> 9 | I17: 11 | J17: Species Management (non-native or unnatural) | K17: ='11 - Species Manage.'!D20 -> 2.13 | L17: =K17/COUNT($K$7:$K$17) -> 0.19363636 | M17: =RANK(K17,$K$7:$K$17,0) -> 8
C18: Water Quality (DO, Toxics, Turbidity, Excess nutrients) | D18: =E18*11 -> 1.8 | E18: =AVERAGE('1 - Protect'!D16,'2 - Inst. Complexity'!D16,'3 - Floodplain'!D16,'4 - Riparian Veg'!D16,'5 - Fish Passage'!D16,'6 - Instream Flow'!D16,'7 - Thermal Refuge'!D16,'8 - WQ Imp'!D16,'9 - Nutrient Enh'!D16,'10 - Upland'!D16,'11 - Species Manage.'!D16) -> 0.16363636 | F18: =RANK(D18,$D$7:$D$21,0) -> 12 | K18: =SUM(K7:K17) -> 36.73 | L18: =SUM(L7:L17) -> 3.3390909
C19: Predation | D19: =E19*11 -> 2.49 | E19: =AVERAGE('1 - Protect'!D17,'2 - Inst. Complexity'!D17,'3 - Floodplain'!D17,'4 - Riparian Veg'!D17,'5 - Fish Passage'!D17,'6 - Instream Flow'!D17,'7 - Thermal Refuge'!D17,'8 - WQ Imp'!D17,'9 - Nutrient Enh'!D17,'10 - Upland'!D17,'11 - Species Manage.'!D17) -> 0.22636364 | F19: =RANK(D19,$D$7:$D$21,0) -> 7
C20: Altered Primary Productivity | D20: =E20*11 -> 3.06 | E20: =AVERAGE('1 - Protect'!D18,'2 - Inst. Complexity'!D18,'3 - Floodplain'!D18,'4 - Riparian Veg'!D18,'5 - Fish Passage'!D18,'6 - Instream Flow'!D18,'7 - Thermal Refuge'!D18,'8 - WQ Imp'!D18,'9 - Nutrient Enh'!D18,'10 - Upland'!D18,'11 - Species Manage.'!D18) -> 0.27818182 | F20: =RANK(D20,$D$7:$D$21,0) -> 5
C21: Non-Native Species Interactions & Competition | D21: =E21*11 -> 1.5 | E21: =AVERAGE('1 - Protect'!D19,'2 - Inst. Complexity'!D19,'3 - Floodplain'!D19,'4 - Riparian Veg'!D19,'5 - Fish Passage'!D19,'6 - Instream Flow'!D19,'7 - Thermal Refuge'!D19,'8 - WQ Imp'!D19,'9 - Nutrient Enh'!D19,'10 - Upland'!D19,'11 - Species Manage.'!D19) -> 0.13636364 | F21: =RANK(D21,$D$7:$D$21,0) -> 15
D22: =SUM(D7:D21) -> 36.72 | E22: =SUM(E7:E21) -> 3.3381818
C24: Max Possible per Limiting Factor | D24: 11
C25: Max Possible per Action Type | D25: 15

Sheet 1 - Protect
A1: Action-Limiting Factor Rating Sheet
B2: Action: Protect Land
A3: Limiting Factor Category | B3: Directness of Benefit | C3: Frequency of Benefit | D3: Score (0-1)
B4: Rating | C4: Rating | D4: Calculated
A5: Anthropogenic Barriers | B5: I | C5: CD | D5: =VLOOKUP(B5,$L$7:$M$9,2,FALSE)*VLOOKUP(C5,$L$11:$M$13,2,FALSE) -> 0.25
A6: Riparian Condition | B6: I | C6: C | D6: =VLOOKUP(B6,$L$7:$M$9,2,FALSE)*VLOOKUP(C6,$L$11:$M$13,2,FALSE) -> 0.5
A7: Floodplain Condition | B7: I | C7: CD | D7: =VLOOKUP(B7,$L$7:$M$9,2,FALSE)*VLOOKUP(C7,$L$11:$M$13,2,FALSE) -> 0.25 | K7: Direct | L7: D | M7: =Score!E14 -> 1
A8: Side Channel and Wetland Habitat | B8: I | C8: CD | D8: =VLOOKUP(B8,$L$7:$M$9,2,FALSE)*VLOOKUP(C8,$L$11:$M$13,2,FALSE) -> 0.25 | K8: Indirect | L8: I | M8: =Score!E15 -> 0.5
A9: Channel and Habitat Structure | B9: I | C9: CD | D9: =VLOOKUP(B9,$L$7:$M$9,2,FALSE)*VLOOKUP(C9,$L$11:$M$13,2,FALSE) -> 0.25 | K9: Negligible | L9: N | M9: =Score!E16 -> 0.1
A10: Decreased Water Quantity | B10: I | C10: CD | D10: =VLOOKUP(B10,$L$7:$M$9,2,FALSE)*VLOOKUP(C10,$L$11:$M$13,2,FALSE) -> 0.25
A11: Altered Flow Timing | B11: I | C11: CD | D11: =VLOOKUP(B11,$L$7:$M$9,2,FALSE)*VLOOKUP(C11,$L$11:$M$13,2,FALSE) -> 0.25 | K11: Common Benefit | L11: C | M11: =Score!E18 -> 1
A12: Decreased Sediment Quantity | B12: I | C12: CD | D12: =VLOOKUP(B12,$L$7:$M$9,2,FALSE)*VLOOKUP(C12,$L$11:$M$13,2,FALSE) -> 0.25 | K12: Context-Dependant Benefit | L12: CD | M12: =Score!E19 -> 0.5
A13: Increased Sediment Quantity (fines, embeddedness) | B13: I | C13: CD | D13: =VLOOKUP(B13,$L$7:$M$9,2,FALSE)*VLOOKUP(C13,$L$11:$M$13,2,FALSE) -> 0.25 | K13: Rare Benefit | L13: R | M13: =Score!E20 -> 0.1
A14: Summer Water Temperature | B14: I | C14: R | D14: =VLOOKUP(B14,$L$7:$M$9,2,FALSE)*VLOOKUP(C14,$L$11:$M$13,2,FALSE) -> 0.05
A15: Winter Water Temperature | B15: I | C15: R | D15: =VLOOKUP(B15,$L$7:$M$9,2,FALSE)*VLOOKUP(C15,$L$11:$M$13,2,FALSE) -> 0.05
A16: Water Quality (DO, Toxics, Turbidity, Excess nutrients) | B16: I | C16: CD | D16: =VLOOKUP(B16,$L$7:$M$9,2,FALSE)*VLOOKUP(C16,$L$11:$M$13,2,FALSE) -> 0.25
A17: Predation | B17: I | C17: R | D17: =VLOOKUP(B17,$L$7:$M$9,2,FALSE)*VLOOKUP(C17,$L$11:$M$13,2,FALSE) -> 0.05
A18: Altered Primary Productivity | B18: I | C18: CD | D18: =VLOOKUP(B18,$L$7:$M$9,2,FALSE)*VLOOKUP(C18,$L$11:$M$13,2,FALSE) -> 0.25
A19: Non-Native Species Interactions & Competition | B19: I | C19: R | D19: =VLOOKUP(B19,$L$7:$M$9,2,FALSE)*VLOOKUP(C19,$L$11:$M$13,2,FALSE) -> 0.05
C20: Total | D20: =SUM(D5:D19) -> 3.2

Sheet 2 - Inst. Complexity
A1: Action-Limiting Factor Rating Sheet
B2: Action: Instream Complexity Improvement
A3: Limiting Factor Category | B3: Directness of Benefit | C3: Frequency of Benefit | D3: Score (0-1)
B4: Rating | C4: Rating | D4: Calculated
A5: Anthropogenic Barriers | B5: N | C5: R | D5: =VLOOKUP(B5,$L$7:$M$9,2,FALSE)*VLOOKUP(C5,$L$11:$M$13,2,FALSE) -> 0.01
A6: Riparian Condition | B6: I | C6: CD | D6: =VLOOKUP(B6,$L$7:$M$9,2,FALSE)*VLOOKUP(C6,$L$11:$M$13,2,FALSE) -> 0.25
A7: Floodplain Condition | B7: I | C7: C | D7: =VLOOKUP(B7,$L$7:$M$9,2,FALSE)*VLOOKUP(C7,$L$11:$M$13,2,FALSE) -> 0.5 | K7: Direct | L7: D | M7: =Score!E14 -> 1
A8: Side Channel and Wetland Habitat | B8: D | C8: C | D8: =VLOOKUP(B8,$L$7:$M$9,2,FALSE)*VLOOKUP(C8,$L$11:$M$13,2,FALSE) -> 1 | K8: Indirect | L8: I | M8: =Score!E15 -> 0.5
A9: Channel and Habitat Structure | B9: D | C9: C | D9: =VLOOKUP(B9,$L$7:$M$9,2,FALSE)*VLOOKUP(C9,$L$11:$M$13,2,FALSE) -> 1 | K9: Negligible | L9: N | M9: =Score!E16 -> 0.1
A10: Decreased Water Quantity | B10: N | C10: R | D10: =VLOOKUP(B10,$L$7:$M$9,2,FALSE)*VLOOKUP(C10,$L$11:$M$13,2,FALSE) -> 0.01
A11: Altered Flow Timing | B11: N | C11: CD | D11: =VLOOKUP(B11,$L$7:$M$9,2,FALSE)*VLOOKUP(C11,$L$11:$M$13,2,FALSE) -> 0.05 | K11: Common Benefit | L11: C | M11: =Score!E18 -> 1
A12: Decreased Sediment Quantity | B12: I | C12: CD | D12: =VLOOKUP(B12,$L$7:$M$9,2,FALSE)*VLOOKUP(C12,$L$11:$M$13,2,FALSE) -> 0.25 | K12: Context-Dependant Benefit | L12: CD | M12: =Score!E19 -> 0.5
A13: Increased Sediment Quantity (fines, embeddedness) | B13: I | C13: C | D13: =VLOOKUP(B13,$L$7:$M$9,2,FALSE)*VLOOKUP(C13,$L$11:$M$13,2,FALSE) -> 0.5 | K13: Rare Benefit | L13: R | M13: =Score!E20 -> 0.1
A14: Summer Water Temperature | B14: I | C14: CD | D14: =VLOOKUP(B14,$L$7:$M$9,2,FALSE)*VLOOKUP(C14,$L$11:$M$13,2,FALSE) -> 0.25
A15: Winter Water Temperature | B15: I | C15: CD | D15: =VLOOKUP(B15,$L$7:$M$9,2,FALSE)*VLOOKUP(C15,$L$11:$M$13,2,FALSE) -> 0.25
A16: Water Quality (DO, Toxics, Turbidity, Excess nutrients) | B16: N | C16: R | D16: =VLOOKUP(B16,$L$7:$M$9,2,FALSE)*VLOOKUP(C16,$L$11:$M$13,2,FALSE) -> 0.01
A17: Predation | B17: I | C17: CD | D17: =VLOOKUP(B17,$L$7:$M$9,2,FALSE)*VLOOKUP(C17,$L$11:$M$13,2,FALSE) -> 0.25
A18: Altered Primary Productivity | B18: N | C18: R | D18: =VLOOKUP(B18,$L$7:$M$9,2,FALSE)*VLOOKUP(C18,$L$11:$M$13,2,FALSE) -> 0.01
A19: Non-Native Species Interactions & Competition | B19: I | C19: CD | D19: =VLOOKUP(B19,$L$7:$M$9,2,FALSE)*VLOOKUP(C19,$L$11:$M$13,2,FALSE) -> 0.25
C20: Total | D20: =SUM(D5:D19) -> 4.59

Sheet 3 - Floodplain
A1: Action-Limiting Factor Rating Sheet (2 action types only)
B2: Action: Floodplain Restoration
A3: Limiting Factor Category | B3: Directness of Benefit | C3: Frequency of Benefit | D3: Score (0-1)
B4: Rating | C4: Rating | D4: Calculated
A5: Anthropogenic Barriers | B5: N | C5: R | D5: =VLOOKUP(B5,$L$7:$M$9,2,FALSE)*VLOOKUP(C5,$L$11:$M$13,2,FALSE) -> 0.01
A6: Riparian Condition | B6: I | C6: C | D6: =VLOOKUP(B6,$L$7:$M$9,2,FALSE)*VLOOKUP(C6,$L$11:$M$13,2,FALSE) -> 0.5
A7: Floodplain Condition | B7: D | C7: C | D7: =VLOOKUP(B7,$L$7:$M$9,2,FALSE)*VLOOKUP(C7,$L$11:$M$13,2,FALSE) -> 1 | K7: Direct | L7: D | M7: =Score!E14 -> 1
A8: Side Channel and Wetland Habitat | B8: D | C8: C | D8: =VLOOKUP(B8,$L$7:$M$9,2,FALSE)*VLOOKUP(C8,$L$11:$M$13,2,FALSE) -> 1 | K8: Indirect | L8: I | M8: =Score!E15 -> 0.5
A9: Channel and Habitat Structure | B9: I | C9: C | D9: =VLOOKUP(B9,$L$7:$M$9,2,FALSE)*VLOOKUP(C9,$L$11:$M$13,2,FALSE) -> 0.5 | K9: Negligible | L9: N | M9: =Score!E16 -> 0.1
A10: Decreased Water Quantity | B10: I | C10: CD | D10: =VLOOKUP(B10,$L$7:$M$9,2,FALSE)*VLOOKUP(C10,$L$11:$M$13,2,FALSE) -> 0.25
A11: Altered Flow Timing | B11: I | C11: CD | D11: =VLOOKUP(B11,$L$7:$M$9,2,FALSE)*VLOOKUP(C11,$L$11:$M$13,2,FALSE) -> 0.25 | K11: Common Benefit | L11: C | M11: =Score!E18 -> 1
A12: Decreased Sediment Quantity | B12: D | C12: C | D12: =VLOOKUP(B12,$L$7:$M$9,2,FALSE)*VLOOKUP(C12,$L$11:$M$13,2,FALSE) -> 1 | K12: Context-Dependant Benefit | L12: CD | M12: =Score!E19 -> 0.5
A13: Increased Sediment Quantity (fines, embeddedness) | B13: D | C13: CD | D13: =VLOOKUP(B13,$L$7:$M$9,2,FALSE)*VLOOKUP(C13,$L$11:$M$13,2,FALSE) -> 0.5 | K13: Rare Benefit | L13: R | M13: =Score!E20 -> 0.1
A14: Summer Water Temperature | B14: D | C14: CD | D14: =VLOOKUP(B14,$L$7:$M$9,2,FALSE)*VLOOKUP(C14,$L$11:$M$13,2,FALSE) -> 0.5
A15: Winter Water Temperature | B15: D | C15: CD | D15: =VLOOKUP(B15,$L$7:$M$9,2,FALSE)*VLOOKUP(C15,$L$11:$M$13,2,FALSE) -> 0.5
A16: Water Quality (DO, Toxics, Turbidity, Excess nutrients) | B16: I | C16: CD | D16: =VLOOKUP(B16,$L$7:$M$9,2,FALSE)*VLOOKUP(C16,$L$11:$M$13,2,FALSE) -> 0.25
A17: Predation | B17: N | C17: R | D17: =VLOOKUP(B17,$L$7:$M$9,2,FALSE)*VLOOKUP(C17,$L$11:$M$13,2,FALSE) -> 0.01 | E17: Uncertainty
A18: Altered Primary Productivity | B18: I | C18: C | D18: =VLOOKUP(B18,$L$7:$M$9,2,FALSE)*VLOOKUP(C18,$L$11:$M$13,2,FALSE) -> 0.5
A19: Non-Native Species Interactions & Competition | B19: N | C19: CD | D19: =VLOOKUP(B19,$L$7:$M$9,2,FALSE)*VLOOKUP(C19,$L$11:$M$13,2,FALSE) -> 0.05
C20: Total | D20: =SUM(D5:D19) -> 6.82

Sheet 4 - Riparian Veg
A1: Action-Limiting Factor Rating Sheet
B2: Action: Riparian Vegetation Restoration
A3: Limiting Factor Category | B3: Directness of Benefit | C3: Frequency of Benefit | D3: Score (0-1)
B4: Rating | C4: Rating | D4: Calculated
A5: Anthropogenic Barriers | B5: N | C5: R | D5: =VLOOKUP(B5,$L$7:$M$9,2,FALSE)*VLOOKUP(C5,$L$11:$M$13,2,FALSE) -> 0.01
A6: Riparian Condition | B6: D | C6: C | D6: =VLOOKUP(B6,$L$7:$M$9,2,FALSE)*VLOOKUP(C6,$L$11:$M$13,2,FALSE) -> 1
A7: Floodplain Condition | B7: D | C7: C | D7: =VLOOKUP(B7,$L$7:$M$9,2,FALSE)*VLOOKUP(C7,$L$11:$M$13,2,FALSE) -> 1 | K7: Direct | L7: D | M7: =Score!E14 -> 1
A8: Side Channel and Wetland Habitat | B8: I | C8: C | D8: =VLOOKUP(B8,$L$7:$M$9,2,FALSE)*VLOOKUP(C8,$L$11:$M$13,2,FALSE) -> 0.5 | K8: Indirect | L8: I | M8: =Score!E15 -> 0.5
A9: Channel and Habitat Structure | B9: D | C9: CD | D9: =VLOOKUP(B9,$L$7:$M$9,2,FALSE)*VLOOKUP(C9,$L$11:$M$13,2,FALSE) -> 0.5 | K9: Negligible | L9: N | M9: =Score!E16 -> 0.1
A10: Decreased Water Quantity | B10: N | C10: R | D10: =VLOOKUP(B10,$L$7:$M$9,2,FALSE)*VLOOKUP(C10,$L$11:$M$13,2,FALSE) -> 0.01
A11: Altered Flow Timing | B11: I | C11: CD | D11: =VLOOKUP(B11,$L$7:$M$9,2,FALSE)*VLOOKUP(C11,$L$11:$M$13,2,FALSE) -> 0.25 | K11: Common Benefit | L11: C | M11: =Score!E18 -> 1
A12: Decreased Sediment Quantity | B12: N | C12: R | D12: =VLOOKUP(B12,$L$7:$M$9,2,FALSE)*VLOOKUP(C12,$L$11:$M$13,2,FALSE) -> 0.01 | K12: Context-Dependant Benefit | L12: CD | M12: =Score!E19 -> 0.5
A13: Increased Sediment Quantity (fines, embeddedness) | B13: D | C13: CD | D13: =VLOOKUP(B13,$L$7:$M$9,2,FALSE)*VLOOKUP(C13,$L$11:$M$13,2,FALSE) -> 0.5 | K13: Rare Benefit | L13: R | M13: =Score!E20 -> 0.1
A14: Summer Water Temperature | B14: D | C14: CD | D14: =VLOOKUP(B14,$L$7:$M$9,2,FALSE)*VLOOKUP(C14,$L$11:$M$13,2,FALSE) -> 0.5
A15: Winter Water Temperature | B15: I | C15: R | D15: =VLOOKUP(B15,$L$7:$M$9,2,FALSE)*VLOOKUP(C15,$L$11:$M$13,2,FALSE) -> 0.05
A16: Water Quality (DO, Toxics, Turbidity, Excess nutrients) | B16: I | C16: CD | D16: =VLOOKUP(B16,$L$7:$M$9,2,FALSE)*VLOOKUP(C16,$L$11:$M$13,2,FALSE) -> 0.25
A17: Predation | B17: N | C17: CD | D17: =VLOOKUP(B17,$L$7:$M$9,2,FALSE)*VLOOKUP(C17,$L$11:$M$13,2,FALSE) -> 0.05
A18: Altered Primary Productivity | B18: D | C18: C | D18: =VLOOKUP(B18,$L$7:$M$9,2,FALSE)*VLOOKUP(C18,$L$11:$M$13,2,FALSE) -> 1
A19: Non-Native Species Interactions & Competition | B19: I | C19: R | D19: =VLOOKUP(B19,$L$7:$M$9,2,FALSE)*VLOOKUP(C19,$L$11:$M$13,2,FALSE) -> 0.05
C20: Total | D20: =SUM(D5:D19) -> 5.68

Sheet 5 - Fish Passage
A1: Action-Limiting Factor Rating Sheet (2 action types only)
B2: Action: Fish Passage – Barrier Removal and Replacement
A3: Limiting Factor Category | B3: Directness of Benefit | C3: Frequency of Benefit | D3: Score (0-1)
B4: Rating | C4: Rating | D4: Calculated
A5: Anthropogenic Barriers | B5: D | C5: C | D5: =VLOOKUP(B5,$L$7:$M$9,2,FALSE)*VLOOKUP(C5,$L$11:$M$13,2,FALSE) -> 1
A6: Riparian Condition | B6: I | C6: R | D6: =VLOOKUP(B6,$L$7:$M$9,2,FALSE)*VLOOKUP(C6,$L$11:$M$13,2,FALSE) -> 0.05
A7: Floodplain Condition | B7: I | C7: CD | D7: =VLOOKUP(B7,$L$7:$M$9,2,FALSE)*VLOOKUP(C7,$L$11:$M$13,2,FALSE) -> 0.25 | K7: Direct | L7: D | M7: =Score!E14 -> 1
A8: Side Channel and Wetland Habitat | B8: I | C8: R | D8: =VLOOKUP(B8,$L$7:$M$9,2,FALSE)*VLOOKUP(C8,$L$11:$M$13,2,FALSE) -> 0.05 | K8: Indirect | L8: I | M8: =Score!E15 -> 0.5
A9: Channel and Habitat Structure | B9: I | C9: CD | D9: =VLOOKUP(B9,$L$7:$M$9,2,FALSE)*VLOOKUP(C9,$L$11:$M$13,2,FALSE) -> 0.25 | K9: Negligible | L9: N | M9: =Score!E16 -> 0.1
A10: Decreased Water Quantity | B10: N | C10: R | D10: =VLOOKUP(B10,$L$7:$M$9,2,FALSE)*VLOOKUP(C10,$L$11:$M$13,2,FALSE) -> 0.01
A11: Altered Flow Timing | B11: I | C11: R | D11: =VLOOKUP(B11,$L$7:$M$9,2,FALSE)*VLOOKUP(C11,$L$11:$M$13,2,FALSE) -> 0.05 | K11: Common Benefit | L11: C | M11: =Score!E18 -> 1
A12: Decreased Sediment Quantity | B12: I | C12: R | D12: =VLOOKUP(B12,$L$7:$M$9,2,FALSE)*VLOOKUP(C12,$L$11:$M$13,2,FALSE) -> 0.05 | K12: Context-Dependant Benefit | L12: CD | M12: =Score!E19 -> 0.5
A13: Increased Sediment Quantity (fines, embeddedness) | B13: I | C13: CD | D13: =VLOOKUP(B13,$L$7:$M$9,2,FALSE)*VLOOKUP(C13,$L$11:$M$13,2,FALSE) -> 0.25 | K13: Rare Benefit | L13: R | M13: =Score!E20 -> 0.1
A14: Summer Water Temperature | B14: I | C14: R | D14: =VLOOKUP(B14,$L$7:$M$9,2,FALSE)*VLOOKUP(C14,$L$11:$M$13,2,FALSE) -> 0.05
A15: Winter Water Temperature | B15: N | C15: R | D15: =VLOOKUP(B15,$L$7:$M$9,2,FALSE)*VLOOKUP(C15,$L$11:$M$13,2,FALSE) -> 0.01
A16: Water Quality (DO, Toxics, Turbidity, Excess nutrients) | B16: I | C16: CD | D16: =VLOOKUP(B16,$L$7:$M$9,2,FALSE)*VLOOKUP(C16,$L$11:$M$13,2,FALSE) -> 0.25
A17: Predation | B17: I | C17: R | D17: =VLOOKUP(B17,$L$7:$M$9,2,FALSE)*VLOOKUP(C17,$L$11:$M$13,2,FALSE) -> 0.05
A18: Altered Primary Productivity | B18: N | C18: R | D18: =VLOOKUP(B18,$L$7:$M$9,2,FALSE)*VLOOKUP(C18,$L$11:$M$13,2,FALSE) -> 0.01
A19: Non-Native Species Interactions & Competition | B19: I | C19: R | D19: =VLOOKUP(B19,$L$7:$M$9,2,FALSE)*VLOOKUP(C19,$L$11:$M$13,2,FALSE) -> 0.05
C20: Total | D20: =SUM(D5:D19) -> 2.38

Sheet 6 - Instream Flow
A1: Action-Limiting Factor Rating Sheet
B2: Action: ######
A3: Limiting Factor Category | B3: Directness of Benefit | C3: Frequency of Benefit | D3: Score (0-1)
B4: Rating | C4: Rating | D4: Calculated
A5: Anthropogenic Barriers | B5: I | C5: CD | D5: =VLOOKUP(B5,$L$7:$M$9,2,FALSE)*VLOOKUP(C5,$L$11:$M$13,2,FALSE) -> 0.25
A6: Riparian Condition | B6: I | C6: CD | D6: =VLOOKUP(B6,$L$7:$M$9,2,FALSE)*VLOOKUP(C6,$L$11:$M$13,2,FALSE) -> 0.25
A7: Floodplain Condition | B7: I | C7: CD | D7: =VLOOKUP(B7,$L$7:$M$9,2,FALSE)*VLOOKUP(C7,$L$11:$M$13,2,FALSE) -> 0.25 | K7: Direct | L7: D | M7: =Score!E14 -> 1
A8: Side Channel and Wetland Habitat | B8: D | C8: CD | D8: =VLOOKUP(B8,$L$7:$M$9,2,FALSE)*VLOOKUP(C8,$L$11:$M$13,2,FALSE) -> 0.5 | K8: Indirect | L8: I | M8: =Score!E15 -> 0.5
A9: Channel and Habitat Structure | B9: N | C9: R | D9: =VLOOKUP(B9,$L$7:$M$9,2,FALSE)*VLOOKUP(C9,$L$11:$M$13,2,FALSE) -> 0.01 | K9: Negligible | L9: N | M9: =Score!E16 -> 0.1
A10: Decreased Water Quantity | B10: D | C10: C | D10: =VLOOKUP(B10,$L$7:$M$9,2,FALSE)*VLOOKUP(C10,$L$11:$M$13,2,FALSE) -> 1
A11: Altered Flow Timing | B11: D | C11: CD | D11: =VLOOKUP(B11,$L$7:$M$9,2,FALSE)*VLOOKUP(C11,$L$11:$M$13,2,FALSE) -> 0.5 | K11: Common Benefit | L11: C | M11: =Score!E18 -> 1
A12: Decreased Sediment Quantity | B12: N | C12: R | D12: =VLOOKUP(B12,$L$7:$M$9,2,FALSE)*VLOOKUP(C12,$L$11:$M$13,2,FALSE) -> 0.01 | K12: Context-Dependant Benefit | L12: CD | M12: =Score!E19 -> 0.5
A13: Increased Sediment Quantity (fines, embeddedness) | B13: N | C13: R | D13: =VLOOKUP(B13,$L$7:$M$9,2,FALSE)*VLOOKUP(C13,$L$11:$M$13,2,FALSE) -> 0.01 | K13: Rare Benefit | L13: R | M13: =Score!E20 -> 0.1
A14: Summer Water Temperature | B14: D | C14: C | D14: =VLOOKUP(B14,$L$7:$M$9,2,FALSE)*VLOOKUP(C14,$L$11:$M$13,2,FALSE) -> 1
A15: Winter Water Temperature | B15: N | C15: R | D15: =VLOOKUP(B15,$L$7:$M$9,2,FALSE)*VLOOKUP(C15,$L$11:$M$13,2,FALSE) -> 0.01
A16: Water Quality (DO, Toxics, Turbidity, Excess nutrients) | B16: D | C16: CD | D16: =VLOOKUP(B16,$L$7:$M$9,2,FALSE)*VLOOKUP(C16,$L$11:$M$13,2,FALSE) -> 0.5
A17: Predation | B17: N | C17: R | D17: =VLOOKUP(B17,$L$7:$M$9,2,FALSE)*VLOOKUP(C17,$L$11:$M$13,2,FALSE) -> 0.01
A18: Altered Primary Productivity | B18: N | C18: R | D18: =VLOOKUP(B18,$L$7:$M$9,2,FALSE)*VLOOKUP(C18,$L$11:$M$13,2,FALSE) -> 0.01
A19: Non-Native Species Interactions & Competition | B19: N | C19: R | D19: =VLOOKUP(B19,$L$7:$M$9,2,FALSE)*VLOOKUP(C19,$L$11:$M$13,2,FALSE) -> 0.01
C20: Total | D20: =SUM(D5:D19) -> 4.32

Sheet 7 - Thermal Refuge
A1: Action-Limiting Factor Rating Sheet
B2: Action: Thermal Refuge Enhancement
A3: Limiting Factor Category | B3: Directness of Benefit | C3: Frequency of Benefit | D3: Score (0-1)
B4: Rating | C4: Rating | D4: Calculated
A5: Anthropogenic Barriers | B5: N | C5: R | D5: =VLOOKUP(B5,$L$7:$M$9,2,FALSE)*VLOOKUP(C5,$L$11:$M$13,2,FALSE) -> 0.01
A6: Riparian Condition | B6: N | C6: R | D6: =VLOOKUP(B6,$L$7:$M$9,2,FALSE)*VLOOKUP(C6,$L$11:$M$13,2,FALSE) -> 0.01
A7: Floodplain Condition | B7: N | C7: CD | D7: =VLOOKUP(B7,$L$7:$M$9,2,FALSE)*VLOOKUP(C7,$L$11:$M$13,2,FALSE) -> 0.05 | K7: Direct | L7: D | M7: =Score!E14 -> 1
A8: Side Channel and Wetland Habitat | B8: I | C8: CD | D8: =VLOOKUP(B8,$L$7:$M$9,2,FALSE)*VLOOKUP(C8,$L$11:$M$13,2,FALSE) -> 0.25 | K8: Indirect | L8: I | M8: =Score!E15 -> 0.5
A9: Channel and Habitat Structure | B9: N | C9: R | D9: =VLOOKUP(B9,$L$7:$M$9,2,FALSE)*VLOOKUP(C9,$L$11:$M$13,2,FALSE) -> 0.01 | K9: Negligible | L9: N | M9: =Score!E16 -> 0.1
A10: Decreased Water Quantity | B10: I | C10: R | D10: =VLOOKUP(B10,$L$7:$M$9,2,FALSE)*VLOOKUP(C10,$L$11:$M$13,2,FALSE) -> 0.05
A11: Altered Flow Timing | B11: N | C11: R | D11: =VLOOKUP(B11,$L$7:$M$9,2,FALSE)*VLOOKUP(C11,$L$11:$M$13,2,FALSE) -> 0.01 | K11: Common Benefit | L11: C | M11: =Score!E18 -> 1
A12: Decreased Sediment Quantity | B12: N | C12: R | D12: =VLOOKUP(B12,$L$7:$M$9,2,FALSE)*VLOOKUP(C12,$L$11:$M$13,2,FALSE) -> 0.01 | K12: Context-Dependant Benefit | L12: CD | M12: =Score!E19 -> 0.5
A13: Increased Sediment Quantity (fines, embeddedness) | B13: N | C13: R | D13: =VLOOKUP(B13,$L$7:$M$9,2,FALSE)*VLOOKUP(C13,$L$11:$M$13,2,FALSE) -> 0.01 | K13: Rare Benefit | L13: R | M13: =Score!E20 -> 0.1
A14: Summer Water Temperature | B14: D | C14: C | D14: =VLOOKUP(B14,$L$7:$M$9,2,FALSE)*VLOOKUP(C14,$L$11:$M$13,2,FALSE) -> 1
A15: Winter Water Temperature | B15: D | C15: C | D15: =VLOOKUP(B15,$L$7:$M$9,2,FALSE)*VLOOKUP(C15,$L$11:$M$13,2,FALSE) -> 1
A16: Water Quality (DO, Toxics, Turbidity, Excess nutrients) | B16: N | C16: R | D16: =VLOOKUP(B16,$L$7:$M$9,2,FALSE)*VLOOKUP(C16,$L$11:$M$13,2,FALSE) -> 0.01
A17: Predation | B17: I | C17: R | D17: =VLOOKUP(B17,$L$7:$M$9,2,FALSE)*VLOOKUP(C17,$L$11:$M$13,2,FALSE) -> 0.05
A18: Altered Primary Productivity | B18: N | C18: R | D18: =VLOOKUP(B18,$L$7:$M$9,2,FALSE)*VLOOKUP(C18,$L$11:$M$13,2,FALSE) -> 0.01
A19: Non-Native Species Interactions & Competition | B19: N | C19: R | D19: =VLOOKUP(B19,$L$7:$M$9,2,FALSE)*VLOOKUP(C19,$L$11:$M$13,2,FALSE) -> 0.01
C20: Total | D20: =SUM(D5:D19) -> 2.49

Sheet 8 - WQ Imp
A1: Action-Limiting Factor Rating Sheet
B2: Action: Water Quality Improvement
A3: Limiting Factor Category | B3: Directness of Benefit | C3: Frequency of Benefit | D3: Score (0-1)
B4: Rating | C4: Rating | D4: Calculated
A5: Anthropogenic Barriers | B5: N | C5: R | D5: =VLOOKUP(B5,$L$7:$M$9,2,FALSE)*VLOOKUP(C5,$L$11:$M$13,2,FALSE) -> 0.01
A6: Riparian Condition | B6: I | C6: CD | D6: =VLOOKUP(B6,$L$7:$M$9,2,FALSE)*VLOOKUP(C6,$L$11:$M$13,2,FALSE) -> 0.25
A7: Floodplain Condition | B7: I | C7: CD | D7: =VLOOKUP(B7,$L$7:$M$9,2,FALSE)*VLOOKUP(C7,$L$11:$M$13,2,FALSE) -> 0.25 | K7: Direct | L7: D | M7: =Score!E14 -> 1
A8: Side Channel and Wetland Habitat | B8: N | C8: R | D8: =VLOOKUP(B8,$L$7:$M$9,2,FALSE)*VLOOKUP(C8,$L$11:$M$13,2,FALSE) -> 0.01 | K8: Indirect | L8: I | M8: =Score!E15 -> 0.5
A9: Channel and Habitat Structure | B9: N | C9: R | D9: =VLOOKUP(B9,$L$7:$M$9,2,FALSE)*VLOOKUP(C9,$L$11:$M$13,2,FALSE) -> 0.01 | K9: Negligible | L9: N | M9: =Score!E16 -> 0.1
A10: Decreased Water Quantity | B10: N | C10: R | D10: =VLOOKUP(B10,$L$7:$M$9,2,FALSE)*VLOOKUP(C10,$L$11:$M$13,2,FALSE) -> 0.01
A11: Altered Flow Timing | B11: N | C11: R | D11: =VLOOKUP(B11,$L$7:$M$9,2,FALSE)*VLOOKUP(C11,$L$11:$M$13,2,FALSE) -> 0.01 | K11: Common Benefit | L11: C | M11: =Score!E18 -> 1
A12: Decreased Water Quantity | B12: N | C12: R | D12: =VLOOKUP(B12,$L$7:$M$9,2,FALSE)*VLOOKUP(C12,$L$11:$M$13,2,FALSE) -> 0.01 | K12: Context-Dependant Benefit | L12: CD | M12: =Score!E19 -> 0.5
A13: Decreased Sediment Quantity | B13: N | C13: R | D13: =VLOOKUP(B13,$L$7:$M$9,2,FALSE)*VLOOKUP(C13,$L$11:$M$13,2,FALSE) -> 0.01 | K13: Rare Benefit | L13: R | M13: =Score!E20 -> 0.1
A14: Increased Sediment Quantity (fines, embeddedness) | B14: I | C14: CD | D14: =VLOOKUP(B14,$L$7:$M$9,2,FALSE)*VLOOKUP(C14,$L$11:$M$13,2,FALSE) -> 0.25
A15: Summer Water Temperature | B15: N | C15: R | D15: =VLOOKUP(B15,$L$7:$M$9,2,FALSE)*VLOOKUP(C15,$L$11:$M$13,2,FALSE) -> 0.01
A16: Winter Water Temperature | B16: N | C16: R | D16: =VLOOKUP(B16,$L$7:$M$9,2,FALSE)*VLOOKUP(C16,$L$11:$M$13,2,FALSE) -> 0.01
A17: Water Quality (DO, Toxics, Turbidity, Excess nutrients) | B17: D | C17: C | D17: =VLOOKUP(B17,$L$7:$M$9,2,FALSE)*VLOOKUP(C17,$L$11:$M$13,2,FALSE) -> 1
A18: Predation | B18: N | C18: R | D18: =VLOOKUP(B18,$L$7:$M$9,2,FALSE)*VLOOKUP(C18,$L$11:$M$13,2,FALSE) -> 0.01
A19: Altered Primary Productivity | B19: N | C19: R | D19: =VLOOKUP(B19,$L$7:$M$9,2,FALSE)*VLOOKUP(C19,$L$11:$M$13,2,FALSE) -> 0.01
A20: Non-Native Species Interactions & Competition | B20: N | C20: R | D20: =VLOOKUP(B20,$L$7:$M$9,2,FALSE)*VLOOKUP(C20,$L$11:$M$13,2,FALSE) -> 0.01
C21: Total | D21: =SUM(D5:D20) -> 1.87

Sheet 9 - Nutrient Enh
A1: Action-Limiting Factor Rating Sheet
B2: Action: Nutrient Enhancement
A3: Limiting Factor Category | B3: Directness of Benefit | C3: Frequency of Benefit | D3: Score (0-1)
B4: Rating | C4: Rating | D4: Calculated
A5: Anthropogenic Barriers | B5: N | C5: R | D5: =VLOOKUP(B5,$L$7:$M$9,2,FALSE)*VLOOKUP(C5,$L$11:$M$13,2,FALSE) -> 0.01
A6: Riparian Condition | B6: I | C6: CD | D6: =VLOOKUP(B6,$L$7:$M$9,2,FALSE)*VLOOKUP(C6,$L$11:$M$13,2,FALSE) -> 0.25
A7: Floodplain Condition | B7: I | C7: R | D7: =VLOOKUP(B7,$L$7:$M$9,2,FALSE)*VLOOKUP(C7,$L$11:$M$13,2,FALSE) -> 0.05 | K7: Direct | L7: D | M7: =Score!E14 -> 1
A8: Side Channel and Wetland Habitat | B8: N | C8: R | D8: =VLOOKUP(B8,$L$7:$M$9,2,FALSE)*VLOOKUP(C8,$L$11:$M$13,2,FALSE) -> 0.01 | K8: Indirect | L8: I | M8: =Score!E15 -> 0.5
A9: Channel and Habitat Structure | B9: N | C9: R | D9: =VLOOKUP(B9,$L$7:$M$9,2,FALSE)*VLOOKUP(C9,$L$11:$M$13,2,FALSE) -> 0.01 | K9: Negligible | L9: N | M9: =Score!E16 -> 0.1
A10: Decreased Water Quantity | B10: N | C10: R | D10: =VLOOKUP(B10,$L$7:$M$9,2,FALSE)*VLOOKUP(C10,$L$11:$M$13,2,FALSE) -> 0.01
A11: Altered Flow Timing | B11: N | C11: R | D11: =VLOOKUP(B11,$L$7:$M$9,2,FALSE)*VLOOKUP(C11,$L$11:$M$13,2,FALSE) -> 0.01 | K11: Common Benefit | L11: C | M11: =Score!E18 -> 1
A12: Decreased Sediment Quantity | B12: N | C12: R | D12: =VLOOKUP(B12,$L$7:$M$9,2,FALSE)*VLOOKUP(C12,$L$11:$M$13,2,FALSE) -> 0.01 | K12: Context-Dependant Benefit | L12: CD | M12: =Score!E19 -> 0.5
A13: Increased Sediment Quantity (fines, embeddedness) | B13: N | C13: R | D13: =VLOOKUP(B13,$L$7:$M$9,2,FALSE)*VLOOKUP(C13,$L$11:$M$13,2,FALSE) -> 0.01 | K13: Rare Benefit | L13: R | M13: =Score!E20 -> 0.1
A14: Summer Water Temperature | B14: N | C14: R | D14: =VLOOKUP(B14,$L$7:$M$9,2,FALSE)*VLOOKUP(C14,$L$11:$M$13,2,FALSE) -> 0.01
A15: Winter Water Temperature | B15: N | C15: R | D15: =VLOOKUP(B15,$L$7:$M$9,2,FALSE)*VLOOKUP(C15,$L$11:$M$13,2,FALSE) -> 0.01
A16: Water Quality (DO, Toxics, Turbidity, Excess nutrients) | B16: N | C16: R | D16: =VLOOKUP(B16,$L$7:$M$9,2,FALSE)*VLOOKUP(C16,$L$11:$M$13,2,FALSE) -> 0.01
A17: Predation | B17: N | C17: R | D17: =VLOOKUP(B17,$L$7:$M$9,2,FALSE)*VLOOKUP(C17,$L$11:$M$13,2,FALSE) -> 0.01
A18: Altered Primary Productivity | B18: D | C18: C | D18: =VLOOKUP(B18,$L$7:$M$9,2,FALSE)*VLOOKUP(C18,$L$11:$M$13,2,FALSE) -> 1
A19: Non-Native Species Interactions & Competition | B19: N | C19: R | D19: =VLOOKUP(B19,$L$7:$M$9,2,FALSE)*VLOOKUP(C19,$L$11:$M$13,2,FALSE) -> 0.01
C20: Total | D20: =SUM(D5:D19) -> 1.42

Sheet 10 - Upland
A1: Action-Limiting Factor Rating Sheet
B2: Action: Upland Treatments
A3: Limiting Factor Category | B3: Directness of Benefit | C3: Frequency of Benefit | D3: Score (0-1)
B4: Rating | C4: Rating | D4: Calculated
A5: Anthropogenic Barriers | B5: N | C5: R | D5: =VLOOKUP(B5,$L$7:$M$9,2,FALSE)*VLOOKUP(C5,$L$11:$M$13,2,FALSE) -> 0.01
A6: Riparian Condition | B6: N | C6: R | D6: =VLOOKUP(B6,$L$7:$M$9,2,FALSE)*VLOOKUP(C6,$L$11:$M$13,2,FALSE) -> 0.01
A7: Floodplain Condition | B7: N | C7: R | D7: =VLOOKUP(B7,$L$7:$M$9,2,FALSE)*VLOOKUP(C7,$L$11:$M$13,2,FALSE) -> 0.01 | K7: Direct | L7: D | M7: =Score!E14 -> 1
A8: Side Channel and Wetland Habitat | B8: N | C8: R | D8: =VLOOKUP(B8,$L$7:$M$9,2,FALSE)*VLOOKUP(C8,$L$11:$M$13,2,FALSE) -> 0.01 | K8: Indirect | L8: I | M8: =Score!E15 -> 0.5
A9: Channel and Habitat Structure | B9: N | C9: R | D9: =VLOOKUP(B9,$L$7:$M$9,2,FALSE)*VLOOKUP(C9,$L$11:$M$13,2,FALSE) -> 0.01 | K9: Negligible | L9: N | M9: =Score!E16 -> 0.1
A10: Decreased Water Quantity | B10: I | C10: CD | D10: =VLOOKUP(B10,$L$7:$M$9,2,FALSE)*VLOOKUP(C10,$L$11:$M$13,2,FALSE) -> 0.25
A11: Altered Flow Timing | B11: I | C11: CD | D11: =VLOOKUP(B11,$L$7:$M$9,2,FALSE)*VLOOKUP(C11,$L$11:$M$13,2,FALSE) -> 0.25 | K11: Common Benefit | L11: C | M11: =Score!E18 -> 1
A12: Decreased Sediment Quantity | B12: I | C12: CD | D12: =VLOOKUP(B12,$L$7:$M$9,2,FALSE)*VLOOKUP(C12,$L$11:$M$13,2,FALSE) -> 0.25 | K12: Context-Dependant Benefit | L12: CD | M12: =Score!E19 -> 0.5
A13: Increased Sediment Quantity (fines, embeddedness) | B13: I | C13: CD | D13: =VLOOKUP(B13,$L$7:$M$9,2,FALSE)*VLOOKUP(C13,$L$11:$M$13,2,FALSE) -> 0.25 | K13: Rare Benefit | L13: R | M13: =Score!E20 -> 0.1
A14: Summer Water Temperature | B14: I | C14: CD | D14: =VLOOKUP(B14,$L$7:$M$9,2,FALSE)*VLOOKUP(C14,$L$11:$M$13,2,FALSE) -> 0.25
A15: Winter Water Temperature | B15: N | C15: R | D15: =VLOOKUP(B15,$L$7:$M$9,2,FALSE)*VLOOKUP(C15,$L$11:$M$13,2,FALSE) -> 0.01
A16: Water Quality (DO, Toxics, Turbidity, Excess nutrients) | B16: I | C16: CD | D16: =VLOOKUP(B16,$L$7:$M$9,2,FALSE)*VLOOKUP(C16,$L$11:$M$13,2,FALSE) -> 0.25
A17: Predation | B17: N | C17: R | D17: =VLOOKUP(B17,$L$7:$M$9,2,FALSE)*VLOOKUP(C17,$L$11:$M$13,2,FALSE) -> 0.01
A18: Altered Primary Productivity | B18: I | C18: CD | D18: =VLOOKUP(B18,$L$7:$M$9,2,FALSE)*VLOOKUP(C18,$L$11:$M$13,2,FALSE) -> 0.25
A19: Non-Native Species Interactions & Competition | B19: N | C19: R | D19: =VLOOKUP(B19,$L$7:$M$9,2,FALSE)*VLOOKUP(C19,$L$11:$M$13,2,FALSE) -> 0.01
C20: Total | D20: =SUM(D5:D19) -> 1.83

Sheet 11 - Species Manage.
A1: Action-Limiting Factor Rating Sheet
B2: Action: Species Management
A3: Limiting Factor Category | B3: Directness of Benefit | C3: Frequency of Benefit | D3: Score (0-1)
B4: Rating | C4: Rating | D4: Calculated
A5: Anthropogenic Barriers | B5: N | C5: R | D5: =VLOOKUP(B5,$L$7:$M$9,2,FALSE)*VLOOKUP(C5,$L$11:$M$13,2,FALSE) -> 0.01
A6: Riparian Condition | B6: N | C6: R | D6: =VLOOKUP(B6,$L$7:$M$9,2,FALSE)*VLOOKUP(C6,$L$11:$M$13,2,FALSE) -> 0.01
A7: Floodplain Condition | B7: N | C7: R | D7: =VLOOKUP(B7,$L$7:$M$9,2,FALSE)*VLOOKUP(C7,$L$11:$M$13,2,FALSE) -> 0.01 | K7: Direct | L7: D | M7: =Score!E14 -> 1
A8: Side Channel and Wetland Habitat | B8: N | C8: R | D8: =VLOOKUP(B8,$L$7:$M$9,2,FALSE)*VLOOKUP(C8,$L$11:$M$13,2,FALSE) -> 0.01 | K8: Indirect | L8: I | M8: =Score!E15 -> 0.5
A9: Channel and Habitat Structure | B9: N | C9: R | D9: =VLOOKUP(B9,$L$7:$M$9,2,FALSE)*VLOOKUP(C9,$L$11:$M$13,2,FALSE) -> 0.01 | K9: Negligible | L9: N | M9: =Score!E16 -> 0.1
A10: Decreased Water Quantity | B10: N | C10: R | D10: =VLOOKUP(B10,$L$7:$M$9,2,FALSE)*VLOOKUP(C10,$L$11:$M$13,2,FALSE) -> 0.01
A11: Altered Flow Timing | B11: N | C11: R | D11: =VLOOKUP(B11,$L$7:$M$9,2,FALSE)*VLOOKUP(C11,$L$11:$M$13,2,FALSE) -> 0.01 | K11: Common Benefit | L11: C | M11: =Score!E18 -> 1
A12: Decreased Sediment Quantity | B12: N | C12: R | D12: =VLOOKUP(B12,$L$7:$M$9,2,FALSE)*VLOOKUP(C12,$L$11:$M$13,2,FALSE) -> 0.01 | K12: Context-Dependant Benefit | L12: CD | M12: =Score!E19 -> 0.5
A13: Increased Sediment Quantity (fines, embeddedness) | B13: N | C13: R | D13: =VLOOKUP(B13,$L$7:$M$9,2,FALSE)*VLOOKUP(C13,$L$11:$M$13,2,FALSE) -> 0.01 | K13: Rare Benefit | L13: R | M13: =Score!E20 -> 0.1
A14: Summer Water Temperature | B14: N | C14: R | D14: =VLOOKUP(B14,$L$7:$M$9,2,FALSE)*VLOOKUP(C14,$L$11:$M$13,2,FALSE) -> 0.01
A15: Winter Water Temperature | B15: N | C15: R | D15: =VLOOKUP(B15,$L$7:$M$9,2,FALSE)*VLOOKUP(C15,$L$11:$M$13,2,FALSE) -> 0.01
A16: Water Quality (DO, Toxics, Turbidity, Excess nutrients) | B16: N | C16: R | D16: =VLOOKUP(B16,$L$7:$M$9,2,FALSE)*VLOOKUP(C16,$L$11:$M$13,2,FALSE) -> 0.01
A17: Predation | B17: D | C17: C | D17: =VLOOKUP(B17,$L$7:$M$9,2,FALSE)*VLOOKUP(C17,$L$11:$M$13,2,FALSE) -> 1
A18: Altered Primary Productivity | B18: N | C18: R | D18: =VLOOKUP(B18,$L$7:$M$9,2,FALSE)*VLOOKUP(C18,$L$11:$M$13,2,FALSE) -> 0.01
A19: Non-Native Species Interactions & Competition | B19: D | C19: C | D19: =VLOOKUP(B19,$L$7:$M$9,2,FALSE)*VLOOKUP(C19,$L$11:$M$13,2,FALSE) -> 1
C20: Total | D20: =SUM(D5:D19) -> 2.13
